Workbook

Sheet Indirect Active (2)
A1: Company code | B1: Pers.no. | C1: Name_C | D1: Name_E | E1: Subgroup | F1: Area | G1: Subarea | H1: Dept. | I1: Cost ctr | J1: Join date | K1: Job | L1: Position | M1: Band Level | N1: Workplan type | O1: 2025 Performance Level | P1: Basic salary | Q1: ① Merit increase % | R1: Merit Increase amount | S1: ② Equity Increase% | T1: Equity Increase amount | U1: Total recommended Increase % (①+②) | V1: Total Recommended Increase amount | W1: Recommended new basic salary | X1: Adjutsed basic salary (input by DH) | Y1: Adjutsed increased/decreased basic salary by DH | Z1: Adjusted basic increase/decreased % by DH | AA1: Adjustment range reference | AB1: Promotion or demotion | AC1: New position title | AD1: New band | AE1: ③ Promotion increase/Demotion decrease % (±5%-±20%) | AF1: Promotion increase/Demotion decrease amount | AG1: Final new basic salary | AH1: Final increase/decrease amount | AI1: Final increase/decrease rate | AJ1: Pay months | AK1: Monthly allowance/bonus | AL1: Monthly Car Allowance | AM1: Other income(e.g.:festival bonus) | AN1: Annual target cash | AO1: 2024 Performance Level | AP1: Disciplinary Records | AQ1: Justifications by DH | AR1: HR Remark | AS1: Responsible ASR Manager | AT1: Responsible ASR HRBP | AU1: PY | AV1: 85% of LMW (for Technician/Counsellor) | AW1: Editable column 1 | AX1: Editable column 2 | AY1: -
A2: CN15 | B2: 15000447 | C2: 柏 正曹 | D2: Bo Zhengcao | E2: Indirect Active | F2: OP | G2: SNa | H2: FCGNa-VVP | I2: 330404 | J2: 38808 | K2: Workshop Leader | L2: Head of FCGNa-VVP | M2: BAND A6 | N2: 2 | O2: 5 | P2: 15840 | Q2: 0.05 | R2: =ROUND(P2*Q2,0) -> 792 | S2: 0 | T2: =ROUND(P2*S2,0) -> 0 | U2: =V2/P2 -> 0.05 | V2: =R2+T2 -> 792 | W2: =P2+V2 -> 16632 | X2: 16780 | Y2: =X2-P2 -> 940 | Z2: =ROUND(X2/P2-1,4) -> 0.0593 | AA2: =IF(OR(N2=1,N2=2,N2=4), TEXT(U2*0.8,"0.00%") & "-" & TEXT(U2*1.2,"0.00%"), IF(OR(N2=3,N2=6), TEXT(0,"0.00%") & "-" & TEXT(7%*1.2,"0.00%"), IF(OR(N2=5,N2=7), TEXT((T2/P2),"0.00%") & "-" & TEXT((T2/P2)+7%,"0.00%"), "" ) ) ) -> 4.00%-6.00% | AF2: =ROUND(P2*AE2,0) -> 0 | AG2: =X2+AF2 -> 16780 | AH2: =AG2-P2 -> 940 | AI2: =AG2/P2-1 -> 0.059343434 | AJ2: 14 | AK2: 450 | AM2: 688 | AN2: =AG2*AJ2+AK2*12+AM2+IF(AD2="",AL2,IF(AD2="D",5000,IF(AD2="C",1000,0)))*12 -> 241008 | AO2: 4 | AS2: Miao Siyuan（15005811） | AT2: Zhu Qianqian（11016705） | AU2: Zhao Chujun | AY2: =_xlfn.LET(_xlpm.actual,Z2,_xlpm.low,VALUE(_xlfn.TEXTBEFORE(AA2,"-")),_xlpm.high,VALUE(_xlfn.TEXTAFTER(AA2,"-")),IF(AND(_xlpm.actual=0,OR(_xlpm.low<>0,_xlpm.high<>0)),"0 increase",IF(_xlpm.actual>_xlpm.high*1.2,">20",IF(_xlpm.actual<_xlpm.low*0.8,"<20","OK")))) -> OK
A3: CN15 | B3: 15014416 | C3: 蔡 凯健 | D3: Cai Kaijian | E3: Indirect Active | F3: OP | G3: SNa | H3: FCGNa-VVE | I3: 330404 | J3: 45063 | K3: Supervisor | L3: Head of Engineering Ventilation | M3: BAND A6 | N3: 2 | O3: 4 | P3: 16456 | Q3: 0.045 | R3: =ROUND(P3*Q3,0) -> 741 | S3: 0.0155 | T3: =ROUND(P3*S3,0) -> 255 | U3: =V3/P3 -> 0.060525036 | V3: =R3+T3 -> 996 | W3: =P3+V3 -> 17452 | X3: 17456 | Y3: =X3-P3 -> 1000 | Z3: =ROUND(X3/P3-1,4) -> 0.0608 | AA3: =IF(OR(N3=1,N3=2,N3=4), TEXT(U3*0.8,"0.00%") & "-" & TEXT(U3*1.2,"0.00%"), IF(OR(N3=3,N3=6), TEXT(0,"0.00%") & "-" & TEXT(7%*1.2,"0.00%"), IF(OR(N3=5,N3=7), TEXT((T3/P3),"0.00%") & "-" & TEXT((T3/P3)+7%,"0.00%"), "" ) ) ) -> 4.84%-7.26% | AF3: =ROUND(P3*AE3,0) -> 0 | AG3: =X3+AF3 -> 17456 | AH3: =AG3-P3 -> 1000 | AI3: =AG3/P3-1 -> 0.060768109 | AJ3: 14 | AK3: 450 | AM3: 688 | AN3: =AG3*AJ3+AK3*12+AM3+IF(AD3="",AL3,IF(AD3="D",5000,IF(AD3="C",1000,0)))*12 -> 250472 | AO3: 5 | AS3: Miao Siyuan（15005811） | AT3: Zhu Qianqian（11016705） | AU3: Zhao Chujun | AY3: =_xlfn.LET(_xlpm.actual,Z3,_xlpm.low,VALUE(_xlfn.TEXTBEFORE(AA3,"-")),_xlpm.high,VALUE(_xlfn.TEXTAFTER(AA3,"-")),IF(AND(_xlpm.actual=0,OR(_xlpm.low<>0,_xlpm.high<>0)),"0 increase",IF(_xlpm.actual>_xlpm.high*1.2,">20",IF(_xlpm.actual<_xlpm.low*0.8,"<20","OK")))) -> OK
A4: CN15 | B4: 15014868 | C4: 符 卫卫 | D4: Fu Weiwei | E4: Indirect Active | F4: OP | G4: SNa | H4: FCGNa-VVE | I4: 330404 | J4: 42291 | K4: Project Manager | L4: Project Manager | M4: BAND A6 | N4: 2 | O4: 3 | P4: 13630 | Q4: 0.03 | R4: =ROUND(P4*Q4,0) -> 409 | S4: 0 | T4: =ROUND(P4*S4,0) -> 0 | U4: =V4/P4 -> 0.030007337 | V4: =R4+T4 -> 409 | W4: =P4+V4 -> 14039 | X4: 14038 | Y4: =X4-P4 -> 408 | Z4: =ROUND(X4/P4-1,4) -> 0.0299 | AA4: =IF(OR(N4=1,N4=2,N4=4), TEXT(U4*0.8,"0.00%") & "-" & TEXT(U4*1.2,"0.00%"), IF(OR(N4=3,N4=6), TEXT(0,"0.00%") & "-" & TEXT(7%*1.2,"0.00%"), IF(OR(N4=5,N4=7), TEXT((T4/P4),"0.00%") & "-" & TEXT((T4/P4)+7%,"0.00%"), "" ) ) ) -> 2.40%-3.60% | AF4: =ROUND(P4*AE4,0) -> 0 | AG4: =X4+AF4 -> 14038 | AH4: =AG4-P4 -> 408 | AI4: =AG4/P4-1 -> 0.029933969 | AJ4: 14 | AK4: 450 | AM4: 688 | AN4: =AG4*AJ4+AK4*12+AM4+IF(AD4="",AL4,IF(AD4="D",5000,IF(AD4="C",1000,0)))*12 -> 202620 | AO4: 4 | AS4: Miao Siyuan（15005811） | AT4: Zhu Qianqian（11016705） | AU4: Zhao Chujun | AY4: =_xlfn.LET(_xlpm.actual,Z4,_xlpm.low,VALUE(_xlfn.TEXTBEFORE(AA4,"-")),_xlpm.high,VALUE(_xlfn.TEXTAFTER(AA4,"-")),IF(AND(_xlpm.actual=0,OR(_xlpm.low<>0,_xlpm.high<>0)),"0 increase",IF(_xlpm.actual>_xlpm.high*1.2,">20",IF(_xlpm.actual<_xlpm.low*0.8,"<20","OK")))) -> OK
A5: CN15 | B5: 15022166 | C5: 李 超 | D5: Li Chao | E5: Indirect Active | F5: OP | G5: SNa | H5: FCGNa-VVE | I5: 330404 | J5: 44664 | K5: Senior Engineer | L5: Senior Electrical Engineer | M5: BAND A5 | N5: 2 | O5: 4 | P5: 14440 | Q5: 0.0375 | R5: =ROUND(P5*Q5,0) -> 542 | S5: 0 | T5: =ROUND(P5*S5,0) -> 0 | U5: =V5/P5 -> 0.037534626 | V5: =R5+T5 -> 542 | W5: =P5+V5 -> 14982 | X5: 15000 | Y5: =X5-P5 -> 560 | Z5: =ROUND(X5/P5-1,4) -> 0.0388 | AA5: =IF(OR(N5=1,N5=2,N5=4), TEXT(U5*0.8,"0.00%") & "-" & TEXT(U5*1.2,"0.00%"), IF(OR(N5=3,N5=6), TEXT(0,"0.00%") & "-" & TEXT(7%*1.2,"0.00%"), IF(OR(N5=5,N5=7), TEXT((T5/P5),"0.00%") & "-" & TEXT((T5/P5)+7%,"0.00%"), "" ) ) ) -> 3.00%-4.50% | AF5: =ROUND(P5*AE5,0) -> 0 | AG5: =X5+AF5 -> 15000 | AH5: =AG5-P5 -> 560 | AI5: =AG5/P5-1 -> 0.038781163 | AJ5: 14 | AK5: 450 | AM5: 688 | AN5: =AG5*AJ5+AK5*12+AM5+IF(AD5="",AL5,IF(AD5="D",5000,IF(AD5="C",1000,0)))*12 -> 216088 | AO5: 2 | AS5: Miao Siyuan（15005811） | AT5: Zhu Qianqian（11016705） | AU5: Zhao Chujun | AY5: =_xlfn.LET(_xlpm.actual,Z5,_xlpm.low,VALUE(_xlfn.TEXTBEFORE(AA5,"-")),_xlpm.high,VALUE(_xlfn.TEXTAFTER(AA5,"-")),IF(AND(_xlpm.actual=0,OR(_xlpm.low<>0,_xlpm.high<>0)),"0 increase",IF(_xlpm.actual>_xlpm.high*1.2,">20",IF(_xlpm.actual<_xlpm.low*0.8,"<20","OK")))) -> OK
A6: CN15 | B6: 15016337 | C6: 刘 文涛 | D6: Liu Wentao | E6: Indirect Active | F6: OP | G6: SNa | H6: FCGNa-VVE | I6: 330404 | J6: 42795 | K6: Functional Specialist | L6: Functional Specialist | M6: BAND A6 | N6: 2 | O6: 3 | P6: 14284 | Q6: 0.03 | R6: =ROUND(P6*Q6,0) -> 429 | S6: 0 | T6: =ROUND(P6*S6,0) -> 0 | U6: =V6/P6 -> 0.030033604 | V6: =R6+T6 -> 429 | W6: =P6+V6 -> 14713 | X6: 14688 | Y6: =X6-P6 -> 404 | Z6: =ROUND(X6/P6-1,4) -> 0.0283 | AA6: =IF(OR(N6=1,N6=2,N6=4), TEXT(U6*0.8,"0.00%") & "-" & TEXT(U6*1.2,"0.00%"), IF(OR(N6=3,N6=6), TEXT(0,"0.00%") & "-" & TEXT(7%*1.2,"0.00%"), IF(OR(N6=5,N6=7), TEXT((T6/P6),"0.00%") & "-" & TEXT((T6/P6)+7%,"0.00%"), "" ) ) ) -> 2.40%-3.60% | AF6: =ROUND(P6*AE6,0) -> 0 | AG6: =X6+AF6 -> 14688 | AH6: =AG6-P6 -> 404 | AI6: =AG6/P6-1 -> 0.028283394 | AJ6: 14 | AK6: 450 | AM6: 688 | AN6: =AG6*AJ6+AK6*12+AM6+IF(AD6="",AL6,IF(AD6="D",5000,IF(AD6="C",1000,0)))*12 -> 211720 | AO6: 2 | AS6: Miao Siyuan（15005811） | AT6: Zhu Qianqian（11016705） | AU6: Zhao Chujun | AY6: =_xlfn.LET(_xlpm.actual,Z6,_xlpm.low,VALUE(_xlfn.TEXTBEFORE(AA6,"-")),_xlpm.high,VALUE(_xlfn.TEXTAFTER(AA6,"-")),IF(AND(_xlpm.actual=0,OR(_xlpm.low<>0,_xlpm.high<>0)),"0 increase",IF(_xlpm.actual>_xlpm.high*1.2,">20",IF(_xlpm.actual<_xlpm.low*0.8,"<20","OK")))) -> OK
A7: CN15 | B7: 15022630 | C7: 王 长德 | D7: Wang Changde | E7: Indirect Active | F7: OP | G7: SNa | H7: FCGNa-VVE | I7: 330408 | J7: 45854 | K7: Functional Specialist | L7: Painting Functional Specialist | M7: BAND A6 | N7: 2 | O7: 3 | P7: 23000 | Q7: 0 | R7: =ROUND(P7*Q7,0) -> 0 | S7: 0 | T7: =ROUND(P7*S7,0) -> 0 | U7: =V7/P7 -> 0 | V7: =R7+T7 -> 0 | W7: =P7+V7 -> 23000 | X7: 23000 | Y7: =X7-P7 -> 0 | Z7: =ROUND(X7/P7-1,4) -> 0 | AA7: =IF(OR(N7=1,N7=2,N7=4), TEXT(U7*0.8,"0.00%") & "-" & TEXT(U7*1.2,"0.00%"), IF(OR(N7=3,N7=6), TEXT(0,"0.00%") & "-" & TEXT(7%*1.2,"0.00%"), IF(OR(N7=5,N7=7), TEXT((T7/P7),"0.00%") & "-" & TEXT((T7/P7)+7%,"0.00%"), "" ) ) ) -> 0.00%-0.00% | AF7: =ROUND(P7*AE7,0) -> 0 | AG7: =X7+AF7 -> 23000 | AH7: =AG7-P7 -> 0 | AI7: =AG7/P7-1 -> 0 | AJ7: 14 | AK7: 450 | AM7: 688 | AN7: =AG7*AJ7+AK7*12+AM7+IF(AD7="",AL7,IF(AD7="D",5000,IF(AD7="C",1000,0)))*12 -> 328088 | AO7: #N/A | AS7: Miao Siyuan（15005811） | AT7: Zhu Qianqian（11016705） | AU7: Zhao Chujun | AY7: =_xlfn.LET(_xlpm.actual,Z7,_xlpm.low,VALUE(_xlfn.TEXTBEFORE(AA7,"-")),_xlpm.high,VALUE(_xlfn.TEXTAFTER(AA7,"-")),IF(AND(_xlpm.actual=0,OR(_xlpm.low<>0,_xlpm.high<>0)),"0 increase",IF(_xlpm.actual>_xlpm.high*1.2,">20",IF(_xlpm.actual<_xlpm.low*0.8,"<20","OK")))) -> OK
A8: CN15 | B8: 15007556 | C8: 武 松 | D8: Wu Song | E8: Indirect Active | F8: OP | G8: SNa | H8: FCGNa-VVM | I8: 330204 | J8: 40962 | K8: Supervisor | L8: Head of FCGNa-VVM | M8: BAND A6 | N8: 2 | O8: 3 | P8: 16100 | Q8: 0.025 | R8: =ROUND(P8*Q8,0) -> 403 | S8: 0 | T8: =ROUND(P8*S8,0) -> 0 | U8: =V8/P8 -> 0.025031056 | V8: =R8+T8 -> 403 | W8: =P8+V8 -> 16503 | X8: 16518 | Y8: =X8-P8 -> 418 | Z8: =ROUND(X8/P8-1,4) -> 0.026 | AA8: =IF(OR(N8=1,N8=2,N8=4), TEXT(U8*0.8,"0.00%") & "-" & TEXT(U8*1.2,"0.00%"), IF(OR(N8=3,N8=6), TEXT(0,"0.00%") & "-" & TEXT(7%*1.2,"0.00%"), IF(OR(N8=5,N8=7), TEXT((T8/P8),"0.00%") & "-" & TEXT((T8/P8)+7%,"0.00%"), "" ) ) ) -> 2.00%-3.00% | AF8: =ROUND(P8*AE8,0) -> 0 | AG8: =X8+AF8 -> 16518 | AH8: =AG8-P8 -> 418 | AI8: =AG8/P8-1 -> 0.025962733 | AJ8: 14 | AK8: 450 | AM8: 688 | AN8: =AG8*AJ8+AK8*12+AM8+IF(AD8="",AL8,IF(AD8="D",5000,IF(AD8="C",1000,0)))*12 -> 237340 | AO8: 3 | AS8: Miao Siyuan（15005811） | AT8: Zhu Qianqian（11016705） | AU8: Zhao Chujun | AY8: =_xlfn.LET(_xlpm.actual,Z8,_xlpm.low,VALUE(_xlfn.TEXTBEFORE(AA8,"-")),_xlpm.high,VALUE(_xlfn.TEXTAFTER(AA8,"-")),IF(AND(_xlpm.actual=0,OR(_xlpm.low<>0,_xlpm.high<>0)),"0 increase",IF(_xlpm.actual>_xlpm.high*1.2,">20",IF(_xlpm.actual<_xlpm.low*0.8,"<20","OK")))) -> OK
A9: CN15 | B9: 1120246 | C9: 张 民强 | D9: Zhang Minqiang | E9: Indirect Active | F9: OP | G9: SNa | H9: FCGNa-VVE | I9: 330404 | J9: 43864 | K9: Functional Specialist | L9: Functional Specialist | M9: BAND A6 | N9: 2 | O9: 4 | P9: 13111 | Q9: 0.045 | R9: =ROUND(P9*Q9,0) -> 590 | S9: 0.0421 | T9: =ROUND(P9*S9,0) -> 552 | U9: =V9/P9 -> 0.087102433 | V9: =R9+T9 -> 1142 | W9: =P9+V9 -> 14253 | X9: 14066 | Y9: =X9-P9 -> 955 | Z9: =ROUND(X9/P9-1,4) -> 0.0728 | AA9: =IF(OR(N9=1,N9=2,N9=4), TEXT(U9*0.8,"0.00%") & "-" & TEXT(U9*1.2,"0.00%"), IF(OR(N9=3,N9=6), TEXT(0,"0.00%") & "-" & TEXT(7%*1.2,"0.00%"), IF(OR(N9=5,N9=7), TEXT((T9/P9),"0.00%") & "-" & TEXT((T9/P9)+7%,"0.00%"), "" ) ) ) -> 6.97%-10.45% | AF9: =ROUND(P9*AE9,0) -> 0 | AG9: =X9+AF9 -> 14066 | AH9: =AG9-P9 -> 955 | AI9: =AG9/P9-1 -> 0.0728396 | AJ9: 14 | AK9: 850 | AM9: 688 | AN9: =AG9*AJ9+AK9*12+AM9+IF(AD9="",AL9,IF(AD9="D",5000,IF(AD9="C",1000,0)))*12 -> 207812 | AO9: 3 | AS9: Miao Siyuan（15005811） | AT9: Zhu Qianqian（11016705） | AU9: Zhao Chujun | AY9: =_xlfn.LET(_xlpm.actual,Z9,_xlpm.low,VALUE(_xlfn.TEXTBEFORE(AA9,"-")),_xlpm.high,VALUE(_xlfn.TEXTAFTER(AA9,"-")),IF(AND(_xlpm.actual=0,OR(_xlpm.low<>0,_xlpm.high<>0)),"0 increase",IF(_xlpm.actual>_xlpm.high*1.2,">20",IF(_xlpm.actual<_xlpm.low*0.8,"<20","OK")))) -> OK
A10: CN15 | B10: 15000219 | C10: 周 金贵 | D10: Zhou Jingui | E10: Indirect Active | F10: OP | G10: SNa | H10: FCGNa-VVE | I10: 330404 | J10: 38608 | K10: Engineer | L10: Project Engineer | M10: BAND A4 | N10: 2 | O10: 2 | P10: 12256 | Q10: 0 | R10: =ROUND(P10*Q10,0) -> 0 | S10: 0 | T10: =ROUND(P10*S10,0) -> 0 | U10: =V10/P10 -> 0 | V10: =R10+T10 -> 0 | W10: =P10+V10 -> 12256 | X10: 12256 | Y10: =X10-P10 -> 0 | Z10: =ROUND(X10/P10-1,4) -> 0 | AA10: =IF(OR(N10=1,N10=2,N10=4), TEXT(U10*0.8,"0.00%") & "-" & TEXT(U10*1.2,"0.00%"), IF(OR(N10=3,N10=6), TEXT(0,"0.00%") & "-" & TEXT(7%*1.2,"0.00%"), IF(OR(N10=5,N10=7), TEXT((T10/P10),"0.00%") & "-" & TEXT((T10/P10)+7%,"0.00%"), "" ) ) ) -> 0.00%-0.00% | AF10: =ROUND(P10*AE10,0) -> 0 | AG10: =X10+AF10 -> 12256 | AH10: =AG10-P10 -> 0 | AI10: =AG10/P10-1 -> 0 | AJ10: 14 | AK10: 450 | AM10: 688 | AN10: =AG10*AJ10+AK10*12+AM10+IF(AD10="",AL10,IF(AD10="D",5000,IF(AD10="C",1000,0)))*12 -> 177672 | AO10: 3 | AS10: Miao Siyuan（15005811） | AT10: Zhu Qianqian（11016705） | AU10: Zhao Chujun | AY10: =_xlfn.LET(_xlpm.actual,Z10,_xlpm.low,VALUE(_xlfn.TEXTBEFORE(AA10,"-")),_xlpm.high,VALUE(_xlfn.TEXTAFTER(AA10,"-")),IF(AND(_xlpm.actual=0,OR(_xlpm.low<>0,_xlpm.high<>0)),"0 increase",IF(_xlpm.actual>_xlpm.high*1.2,">20",IF(_xlpm.actual<_xlpm.low*0.8,"<20","OK")))) -> OK
A11: CN15 | B11: 15014810 | C11: 朱 菊香 | D11: Zhu Juxiang | E11: Indirect Active | F11: OP | G11: SNa | H11: FCGNa-VVE | I11: 330404 | J11: 42248 | K11: Senior Specialist | L11: Senior IE Specialist | M11: BAND A5 | N11: 2 | O11: 4 | P11: 11666 | Q11: 0.0375 | R11: =ROUND(P11*Q11,0) -> 437 | S11: 0.0155 | T11: =ROUND(P11*S11,0) -> 181 | U11: =V11/P11 -> 0.052974456 | V11: =R11+T11 -> 618 | W11: =P11+V11 -> 12284 | X11: 12312 | Y11: =X11-P11 -> 646 | Z11: =ROUND(X11/P11-1,4) -> 0.0554 | AA11: =IF(OR(N11=1,N11=2,N11=4), TEXT(U11*0.8,"0.00%") & "-" & TEXT(U11*1.2,"0.00%"), IF(OR(N11=3,N11=6), TEXT(0,"0.00%") & "-" & TEXT(7%*1.2,"0.00%"), IF(OR(N11=5,N11=7), TEXT((T11/P11),"0.00%") & "-" & TEXT((T11/P11)+7%,"0.00%"), "" ) ) ) -> 4.24%-6.36% | AB11: Promotion | AC11: Function specialist | AD11: A6 | AE11: 0.0646 | AF11: =ROUND(P11*AE11,0) -> 754 | AG11: =X11+AF11 -> 13066 | AH11: =AG11-P11 -> 1400 | AI11: =AG11/P11-1 -> 0.12000686 | AJ11: 14 | AK11: 550 | AM11: 688 | AN11: =AG11*AJ11+AK11*12+AM11+IF(AD11="",AL11,IF(AD11="D",5000,IF(AD11="C",1000,0)))*12 -> 190212 | AO11: 4 | AQ11: Good performance and high competence | AR11: Good performance and high competence | AS11: Miao Siyuan（15005811） | AT11: Zhu Qianqian（11016705） | AU11: Zhao Chujun | AY11: =_xlfn.LET(_xlpm.actual,Z11,_xlpm.low,VALUE(_xlfn.TEXTBEFORE(AA11,"-")),_xlpm.high,VALUE(_xlfn.TEXTAFTER(AA11,"-")),IF(AND(_xlpm.actual=0,OR(_xlpm.low<>0,_xlpm.high<>0)),"0 increase",IF(_xlpm.actual>_xlpm.high*1.2,">20",IF(_xlpm.actual<_xlpm.low*0.8,"<20","OK")))) -> OK
A12: CN15 | B12: 15000226 | C12: 江 兵 | D12: Jiang Bing | E12: Indirect Active | F12: OP | G12: SNa | H12: FCGNa-VCP | I12: 330405 | J12: 38614 | K12: Workshop Leader | L12: Head of FCGNa-VCP | M12: BAND A6 | N12: 2 | O12: 3 | P12: 15800 | Q12: 0.025 | R12: =ROUND(P12*Q12,0) -> 395 | S12: 0 | T12: =ROUND(P12*S12,0) -> 0 | U12: =V12/P12 -> 0.025 | V12: =R12+T12 -> 395 | W12: =P12+V12 -> 16195 | X12: 16272 | Y12: =X12-P12 -> 472 | Z12: =ROUND(X12/P12-1,4) -> 0.0299 | AA12: =IF(OR(N12=1,N12=2,N12=4), TEXT(U12*0.8,"0.00%") & "-" & TEXT(U12*1.2,"0.00%"), IF(OR(N12=3,N12=6), TEXT(0,"0.00%") & "-" & TEXT(7%*1.2,"0.00%"), IF(OR(N12=5,N12=7), TEXT((T12/P12),"0.00%") & "-" & TEXT((T12/P12)+7%,"0.00%"), "" ) ) ) -> 2.00%-3.00% | AF12: =ROUND(P12*AE12,0) -> 0 | AG12: =X12+AF12 -> 16272 | AH12: =AG12-P12 -> 472 | AI12: =AG12/P12-1 -> 0.029873418 | AJ12: 14 | AK12: 450 | AM12: 688 | AN12: =AG12*AJ12+AK12*12+AM12+IF(AD12="",AL12,IF(AD12="D",5000,IF(AD12="C",1000,0)))*12 -> 233896 | AO12: 5 | AS12: Liu Haigang（15013255） | AT12: Zhu Qianqian（11016705） | AU12: Zhao Chujun | AY12: =_xlfn.LET(_xlpm.actual,Z12,_xlpm.low,VALUE(_xlfn.TEXTBEFORE(AA12,"-")),_xlpm.high,VALUE(_xlfn.TEXTAFTER(AA12,"-")),IF(AND(_xlpm.actual=0,OR(_xlpm.low<>0,_xlpm.high<>0)),"0 increase",IF(_xlpm.actual>_xlpm.high*1.2,">20",IF(_xlpm.actual<_xlpm.low*0.8,"<20","OK")))) -> OK
A13: CN15 | B13: 15000166 | C13: 蒋 莹 | D13: Jiang Ying | E13: Indirect Active | F13: OP | G13: SNa | H13: FCGNa-VCE | I13: 330405 | J13: 38600 | K13: Senior Engineer | L13: Senior Engineer | M13: BAND A5 | N13: 2 | O13: 3 | P13: 14610 | Q13: 0.025 | R13: =ROUND(P13*Q13,0) -> 365 | S13: 0 | T13: =ROUND(P13*S13,0) -> 0 | U13: =V13/P13 -> 0.024982888 | V13: =R13+T13 -> 365 | W13: =P13+V13 -> 14975 | X13: 14610 | Y13: =X13-P13 -> 0 | Z13: =ROUND(X13/P13-1,4) -> 0 | AA13: =IF(OR(N13=1,N13=2,N13=4), TEXT(U13*0.8,"0.00%") & "-" & TEXT(U13*1.2,"0.00%"), IF(OR(N13=3,N13=6), TEXT(0,"0.00%") & "-" & TEXT(7%*1.2,"0.00%"), IF(OR(N13=5,N13=7), TEXT((T13/P13),"0.00%") & "-" & TEXT((T13/P13)+7%,"0.00%"), "" ) ) ) -> 2.00%-3.00% | AF13: =ROUND(P13*AE13,0) -> 0 | AG13: =X13+AF13 -> 14610 | AH13: =AG13-P13 -> 0 | AI13: =AG13/P13-1 -> 0 | AJ13: 14 | AK13: 450 | AM13: 688 | AN13: =AG13*AJ13+AK13*12+AM13+IF(AD13="",AL13,IF(AD13="D",5000,IF(AD13="C",1000,0)))*12 -> 210628 | AO13: 3 | AQ13: Only focus on route tasks, lack of innovation and new product maturity improvement | AR13: Less responsibility compare with job level | AS13: Liu Haigang（15013255） | AT13: Zhu Qianqian（11016705） | AU13: Zhao Chujun | AW13: recommend increasing but propose zero increase | AY13: =_xlfn.LET(_xlpm.actual,Z13,_xlpm.low,VALUE(_xlfn.TEXTBEFORE(AA13,"-")),_xlpm.high,VALUE(_xlfn.TEXTAFTER(AA13,"-")),IF(AND(_xlpm.actual=0,OR(_xlpm.low<>0,_xlpm.high<>0)),"0 increase",IF(_xlpm.actual>_xlpm.high*1.2,">20",IF(_xlpm.actual<_xlpm.low*0.8,"<20","OK")))) -> 0 increase
A14: CN15 | B14: 15007522 | C14: 刘 栋 | D14: Liu Dong | E14: Indirect Active | F14: OP | G14: SNa | H14: FCGNa-VCE | I14: 330405 | J14: 41091 | K14: Supervisor | L14: Head of FCGNa-VCE | M14: BAND A6 | N14: 2 | O14: 3 | P14: 13100 | Q14: 0.03 | R14: =ROUND(P14*Q14,0) -> 393 | S14: 0 | T14: =ROUND(P14*S14,0) -> 0 | U14: =V14/P14 -> 0.03 | V14: =R14+T14 -> 393 | W14: =P14+V14 -> 13493 | X14: 14312 | Y14: =X14-P14 -> 1212 | Z14: =ROUND(X14/P14-1,4) -> 0.0925 | AA14: =IF(OR(N14=1,N14=2,N14=4), TEXT(U14*0.8,"0.00%") & "-" & TEXT(U14*1.2,"0.00%"), IF(OR(N14=3,N14=6), TEXT(0,"0.00%") & "-" & TEXT(7%*1.2,"0.00%"), IF(OR(N14=5,N14=7), TEXT((T14/P14),"0.00%") & "-" & TEXT((T14/P14)+7%,"0.00%"), "" ) ) ) -> 2.40%-3.60% | AF14: =ROUND(P14*AE14,0) -> 0 | AG14: =X14+AF14 -> 14312 | AH14: =AG14-P14 -> 1212 | AI14: =AG14/P14-1 -> 0.092519084 | AJ14: 14 | AK14: 450 | AM14: 688 | AN14: =AG14*AJ14+AK14*12+AM14+IF(AD14="",AL14,IF(AD14="D",5000,IF(AD14="C",1000,0)))*12 -> 206456 | AO14: 2 | AQ14: 1. In 2025, he achieved an 11% reduction in cooker SPC and cut silicone usage by 50%. 2. As a supervisor, his salary is the lowest in the team, so I need to catch up appropriately. | AR14: Good performers with relatively lower salary | AS14: Liu Haigang（15013255） | AT14: Zhu Qianqian（11016705） | AU14: Zhao Chujun | AW14: exceed +/-20% adjustment | AX14: >20 | AY14: =_xlfn.LET(_xlpm.actual,Z14,_xlpm.low,VALUE(_xlfn.TEXTBEFORE(AA14,"-")),_xlpm.high,VALUE(_xlfn.TEXTAFTER(AA14,"-")),IF(AND(_xlpm.actual=0,OR(_xlpm.low<>0,_xlpm.high<>0)),"0 increase",IF(_xlpm.actual>_xlpm.high*1.2,">20",IF(_xlpm.actual<_xlpm.low*0.8,"<20","OK")))) -> >20
A15: CN15 | B15: 15001471 | C15: 马 爱军 | D15: Ma Aijun | E15: Indirect Active | F15: OP | G15: SNa | H15: FCGNa-VCM | I15: 330405 | J15: 39546 | K15: Supervisor | L15: Head of FCGNa-VCM | M15: BAND A6 | N15: 2 | O15: 3 | P15: 15326 | Q15: 0.03 | R15: =ROUND(P15*Q15,0) -> 460 | S15: 0 | T15: =ROUND(P15*S15,0) -> 0 | U15: =V15/P15 -> 0.030014355 | V15: =R15+T15 -> 460 | W15: =P15+V15 -> 15786 | X15: 15326 | Y15: =X15-P15 -> 0 | Z15: =ROUND(X15/P15-1,4) -> 0 | AA15: =IF(OR(N15=1,N15=2,N15=4), TEXT(U15*0.8,"0.00%") & "-" & TEXT(U15*1.2,"0.00%"), IF(OR(N15=3,N15=6), TEXT(0,"0.00%") & "-" & TEXT(7%*1.2,"0.00%"), IF(OR(N15=5,N15=7), TEXT((T15/P15),"0.00%") & "-" & TEXT((T15/P15)+7%,"0.00%"), "" ) ) ) -> 2.40%-3.60% | AF15: =ROUND(P15*AE15,0) -> 0 | AG15: =X15+AF15 -> 15326 | AH15: =AG15-P15 -> 0 | AI15: =AG15/P15-1 -> 0 | AJ15: 14 | AK15: 450 | AM15: 688 | AN15: =AG15*AJ15+AK15*12+AM15+IF(AD15="",AL15,IF(AD15="D",5000,IF(AD15="C",1000,0)))*12 -> 220652 | AO15: 4 | AQ15: Low performance as supervisor | AR15: Low performer | AS15: Liu Haigang（15013255） | AT15: Zhu Qianqian（11016705） | AU15: Zhao Chujun | AW15: recommend increasing but propose zero increase | AY15: =_xlfn.LET(_xlpm.actual,Z15,_xlpm.low,VALUE(_xlfn.TEXTBEFORE(AA15,"-")),_xlpm.high,VALUE(_xlfn.TEXTAFTER(AA15,"-")),IF(AND(_xlpm.actual=0,OR(_xlpm.low<>0,_xlpm.high<>0)),"0 increase",IF(_xlpm.actual>_xlpm.high*1.2,">20",IF(_xlpm.actual<_xlpm.low*0.8,"<20","OK")))) -> 0 increase
A16: CN15 | B16: 15022189 | C16: 张 林波 | D16: Zhang Linbo | E16: Indirect Active | F16: OP | G16: SNa | H16: FCGNa-VCE | I16: 330401 | J16: 44713 | K16: Senior Engineer | L16: Press Senior Engineer | M16: BAND A5 | N16: 2 | O16: 3 | P16: 14850 | Q16: 0.025 | R16: =ROUND(P16*Q16,0) -> 371 | S16: 0 | T16: =ROUND(P16*S16,0) -> 0 | U16: =V16/P16 -> 0.024983165 | V16: =R16+T16 -> 371 | W16: =P16+V16 -> 15221 | X16: 15150 | Y16: =X16-P16 -> 300 | Z16: =ROUND(X16/P16-1,4) -> 0.0202 | AA16: =IF(OR(N16=1,N16=2,N16=4), TEXT(U16*0.8,"0.00%") & "-" & TEXT(U16*1.2,"0.00%"), IF(OR(N16=3,N16=6), TEXT(0,"0.00%") & "-" & TEXT(7%*1.2,"0.00%"), IF(OR(N16=5,N16=7), TEXT((T16/P16),"0.00%") & "-" & TEXT((T16/P16)+7%,"0.00%"), "" ) ) ) -> 2.00%-3.00% | AF16: =ROUND(P16*AE16,0) -> 0 | AG16: =X16+AF16 -> 15150 | AH16: =AG16-P16 -> 300 | AI16: =AG16/P16-1 -> 0.02020202 | AJ16: 14 | AK16: 450 | AM16: 688 | AN16: =AG16*AJ16+AK16*12+AM16+IF(AD16="",AL16,IF(AD16="D",5000,IF(AD16="C",1000,0)))*12 -> 218188 | AO16: 3 | AS16: Liu Haigang（15013255） | AT16: Zhu Qianqian（11016705） | AU16: Zhao Chujun | AY16: =_xlfn.LET(_xlpm.actual,Z16,_xlpm.low,VALUE(_xlfn.TEXTBEFORE(AA16,"-")),_xlpm.high,VALUE(_xlfn.TEXTAFTER(AA16,"-")),IF(AND(_xlpm.actual=0,OR(_xlpm.low<>0,_xlpm.high<>0)),"0 increase",IF(_xlpm.actual>_xlpm.high*1.2,">20",IF(_xlpm.actual<_xlpm.low*0.8,"<20","OK")))) -> OK
A17: CN15 | B17: 15017481 | C17: 赵 磊 | D17: Zhao Lei | E17: Indirect Active | F17: OP | G17: SNa | H17: FCGNa-VCE | I17: 330405 | J17: 42893 | K17: Senior Engineer | L17: Senior Engineer | M17: BAND A5 | N17: 2 | O17: 2 | P17: 13610 | Q17: 0 | R17: =ROUND(P17*Q17,0) -> 0 | S17: 0 | T17: =ROUND(P17*S17,0) -> 0 | U17: =V17/P17 -> 0 | V17: =R17+T17 -> 0 | W17: =P17+V17 -> 13610 | X17: 13610 | Y17: =X17-P17 -> 0 | Z17: =ROUND(X17/P17-1,4) -> 0 | AA17: =IF(OR(N17=1,N17=2,N17=4), TEXT(U17*0.8,"0.00%") & "-" & TEXT(U17*1.2,"0.00%"), IF(OR(N17=3,N17=6), TEXT(0,"0.00%") & "-" & TEXT(7%*1.2,"0.00%"), IF(OR(N17=5,N17=7), TEXT((T17/P17),"0.00%") & "-" & TEXT((T17/P17)+7%,"0.00%"), "" ) ) ) -> 0.00%-0.00% | AF17: =ROUND(P17*AE17,0) -> 0 | AG17: =X17+AF17 -> 13610 | AH17: =AG17-P17 -> 0 | AI17: =AG17/P17-1 -> 0 | AJ17: 14 | AK17: 550 | AM17: 688 | AN17: =AG17*AJ17+AK17*12+AM17+IF(AD17="",AL17,IF(AD17="D",5000,IF(AD17="C",1000,0)))*12 -> 197828 | AO17: 3 | AS17: Liu Haigang（15013255） | AT17: Zhu Qianqian（11016705） | AU17: Zhao Chujun | AY17: =_xlfn.LET(_xlpm.actual,Z17,_xlpm.low,VALUE(_xlfn.TEXTBEFORE(AA17,"-")),_xlpm.high,VALUE(_xlfn.TEXTAFTER(AA17,"-")),IF(AND(_xlpm.actual=0,OR(_xlpm.low<>0,_xlpm.high<>0)),"0 increase",IF(_xlpm.actual>_xlpm.high*1.2,">20",IF(_xlpm.actual<_xlpm.low*0.8,"<20","OK")))) -> OK
A18: CN15 | B18: 15014900 | C18: 李 辉祥 | D18: Li Huixiang | E18: Indirect Active | F18: OP | G18: SNa | H18: FCGNa | I18: 330100 | J18: 42298 | K18: Manager | L18: Manager | M18: BAND B | N18: 2 | O18: 2 | P18: 20200 | Q18: 0 | R18: =ROUND(P18*Q18,0) -> 0 | S18: 0 | T18: =ROUND(P18*S18,0) -> 0 | U18: =V18/P18 -> 0 | V18: =R18+T18 -> 0 | W18: =P18+V18 -> 20200 | X18: =W18 -> 20200 | Y18: =X18-P18 -> 0 | Z18: =ROUND(X18/P18-1,4) -> 0 | AA18: =IF(OR(N18=1,N18=2,N18=4), TEXT(U18*0.8,"0.00%") & "-" & TEXT(U18*1.2,"0.00%"), IF(OR(N18=3,N18=6), TEXT(0,"0.00%") & "-" & TEXT(7%*1.2,"0.00%"), IF(OR(N18=5,N18=7), TEXT((T18/P18),"0.00%") & "-" & TEXT((T18/P18)+7%,"0.00%"), "" ) ) ) -> 0.00%-0.00% | AF18: =ROUND(P18*AE18,0) -> 0 | AG18: =X18+AF18 -> 20200 | AH18: =AG18-P18 -> 0 | AI18: =AG18/P18-1 -> 0 | AJ18: 14 | AK18: 450 | AM18: 688 | AN18: =AG18*AJ18+AK18*12+AM18+IF(AD18="",AL18,IF(AD18="D",5000,IF(AD18="C",1000,0)))*12 -> 288888 | AO18: 3 | AS18: Chen Chao（15005032） | AT18: Zhu Qianqian（11016705） | AU18: Zhao Chujun | AY18: =_xlfn.LET(_xlpm.actual,Z18,_xlpm.low,VALUE(_xlfn.TEXTBEFORE(AA18,"-")),_xlpm.high,VALUE(_xlfn.TEXTAFTER(AA18,"-")),IF(AND(_xlpm.actual=0,OR(_xlpm.low<>0,_xlpm.high<>0)),"0 increase",IF(_xlpm.actual>_xlpm.high*1.2,">20",IF(_xlpm.actual<_xlpm.low*0.8,"<20","OK")))) -> OK
A19: CN15 | B19: 15013255 | C19: 刘 海刚 | D19: Liu Haigang | E19: Indirect Active | F19: OP | G19: SNa | H19: FCGNa-VC | I19: 330405 | J19: 41801 | K19: Manager | L19: Head of Value Stream Cooktop | M19: BAND B | N19: 2 | O19: 4 | P19: 23800 | Q19: 0.03 | R19: =ROUND(P19*Q19,0) -> 714 | S19: 0 | T19: =ROUND(P19*S19,0) -> 0 | U19: =V19/P19 -> 0.03 | V19: =R19+T19 -> 714 | W19: =P19+V19 -> 24514 | X19: =W19 -> 24514 | Y19: =X19-P19 -> 714 | Z19: =ROUND(X19/P19-1,4) -> 0.03 | AA19: =IF(OR(N19=1,N19=2,N19=4), TEXT(U19*0.8,"0.00%") & "-" & TEXT(U19*1.2,"0.00%"), IF(OR(N19=3,N19=6), TEXT(0,"0.00%") & "-" & TEXT(7%*1.2,"0.00%"), IF(OR(N19=5,N19=7), TEXT((T19/P19),"0.00%") & "-" & TEXT((T19/P19)+7%,"0.00%"), "" ) ) ) -> 2.40%-3.60% | AB19: Promotion | AC19: Head of Value Stream Cooktop | AD19: C | AE19: 0.09 | AF19: =ROUND(P19*AE19,0) -> 2142 | AG19: =X19+AF19 -> 26656 | AH19: =AG19-P19 -> 2856 | AI19: =AG19/P19-1 -> 0.12 | AJ19: 14 | AK19: 450 | AM19: 688 | AN19: =AG19*AJ19+AK19*12+AM19+IF(AD19="",AL19,IF(AD19="D",5000,IF(AD19="C",1000,0)))*12 -> 391272 | AO19: 5 | AQ19: Good performance and high competence | AR19: Good performance and high competence | AS19: Chen Chao（15005032） | AT19: Zhu Qianqian（11016705） | AU19: Zhao Chujun | AY19: =_xlfn.LET(_xlpm.actual,Z19,_xlpm.low,VALUE(_xlfn.TEXTBEFORE(AA19,"-")),_xlpm.high,VALUE(_xlfn.TEXTAFTER(AA19,"-")),IF(AND(_xlpm.actual=0,OR(_xlpm.low<>0,_xlpm.high<>0)),"0 increase",IF(_xlpm.actual>_xlpm.high*1.2,">20",IF(_xlpm.actual<_xlpm.low*0.8,"<20","OK")))) -> OK
A20: CN15 | B20: 15005811 | C20: 缪 思远 | D20: Miao Siyuan | E20: Indirect Active | F20: OP | G20: SNa | H20: FCGNa-VV | I20: 330404 | J20: 40646 | K20: Manager | L20: Head of Value Stream Ventilation | M20: BAND B | N20: 2 | O20: 5 | P20: 24500 | Q20: 0.04 | R20: =ROUND(P20*Q20,0) -> 980 | S20: 0 | T20: =ROUND(P20*S20,0) -> 0 | U20: =V20/P20 -> 0.04 | V20: =R20+T20 -> 980 | W20: =P20+V20 -> 25480 | X20: =W20 -> 25480 | Y20: =X20-P20 -> 980 | Z20: =ROUND(X20/P20-1,4) -> 0.04 | AA20: =IF(OR(N20=1,N20=2,N20=4), TEXT(U20*0.8,"0.00%") & "-" & TEXT(U20*1.2,"0.00%"), IF(OR(N20=3,N20=6), TEXT(0,"0.00%") & "-" & TEXT(7%*1.2,"0.00%"), IF(OR(N20=5,N20=7), TEXT((T20/P20),"0.00%") & "-" & TEXT((T20/P20)+7%,"0.00%"), "" ) ) ) -> 3.20%-4.80% | AB20: Promotion | AC20: Head of Value Stream Ventilation | AD20: C | AE20: 0.08 | AF20: =ROUND(P20*AE20,0) -> 1960 | AG20: =X20+AF20 -> 27440 | AH20: =AG20-P20 -> 2940 | AI20: =AG20/P20-1 -> 0.12 | AJ20: 14 | AK20: 450 | AM20: 688 | AN20: =AG20*AJ20+AK20*12+AM20+IF(AD20="",AL20,IF(AD20="D",5000,IF(AD20="C",1000,0)))*12 -> 402248 | AO20: 3 | AQ20: Good performance and high competence | AR20: Good performance and high competence | AS20: Chen Chao（15005032） | AT20: Zhu Qianqian（11016705） | AU20: Zhao Chujun | AY20: =_xlfn.LET(_xlpm.actual,Z20,_xlpm.low,VALUE(_xlfn.TEXTBEFORE(AA20,"-")),_xlpm.high,VALUE(_xlfn.TEXTAFTER(AA20,"-")),IF(AND(_xlpm.actual=0,OR(_xlpm.low<>0,_xlpm.high<>0)),"0 increase",IF(_xlpm.actual>_xlpm.high*1.2,">20",IF(_xlpm.actual<_xlpm.low*0.8,"<20","OK")))) -> OK
A21: CN15 | B21: 15022316 | C21: 孙 超 | D21: Sun Chao | E21: Indirect Active | F21: OP | G21: SNa | H21: FCGNa | I21: 330100 | J21: 44930 | K21: Senior Engineer | L21: Senior Testing and Programming Engineer | M21: BAND A5 | N21: 2 | O21: 3 | P21: 14375 | Q21: 0.025 | R21: =ROUND(P21*Q21,0) -> 359 | S21: 0 | T21: =ROUND(P21*S21,0) -> 0 | U21: =V21/P21 -> 0.024973913 | V21: =R21+T21 -> 359 | W21: =P21+V21 -> 14734 | X21: =W21 -> 14734 | Y21: =X21-P21 -> 359 | Z21: =ROUND(X21/P21-1,4) -> 0.025 | AA21: =IF(OR(N21=1,N21=2,N21=4), TEXT(U21*0.8,"0.00%") & "-" & TEXT(U21*1.2,"0.00%"), IF(OR(N21=3,N21=6), TEXT(0,"0.00%") & "-" & TEXT(7%*1.2,"0.00%"), IF(OR(N21=5,N21=7), TEXT((T21/P21),"0.00%") & "-" & TEXT((T21/P21)+7%,"0.00%"), "" ) ) ) -> 2.00%-3.00% | AF21: =ROUND(P21*AE21,0) -> 0 | AG21: =X21+AF21 -> 14734 | AH21: =AG21-P21 -> 359 | AI21: =AG21/P21-1 -> 0.024973913 | AJ21: 14 | AK21: 450 | AM21: 688 | AN21: =AG21*AJ21+AK21*12+AM21+IF(AD21="",AL21,IF(AD21="D",5000,IF(AD21="C",1000,0)))*12 -> 212364 | AO21: 4 | AS21: Chen Chao（15005032） | AT21: Zhu Qianqian（11016705） | AU21: Zhao Chujun | AY21: =_xlfn.LET(_xlpm.actual,Z21,_xlpm.low,VALUE(_xlfn.TEXTBEFORE(AA21,"-")),_xlpm.high,VALUE(_xlfn.TEXTAFTER(AA21,"-")),IF(AND(_xlpm.actual=0,OR(_xlpm.low<>0,_xlpm.high<>0)),"0 increase",IF(_xlpm.actual>_xlpm.high*1.2,">20",IF(_xlpm.actual<_xlpm.low*0.8,"<20","OK")))) -> OK
A22: CN15 | B22: 15001764 | C22: 张 利利 | D22: Zhang Lili | E22: Indirect Active | F22: OP | G22: SNa | H22: FCGNa | I22: 330100 | J22: 40360 | K22: Senior Engineer | L22: Senior Engineer | M22: BAND A5 | N22: 2 | O22: 4 | P22: 9891 | Q22: 0.045 | R22: =ROUND(P22*Q22,0) -> 445 | S22: 0.0421 | T22: =ROUND(P22*S22,0) -> 416 | U22: =V22/P22 -> 0.087048832 | V22: =R22+T22 -> 861 | W22: =P22+V22 -> 10752 | X22: =W22 -> 10752 | Y22: =X22-P22 -> 861 | Z22: =ROUND(X22/P22-1,4) -> 0.087 | AA22: =IF(OR(N22=1,N22=2,N22=4), TEXT(U22*0.8,"0.00%") & "-" & TEXT(U22*1.2,"0.00%"), IF(OR(N22=3,N22=6), TEXT(0,"0.00%") & "-" & TEXT(7%*1.2,"0.00%"), IF(OR(N22=5,N22=7), TEXT((T22/P22),"0.00%") & "-" & TEXT((T22/P22)+7%,"0.00%"), "" ) ) ) -> 6.96%-10.45% | AF22: =ROUND(P22*AE22,0) -> 0 | AG22: =X22+AF22 -> 10752 | AH22: =AG22-P22 -> 861 | AI22: =AG22/P22-1 -> 0.087048832 | AJ22: 14 | AK22: 450 | AM22: 688 | AN22: =AG22*AJ22+AK22*12+AM22+IF(AD22="",AL22,IF(AD22="D",5000,IF(AD22="C",1000,0)))*12 -> 156616 | AO22: 3 | AS22: Chen Chao（15005032） | AT22: Zhu Qianqian（11016705） | AU22: Zhao Chujun | AY22: =_xlfn.LET(_xlpm.actual,Z22,_xlpm.low,VALUE(_xlfn.TEXTBEFORE(AA22,"-")),_xlpm.high,VALUE(_xlfn.TEXTAFTER(AA22,"-")),IF(AND(_xlpm.actual=0,OR(_xlpm.low<>0,_xlpm.high<>0)),"0 increase",IF(_xlpm.actual>_xlpm.high*1.2,">20",IF(_xlpm.actual<_xlpm.low*0.8,"<20","OK")))) -> OK
A23: CN15 | B23: 15022180 | C23: 陈 邢逸 | D23: Chen Xingyi | E23: Indirect Active | F23: OP | G23: SNa | H23: FEDNa-MEP | I23: 370200 | J23: 44686 | K23: Engineer | L23: Process Engineer | M23: BAND A4 | N23: 2 | O23: 3 | P23: 8200 | Q23: 0.025 | R23: =ROUND(P23*Q23,0) -> 205 | S23: 0 | T23: =ROUND(P23*S23,0) -> 0 | U23: =V23/P23 -> 0.025 | V23: =R23+T23 -> 205 | W23: =P23+V23 -> 8405 | X23: 8415 | Y23: =X23-P23 -> 215 | Z23: =ROUND(X23/P23-1,4) -> 0.0262 | AA23: =IF(OR(N23=1,N23=2,N23=4),TEXT(U23*0.8,"0.00%")&"-"&TEXT(U23*1.2,"0.00%"),IF(OR(N23=3,N23=6),TEXT(0,"0.00%")&"-"&TEXT(7%*1.2,"0.00%"),IF(OR(N23=5,N23=7),TEXT((T23/P23),"0.00%")&"-"&TEXT((T23/P23)+7%,"0.00%"),""))) -> 2.00%-3.00% | AF23: =ROUND(P23*AE23,0) -> 0 | AG23: =X23+AF23 -> 8415 | AH23: =AG23-P23 -> 215 | AI23: =AG23/P23-1 -> 0.026219512 | AJ23: 14 | AK23: 550 | AM23: 688 | AN23: =AG23*AJ23+AK23*12+AM23+IF(AD23="",AL23,IF(AD23="D",5000,IF(AD23="C",1000,0)))*12 -> 125098 | AO23: 3 | AS23: Ding Xudong（15000307） | AT23: Xu Lan（11013544） | AU23: Zhao Chujun | AY23: =_xlfn.LET(_xlpm.actual,Z23,_xlpm.low,VALUE(_xlfn.TEXTBEFORE(AA23,"-")),_xlpm.high,VALUE(_xlfn.TEXTAFTER(AA23,"-")),IF(AND(_xlpm.actual=0,OR(_xlpm.low<>0,_xlpm.high<>0)),"0 increase",IF(_xlpm.actual>_xlpm.high*1.2,">20",IF(_xlpm.actual<_xlpm.low*0.8,"<20","OK")))) -> OK
A24: CN15 | B24: 15003790 | C24: 方 红祥 | D24: Fang Hongxiang | E24: Indirect Active | F24: OP | G24: SNa | H24: FEDNa-MEM | I24: 370201 | J24: 40310 | K24: Supervisor | L24: Head of Mechanical Support | M24: BAND A6 | N24: 2 | O24: 3 | P24: 15324 | Q24: 0.03 | R24: =ROUND(P24*Q24,0) -> 460 | S24: 0 | T24: =ROUND(P24*S24,0) -> 0 | U24: =V24/P24 -> 0.030018272 | V24: =R24+T24 -> 460 | W24: =P24+V24 -> 15784 | X24: 15600 | Y24: =X24-P24 -> 276 | Z24: =ROUND(X24/P24-1,4) -> 0.018 | AA24: =IF(OR(N24=1,N24=2,N24=4),TEXT(U24*0.8,"0.00%")&"-"&TEXT(U24*1.2,"0.00%"),IF(OR(N24=3,N24=6),TEXT(0,"0.00%")&"-"&TEXT(7%*1.2,"0.00%"),IF(OR(N24=5,N24=7),TEXT((T24/P24),"0.00%")&"-"&TEXT((T24/P24)+7%,"0.00%"),""))) -> 2.40%-3.60% | AF24: =ROUND(P24*AE24,0) -> 0 | AG24: =X24+AF24 -> 15600 | AH24: =AG24-P24 -> 276 | AI24: =AG24/P24-1 -> 0.018010963 | AJ24: 14 | AK24: 450 | AM24: 688 | AN24: =AG24*AJ24+AK24*12+AM24+IF(AD24="",AL24,IF(AD24="D",5000,IF(AD24="C",1000,0)))*12 -> 224488 | AO24: 3 | AR24: Internal balance | AS24: Ding Xudong（15000307） | AT24: Xu Lan（11013544） | AU24: Zhao Chujun | AW24: exceed +/-20% adjustment | AX24: <20 | AY24: =_xlfn.LET(_xlpm.actual,Z24,_xlpm.low,VALUE(_xlfn.TEXTBEFORE(AA24,"-")),_xlpm.high,VALUE(_xlfn.TEXTAFTER(AA24,"-")),IF(AND(_xlpm.actual=0,OR(_xlpm.low<>0,_xlpm.high<>0)),"0 increase",IF(_xlpm.actual>_xlpm.high*1.2,">20",IF(_xlpm.actual<_xlpm.low*0.8,"<20","OK")))) -> <20
A25: CN15 | B25: 15016330 | C25: 何 磊 | D25: He Lei | E25: Indirect Active | F25: OP | G25: SNa | H25: FEDNa-V2 | I25: 370400 | J25: 42781 | K25: Manager | L25: Head of FEDNa-V2 | M25: BAND B | N25: 2 | O25: 4 | P25: 20300 | Q25: 0.0375 | R25: =ROUND(P25*Q25,0) -> 761 | S25: 0.0155 | T25: =ROUND(P25*S25,0) -> 315 | U25: =V25/P25 -> 0.053004926 | V25: =R25+T25 -> 1076 | W25: =P25+V25 -> 21376 | X25: 21500 | Y25: =X25-P25 -> 1200 | Z25: =ROUND(X25/P25-1,4) -> 0.0591 | AA25: =IF(OR(N25=1,N25=2,N25=4),TEXT(U25*0.8,"0.00%")&"-"&TEXT(U25*1.2,"0.00%"),IF(OR(N25=3,N25=6),TEXT(0,"0.00%")&"-"&TEXT(7%*1.2,"0.00%"),IF(OR(N25=5,N25=7),TEXT((T25/P25),"0.00%")&"-"&TEXT((T25/P25)+7%,"0.00%"),""))) -> 4.24%-6.36% | AF25: =ROUND(P25*AE25,0) -> 0 | AG25: =X25+AF25 -> 21500 | AH25: =AG25-P25 -> 1200 | AI25: =AG25/P25-1 -> 0.0591133 | AJ25: 14 | AK25: 450 | AM25: 688 | AN25: =AG25*AJ25+AK25*12+AM25+IF(AD25="",AL25,IF(AD25="D",5000,IF(AD25="C",1000,0)))*12 -> 307088 | AO25: 3 | AS25: Ding Xudong（15000307） | AT25: Xu Lan（11013544） | AU25: Zhao Chujun | AY25: =_xlfn.LET(_xlpm.actual,Z25,_xlpm.low,VALUE(_xlfn.TEXTBEFORE(AA25,"-")),_xlpm.high,VALUE(_xlfn.TEXTAFTER(AA25,"-")),IF(AND(_xlpm.actual=0,OR(_xlpm.low<>0,_xlpm.high<>0)),"0 increase",IF(_xlpm.actual>_xlpm.high*1.2,">20",IF(_xlpm.actual<_xlpm.low*0.8,"<20","OK")))) -> OK
A26: CN15 | B26: 15001485 | C26: 李 新华 | D26: Li Xinhua | E26: Indirect Active | F26: OP | G26: SNa | H26: FEDNa-ME | I26: 370200 | J26: 39547 | K26: Manager | L26: Head of Manufacturing Engineering | M26: BAND B | N26: 2 | O26: 3 | P26: 27011 | Q26: 0.025 | R26: =ROUND(P26*Q26,0) -> 675 | S26: 0 | T26: =ROUND(P26*S26,0) -> 0 | U26: =V26/P26 -> 0.024989819 | V26: =R26+T26 -> 675 | W26: =P26+V26 -> 27686 | X26: 27700 | Y26: =X26-P26 -> 689 | Z26: =ROUND(X26/P26-1,4) -> 0.0255 | AA26: =IF(OR(N26=1,N26=2,N26=4),TEXT(U26*0.8,"0.00%")&"-"&TEXT(U26*1.2,"0.00%"),IF(OR(N26=3,N26=6),TEXT(0,"0.00%")&"-"&TEXT(7%*1.2,"0.00%"),IF(OR(N26=5,N26=7),TEXT((T26/P26),"0.00%")&"-"&TEXT((T26/P26)+7%,"0.00%"),""))) -> 2.00%-3.00% | AF26: =ROUND(P26*AE26,0) -> 0 | AG26: =X26+AF26 -> 27700 | AH26: =AG26-P26 -> 689 | AI26: =AG26/P26-1 -> 0.025508126 | AJ26: 14 | AK26: 450 | AM26: 688 | AN26: =AG26*AJ26+AK26*12+AM26+IF(AD26="",AL26,IF(AD26="D",5000,IF(AD26="C",1000,0)))*12 -> 393888 | AO26: 4 | AS26: Ding Xudong（15000307） | AT26: Xu Lan（11013544） | AU26: Zhao Chujun | AY26: =_xlfn.LET(_xlpm.actual,Z26,_xlpm.low,VALUE(_xlfn.TEXTBEFORE(AA26,"-")),_xlpm.high,VALUE(_xlfn.TEXTAFTER(AA26,"-")),IF(AND(_xlpm.actual=0,OR(_xlpm.low<>0,_xlpm.high<>0)),"0 increase",IF(_xlpm.actual>_xlpm.high*1.2,">20",IF(_xlpm.actual<_xlpm.low*0.8,"<20","OK")))) -> OK
A27: CN15 | B27: 1020358 | C27: 刘 继萍 | D27: Liu Jiping | E27: Indirect Active | F27: OP | G27: SNa | H27: FEDNa-MEP | I27: 370200 | J27: 45000 | K27: Senior Engineer | L27: Senior Process Engineer | M27: BAND A5 | N27: 2 | O27: 5 | P27: 13610 | Q27: 0.05 | R27: =ROUND(P27*Q27,0) -> 681 | S27: 0.027 | T27: =ROUND(P27*S27,0) -> 367 | U27: =V27/P27 -> 0.077002204 | V27: =R27+T27 -> 1048 | W27: =P27+V27 -> 14658 | X27: 15000 | Y27: =X27-P27 -> 1390 | Z27: =ROUND(X27/P27-1,4) -> 0.1021 | AA27: =IF(OR(N27=1,N27=2,N27=4),TEXT(U27*0.8,"0.00%")&"-"&TEXT(U27*1.2,"0.00%"),IF(OR(N27=3,N27=6),TEXT(0,"0.00%")&"-"&TEXT(7%*1.2,"0.00%"),IF(OR(N27=5,N27=7),TEXT((T27/P27),"0.00%")&"-"&TEXT((T27/P27)+7%,"0.00%"),""))) -> 6.16%-9.24% | AF27: =ROUND(P27*AE27,0) -> 0 | AG27: =X27+AF27 -> 15000 | AH27: =AG27-P27 -> 1390 | AI27: =AG27/P27-1 -> 0.10213079 | AJ27: 14 | AK27: 450 | AM27: 688 | AN27: =AG27*AJ27+AK27*12+AM27+IF(AD27="",AL27,IF(AD27="D",5000,IF(AD27="C",1000,0)))*12 -> 216088 | AO27: 3 | AR27: Rounding | AS27: Ding Xudong（15000307） | AT27: Xu Lan（11013544） | AU27: Zhao Chujun | AW27: exceed +/-20% adjustment | AX27: >20 | AY27: =_xlfn.LET(_xlpm.actual,Z27,_xlpm.low,VALUE(_xlfn.TEXTBEFORE(AA27,"-")),_xlpm.high,VALUE(_xlfn.TEXTAFTER(AA27,"-")),IF(AND(_xlpm.actual=0,OR(_xlpm.low<>0,_xlpm.high<>0)),"0 increase",IF(_xlpm.actual>_xlpm.high*1.2,">20",IF(_xlpm.actual<_xlpm.low*0.8,"<20","OK")))) -> OK
A28: CN15 | B28: 15021547 | C28: 刘 彦达 | D28: Liu Yanda | E28: Indirect Active | F28: OP | G28: SNa | H28: FEDNa-MEP | I28: 370200 | J28: 44391 | K28: Engineer | L28: Electrical Engineer | M28: BAND A4 | N28: 2 | O28: 4 | P28: 10500 | Q28: 0.0375 | R28: =ROUND(P28*Q28,0) -> 394 | S28: 0 | T28: =ROUND(P28*S28,0) -> 0 | U28: =V28/P28 -> 0.03752381 | V28: =R28+T28 -> 394 | W28: =P28+V28 -> 10894 | X28: 10827 | Y28: =X28-P28 -> 327 | Z28: =ROUND(X28/P28-1,4) -> 0.0311 | AA28: =IF(OR(N28=1,N28=2,N28=4),TEXT(U28*0.8,"0.00%")&"-"&TEXT(U28*1.2,"0.00%"),IF(OR(N28=3,N28=6),TEXT(0,"0.00%")&"-"&TEXT(7%*1.2,"0.00%"),IF(OR(N28=5,N28=7),TEXT((T28/P28),"0.00%")&"-"&TEXT((T28/P28)+7%,"0.00%"),""))) -> 3.00%-4.50% | AB28: Promotion | AC28: senior engineer | AD28: A5 | AE28: 0.1117 | AF28: =ROUND(P28*AE28,0) -> 1173 | AG28: =X28+AF28 -> 12000 | AH28: =AG28-P28 -> 1500 | AI28: =AG28/P28-1 -> 0.14285714 | AJ28: 14 | AK28: 500 | AM28: 688 | AN28: =AG28*AJ28+AK28*12+AM28+IF(AD28="",AL28,IF(AD28="D",5000,IF(AD28="C",1000,0)))*12 -> 174688 | AO28: 3 | AR28: Good performance and high competence | AS28: Ding Xudong（15000307） | AT28: Xu Lan（11013544） | AU28: Zhao Chujun | AY28: =_xlfn.LET(_xlpm.actual,Z28,_xlpm.low,VALUE(_xlfn.TEXTBEFORE(AA28,"-")),_xlpm.high,VALUE(_xlfn.TEXTAFTER(AA28,"-")),IF(AND(_xlpm.actual=0,OR(_xlpm.low<>0,_xlpm.high<>0)),"0 increase",IF(_xlpm.actual>_xlpm.high*1.2,">20",IF(_xlpm.actual<_xlpm.low*0.8,"<20","OK")))) -> OK
A29: CN15 | B29: 15012913 | C29: 陆 彬 | D29: Lu Bin | E29: Indirect Active | F29: OP | G29: SNa | H29: FEDNa-ME | I29: 370200 | J29: 41738 | K29: Associate Expert (CN) | L29: Associate Expert (C) | M29: BAND A6 | N29: 2 | O29: 5 | P29: 16000 | Q29: 0.06 | R29: =ROUND(P29*Q29,0) -> 960 | S29: 0.0778 | T29: =ROUND(P29*S29,0) -> 1245 | U29: =V29/P29 -> 0.1378125 | V29: =R29+T29 -> 2205 | W29: =P29+V29 -> 18205 | X29: 18000 | Y29: =X29-P29 -> 2000 | Z29: =ROUND(X29/P29-1,4) -> 0.125 | AA29: =IF(OR(N29=1,N29=2,N29=4),TEXT(U29*0.8,"0.00%")&"-"&TEXT(U29*1.2,"0.00%"),IF(OR(N29=3,N29=6),TEXT(0,"0.00%")&"-"&TEXT(7%*1.2,"0.00%"),IF(OR(N29=5,N29=7),TEXT((T29/P29),"0.00%")&"-"&TEXT((T29/P29)+7%,"0.00%"),""))) -> 11.03%-16.54% | AF29: =ROUND(P29*AE29,0) -> 0 | AG29: =X29+AF29 -> 18000 | AH29: =AG29-P29 -> 2000 | AI29: =AG29/P29-1 -> 0.125 | AJ29: 14 | AK29: 500 | AM29: 688 | AN29: =AG29*AJ29+AK29*12+AM29+IF(AD29="",AL29,IF(AD29="D",5000,IF(AD29="C",1000,0)))*12 -> 258688 | AO29: 4 | AS29: Ding Xudong（15000307） | AT29: Xu Lan（11013544） | AU29: Zhao Chujun | AY29: =_xlfn.LET(_xlpm.actual,Z29,_xlpm.low,VALUE(_xlfn.TEXTBEFORE(AA29,"-")),_xlpm.high,VALUE(_xlfn.TEXTAFTER(AA29,"-")),IF(AND(_xlpm.actual=0,OR(_xlpm.low<>0,_xlpm.high<>0)),"0 increase",IF(_xlpm.actual>_xlpm.high*1.2,">20",IF(_xlpm.actual<_xlpm.low*0.8,"<20","OK")))) -> OK
A30: CN15 | B30: 15001306 | C30: 钱 山杰 | D30: Qian Shanjie | E30: Indirect Active | F30: OP | G30: SNa | H30: FEDNa-ME | I30: 370200 | J30: 39420 | K30: Functional Specialist | L30: Functional Specialist | M30: BAND A6 | N30: 2 | O30: 3 | P30: 20306 | Q30: 0 | R30: =ROUND(P30*Q30,0) -> 0 | S30: 0 | T30: =ROUND(P30*S30,0) -> 0 | U30: =V30/P30 -> 0 | V30: =R30+T30 -> 0 | W30: =P30+V30 -> 20306 | X30: 20500 | Y30: =X30-P30 -> 194 | Z30: =ROUND(X30/P30-1,4) -> 0.0096 | AA30: =IF(OR(N30=1,N30=2,N30=4),TEXT(U30*0.8,"0.00%")&"-"&TEXT(U30*1.2,"0.00%"),IF(OR(N30=3,N30=6),TEXT(0,"0.00%")&"-"&TEXT(7%*1.2,"0.00%"),IF(OR(N30=5,N30=7),TEXT((T30/P30),"0.00%")&"-"&TEXT((T30/P30)+7%,"0.00%"),""))) -> 0.00%-0.00% | AF30: =ROUND(P30*AE30,0) -> 0 | AG30: =X30+AF30 -> 20500 | AH30: =AG30-P30 -> 194 | AI30: =AG30/P30-1 -> 0.0095538265 | AJ30: 14 | AK30: 600 | AM30: 688 | AN30: =AG30*AJ30+AK30*12+AM30+IF(AD30="",AL30,IF(AD30="D",5000,IF(AD30="C",1000,0)))*12 -> 294888 | AO30: 4 | AR30: Good performance and high competence | AS30: Ding Xudong（15000307） | AT30: Xu Lan（11013544） | AU30: Zhao Chujun | AW30: exceed +/-20% adjustment | AX30: >20 | AY30: =_xlfn.LET(_xlpm.actual,Z30,_xlpm.low,VALUE(_xlfn.TEXTBEFORE(AA30,"-")),_xlpm.high,VALUE(_xlfn.TEXTAFTER(AA30,"-")),IF(AND(_xlpm.actual=0,OR(_xlpm.low<>0,_xlpm.high<>0)),"0 increase",IF(_xlpm.actual>_xlpm.high*1.2,">20",IF(_xlpm.actual<_xlpm.low*0.8,"<20","OK")))) -> >20
A31: CN15 | B31: 15021548 | C31: 沈 燕达 | D31: Shen Yanda | E31: Indirect Active | F31: OP | G31: SNa | H31: FEDNa-ME | I31: 370200 | J31: 44391 | K31: Senior Engineer | L31: Senior Equipment Engineer | M31: BAND A5 | N31: 2 | O31: 3 | P31: 13330 | Q31: 0.025 | R31: =ROUND(P31*Q31,0) -> 333 | S31: 0 | T31: =ROUND(P31*S31,0) -> 0 | U31: =V31/P31 -> 0.024981245 | V31: =R31+T31 -> 333 | W31: =P31+V31 -> 13663 | X31: 13600 | Y31: =X31-P31 -> 270 | Z31: =ROUND(X31/P31-1,4) -> 0.0203 | AA31: =IF(OR(N31=1,N31=2,N31=4),TEXT(U31*0.8,"0.00%")&"-"&TEXT(U31*1.2,"0.00%"),IF(OR(N31=3,N31=6),TEXT(0,"0.00%")&"-"&TEXT(7%*1.2,"0.00%"),IF(OR(N31=5,N31=7),TEXT((T31/P31),"0.00%")&"-"&TEXT((T31/P31)+7%,"0.00%"),""))) -> 2.00%-3.00% | AF31: =ROUND(P31*AE31,0) -> 0 | AG31: =X31+AF31 -> 13600 | AH31: =AG31-P31 -> 270 | AI31: =AG31/P31-1 -> 0.020255064 | AJ31: 14 | AK31: 450 | AM31: 688 | AN31: =AG31*AJ31+AK31*12+AM31+IF(AD31="",AL31,IF(AD31="D",5000,IF(AD31="C",1000,0)))*12 -> 196488 | AO31: 3 | AS31: Ding Xudong（15000307） | AT31: Xu Lan（11013544） | AU31: Zhao Chujun | AY31: =_xlfn.LET(_xlpm.actual,Z31,_xlpm.low,VALUE(_xlfn.TEXTBEFORE(AA31,"-")),_xlpm.high,VALUE(_xlfn.TEXTAFTER(AA31,"-")),IF(AND(_xlpm.actual=0,OR(_xlpm.low<>0,_xlpm.high<>0)),"0 increase",IF(_xlpm.actual>_xlpm.high*1.2,">20",IF(_xlpm.actual<_xlpm.low*0.8,"<20","OK")))) -> OK
A32: CN15 | B32: 15021979 | C32: 孙 毅 | D32: Sun Yi | E32: Indirect Active | F32: OP | G32: SNa | H32: FEDNa-V2 | I32: 370404 | J32: 44503 | K32: Engineer | L32: Production Engineer | M32: BAND A4 | N32: 2 | O32: 3 | P32: 9450 | Q32: 0.025 | R32: =ROUND(P32*Q32,0) -> 236 | S32: 0 | T32: =ROUND(P32*S32,0) -> 0 | U32: =V32/P32 -> 0.024973545 | V32: =R32+T32 -> 236 | W32: =P32+V32 -> 9686 | X32: 9700 | Y32: =X32-P32 -> 250 | Z32: =ROUND(X32/P32-1,4) -> 0.0265 | AA32: =IF(OR(N32=1,N32=2,N32=4),TEXT(U32*0.8,"0.00%")&"-"&TEXT(U32*1.2,"0.00%"),IF(OR(N32=3,N32=6),TEXT(0,"0.00%")&"-"&TEXT(7%*1.2,"0.00%"),IF(OR(N32=5,N32=7),TEXT((T32/P32),"0.00%")&"-"&TEXT((T32/P32)+7%,"0.00%"),""))) -> 2.00%-3.00% | AF32: =ROUND(P32*AE32,0) -> 0 | AG32: =X32+AF32 -> 9700 | AH32: =AG32-P32 -> 250 | AI32: =AG32/P32-1 -> 0.026455026 | AJ32: 14 | AK32: 450 | AM32: 688 | AN32: =AG32*AJ32+AK32*12+AM32+IF(AD32="",AL32,IF(AD32="D",5000,IF(AD32="C",1000,0)))*12 -> 141888 | AO32: 2 | AS32: Ding Xudong（15000307） | AT32: Xu Lan（11013544） | AU32: Zhao Chujun | AY32: =_xlfn.LET(_xlpm.actual,Z32,_xlpm.low,VALUE(_xlfn.TEXTBEFORE(AA32,"-")),_xlpm.high,VALUE(_xlfn.TEXTAFTER(AA32,"-")),IF(AND(_xlpm.actual=0,OR(_xlpm.low<>0,_xlpm.high<>0)),"0 increase",IF(_xlpm.actual>_xlpm.high*1.2,">20",IF(_xlpm.actual<_xlpm.low*0.8,"<20","OK")))) -> OK
A33: CN15 | B33: 15000525 | C33: 王 飞 | D33: Wang Fei | E33: Indirect Active | F33: OP | G33: SNa | H33: FEDNa-FS | I33: 370100 | J33: 38869 | K33: Coordinator | L33: TPM Coordinator | M33: BAND A4 | N33: 2 | O33: 3 | P33: 7900 | Q33: 0 | R33: =ROUND(P33*Q33,0) -> 0 | S33: 0 | T33: =ROUND(P33*S33,0) -> 0 | U33: =V33/P33 -> 0 | V33: =R33+T33 -> 0 | W33: =P33+V33 -> 7900 | X33: 8000 | Y33: =X33-P33 -> 100 | Z33: =ROUND(X33/P33-1,4) -> 0.0127 | AA33: =IF(OR(N33=1,N33=2,N33=4),TEXT(U33*0.8,"0.00%")&"-"&TEXT(U33*1.2,"0.00%"),IF(OR(N33=3,N33=6),TEXT(0,"0.00%")&"-"&TEXT(7%*1.2,"0.00%"),IF(OR(N33=5,N33=7),TEXT((T33/P33),"0.00%")&"-"&TEXT((T33/P33)+7%,"0.00%"),""))) -> 0.00%-0.00% | AF33: =ROUND(P33*AE33,0) -> 0 | AG33: =X33+AF33 -> 8000 | AH33: =AG33-P33 -> 100 | AI33: =AG33/P33-1 -> 0.012658228 | AJ33: 14 | AK33: 650 | AM33: 688 | AN33: =AG33*AJ33+AK33*12+AM33+IF(AD33="",AL33,IF(AD33="D",5000,IF(AD33="C",1000,0)))*12 -> 120488 | AO33: 3 | AR33: Internal balance | AS33: Ding Xudong（15000307） | AT33: Xu Lan（11013544） | AU33: Zhao Chujun | AW33: exceed +/-20% adjustment | AX33: >20 | AY33: =_xlfn.LET(_xlpm.actual,Z33,_xlpm.low,VALUE(_xlfn.TEXTBEFORE(AA33,"-")),_xlpm.high,VALUE(_xlfn.TEXTAFTER(AA33,"-")),IF(AND(_xlpm.actual=0,OR(_xlpm.low<>0,_xlpm.high<>0)),"0 increase",IF(_xlpm.actual>_xlpm.high*1.2,">20",IF(_xlpm.actual<_xlpm.low*0.8,"<20","OK")))) -> >20
A34: CN15 | B34: 15020089 | C34: 王 鲜 | D34: Wang Xian | E34: Indirect Active | F34: OP | G34: SNa | H34: FEDNa-MEP | I34: 370200 | J34: 43908 | K34: Engineer | L34: Process Engineer | M34: BAND A4 | N34: 2 | O34: 3 | P34: 10100 | Q34: 0.025 | R34: =ROUND(P34*Q34,0) -> 253 | S34: 0 | T34: =ROUND(P34*S34,0) -> 0 | U34: =V34/P34 -> 0.025049505 | V34: =R34+T34 -> 253 | W34: =P34+V34 -> 10353 | X34: 10300 | Y34: =X34-P34 -> 200 | Z34: =ROUND(X34/P34-1,4) -> 0.0198 | AA34: =IF(OR(N34=1,N34=2,N34=4),TEXT(U34*0.8,"0.00%")&"-"&TEXT(U34*1.2,"0.00%"),IF(OR(N34=3,N34=6),TEXT(0,"0.00%")&"-"&TEXT(7%*1.2,"0.00%"),IF(OR(N34=5,N34=7),TEXT((T34/P34),"0.00%")&"-"&TEXT((T34/P34)+7%,"0.00%"),""))) -> 2.00%-3.01% | AF34: =ROUND(P34*AE34,0) -> 0 | AG34: =X34+AF34 -> 10300 | AH34: =AG34-P34 -> 200 | AI34: =AG34/P34-1 -> 0.01980198 | AJ34: 14 | AK34: 450 | AM34: 688 | AN34: =AG34*AJ34+AK34*12+AM34+IF(AD34="",AL34,IF(AD34="D",5000,IF(AD34="C",1000,0)))*12 -> 150288 | AO34: 3 | AR34: Rounding | AS34: Ding Xudong（15000307） | AT34: Xu Lan（11013544） | AU34: Zhao Chujun | AW34: exceed +/-20% adjustment | AX34: <20 | AY34: =_xlfn.LET(_xlpm.actual,Z34,_xlpm.low,VALUE(_xlfn.TEXTBEFORE(AA34,"-")),_xlpm.high,VALUE(_xlfn.TEXTAFTER(AA34,"-")),IF(AND(_xlpm.actual=0,OR(_xlpm.low<>0,_xlpm.high<>0)),"0 increase",IF(_xlpm.actual>_xlpm.high*1.2,">20",IF(_xlpm.actual<_xlpm.low*0.8,"<20","OK")))) -> OK
A35: CN15 | B35: 15000550 | C35: 夏 邦猛 | D35: Xia Bangmeng | E35: Indirect Active | F35: OP | G35: SNa | H35: FEDNa-V2 | I35: 370404 | J35: 38881 | K35: Engineer | L35: Engineer | M35: BAND A4 | N35: 2 | O35: 4 | P35: 9800 | Q35: 0.0375 | R35: =ROUND(P35*Q35,0) -> 368 | S35: 0.0155 | T35: =ROUND(P35*S35,0) -> 152 | U35: =V35/P35 -> 0.053061224 | V35: =R35+T35 -> 520 | W35: =P35+V35 -> 10320 | X35: 10300 | Y35: =X35-P35 -> 500 | Z35: =ROUND(X35/P35-1,4) -> 0.051 | AA35: =IF(OR(N35=1,N35=2,N35=4),TEXT(U35*0.8,"0.00%")&"-"&TEXT(U35*1.2,"0.00%"),IF(OR(N35=3,N35=6),TEXT(0,"0.00%")&"-"&TEXT(7%*1.2,"0.00%"),IF(OR(N35=5,N35=7),TEXT((T35/P35),"0.00%")&"-"&TEXT((T35/P35)+7%,"0.00%"),""))) -> 4.24%-6.37% | AF35: =ROUND(P35*AE35,0) -> 0 | AG35: =X35+AF35 -> 10300 | AH35: =AG35-P35 -> 500 | AI35: =AG35/P35-1 -> 0.051020408 | AJ35: 14 | AK35: 550 | AM35: 688 | AN35: =AG35*AJ35+AK35*12+AM35+IF(AD35="",AL35,IF(AD35="D",5000,IF(AD35="C",1000,0)))*12 -> 151488 | AO35: 3 | AS35: Ding Xudong（15000307） | AT35: Xu Lan（11013544） | AU35: Zhao Chujun | AY35: =_xlfn.LET(_xlpm.actual,Z35,_xlpm.low,VALUE(_xlfn.TEXTBEFORE(AA35,"-")),_xlpm.high,VALUE(_xlfn.TEXTAFTER(AA35,"-")),IF(AND(_xlpm.actual=0,OR(_xlpm.low<>0,_xlpm.high<>0)),"0 increase",IF(_xlpm.actual>_xlpm.high*1.2,">20",IF(_xlpm.actual<_xlpm.low*0.8,"<20","OK")))) -> OK
A36: CN15 | B36: 15015967 | C36: 徐 擎月 | D36: Xu Qingyue | E36: Indirect Active | F36: OP | G36: SNa | H36: FEDNa-FS | I36: 370100 | J36: 42683 | K36: Associate Expert (CN) | L36: Associate Expert (C) | M36: BAND A6 | N36: 2 | O36: 4 | P36: 12360 | Q36: 0.045 | R36: =ROUND(P36*Q36,0) -> 556 | S36: 0.0421 | T36: =ROUND(P36*S36,0) -> 520 | U36: =V36/P36 -> 0.087055016 | V36: =R36+T36 -> 1076 | W36: =P36+V36 -> 13436 | X36: 13300 | Y36: =X36-P36 -> 940 | Z36: =ROUND(X36/P36-1,4) -> 0.0761 | AA36: =IF(OR(N36=1,N36=2,N36=4),TEXT(U36*0.8,"0.00%")&"-"&TEXT(U36*1.2,"0.00%"),IF(OR(N36=3,N36=6),TEXT(0,"0.00%")&"-"&TEXT(7%*1.2,"0.00%"),IF(OR(N36=5,N36=7),TEXT((T36/P36),"0.00%")&"-"&TEXT((T36/P36)+7%,"0.00%"),""))) -> 6.96%-10.45% | AF36: =ROUND(P36*AE36,0) -> 0 | AG36: =X36+AF36 -> 13300 | AH36: =AG36-P36 -> 940 | AI36: =AG36/P36-1 -> 0.07605178 | AJ36: 14 | AK36: 450 | AM36: 688 | AN36: =AG36*AJ36+AK36*12+AM36+IF(AD36="",AL36,IF(AD36="D",5000,IF(AD36="C",1000,0)))*12 -> 192288 | AO36: 3 | AS36: Ding Xudong（15000307） | AT36: Xu Lan（11013544） | AU36: Zhao Chujun | AY36: =_xlfn.LET(_xlpm.actual,Z36,_xlpm.low,VALUE(_xlfn.TEXTBEFORE(AA36,"-")),_xlpm.high,VALUE(_xlfn.TEXTAFTER(AA36,"-")),IF(AND(_xlpm.actual=0,OR(_xlpm.low<>0,_xlpm.high<>0)),"0 increase",IF(_xlpm.actual>_xlpm.high*1.2,">20",IF(_xlpm.actual<_xlpm.low*0.8,"<20","OK")))) -> OK
A37: CN15 | B37: 15001287 | C37: 原 丰霞 | D37: Yuan Fengxia | E37: Indirect Active | F37: OP | G37: SNa | H37: FEDNa-MEP | I37: 370200 | J37: 39392 | K37: Senior Engineer | L37: Senior Electrical Engineer | M37: BAND A5 | N37: 2 | O37: 3 | P37: 12500 | Q37: 0.025 | R37: =ROUND(P37*Q37,0) -> 313 | S37: 0 | T37: =ROUND(P37*S37,0) -> 0 | U37: =V37/P37 -> 0.02504 | V37: =R37+T37 -> 313 | W37: =P37+V37 -> 12813 | X37: 12600 | Y37: =X37-P37 -> 100 | Z37: =ROUND(X37/P37-1,4) -> 0.008 | AA37: =IF(OR(N37=1,N37=2,N37=4),TEXT(U37*0.8,"0.00%")&"-"&TEXT(U37*1.2,"0.00%"),IF(OR(N37=3,N37=6),TEXT(0,"0.00%")&"-"&TEXT(7%*1.2,"0.00%"),IF(OR(N37=5,N37=7),TEXT((T37/P37),"0.00%")&"-"&TEXT((T37/P37)+7%,"0.00%"),""))) -> 2.00%-3.00% | AF37: =ROUND(P37*AE37,0) -> 0 | AG37: =X37+AF37 -> 12600 | AH37: =AG37-P37 -> 100 | AI37: =AG37/P37-1 -> 0.008 | AJ37: 14 | AK37: 450 | AM37: 688 | AN37: =AG37*AJ37+AK37*12+AM37+IF(AD37="",AL37,IF(AD37="D",5000,IF(AD37="C",1000,0)))*12 -> 182488 | AO37: 3 | AR37: Left/will leave/retire soon | AS37: Ding Xudong（15000307） | AT37: Xu Lan（11013544） | AU37: Zhao Chujun | AW37: exceed +/-20% adjustment | AX37: <20 | AY37: =_xlfn.LET(_xlpm.actual,Z37,_xlpm.low,VALUE(_xlfn.TEXTBEFORE(AA37,"-")),_xlpm.high,VALUE(_xlfn.TEXTAFTER(AA37,"-")),IF(AND(_xlpm.actual=0,OR(_xlpm.low<>0,_xlpm.high<>0)),"0 increase",IF(_xlpm.actual>_xlpm.high*1.2,">20",IF(_xlpm.actual<_xlpm.low*0.8,"<20","OK")))) -> <20
A38: CN15 | B38: 15016938 | C38: 张 来翔 | D38: Zhang Laixiang | E38: Indirect Active | F38: OP | G38: SNa | H38: FEDNa-MEP | I38: 370200 | J38: 42830 | K38: Supervisor | L38: Head of FEDNa-MEP | M38: BAND A6 | N38: 2 | O38: 5 | P38: 18000 | Q38: 0.05 | R38: =ROUND(P38*Q38,0) -> 900 | S38: 0.027 | T38: =ROUND(P38*S38,0) -> 486 | U38: =V38/P38 -> 0.077 | V38: =R38+T38 -> 1386 | W38: =P38+V38 -> 19386 | X38: 19700 | Y38: =X38-P38 -> 1700 | Z38: =ROUND(X38/P38-1,4) -> 0.0944 | AA38: =IF(OR(N38=1,N38=2,N38=4),TEXT(U38*0.8,"0.00%")&"-"&TEXT(U38*1.2,"0.00%"),IF(OR(N38=3,N38=6),TEXT(0,"0.00%")&"-"&TEXT(7%*1.2,"0.00%"),IF(OR(N38=5,N38=7),TEXT((T38/P38),"0.00%")&"-"&TEXT((T38/P38)+7%,"0.00%"),""))) -> 6.16%-9.24% | AF38: =ROUND(P38*AE38,0) -> 0 | AG38: =X38+AF38 -> 19700 | AH38: =AG38-P38 -> 1700 | AI38: =AG38/P38-1 -> 0.094444444 | AJ38: 14 | AK38: 450 | AM38: 688 | AN38: =AG38*AJ38+AK38*12+AM38+IF(AD38="",AL38,IF(AD38="D",5000,IF(AD38="C",1000,0)))*12 -> 281888 | AO38: 5 | AR38: Good performance/talent | AS38: Ding Xudong（15000307） | AT38: Xu Lan（11013544） | AU38: Zhao Chujun | AW38: exceed +/-20% adjustment | AX38: >20 | AY38: =_xlfn.LET(_xlpm.actual,Z38,_xlpm.low,VALUE(_xlfn.TEXTBEFORE(AA38,"-")),_xlpm.high,VALUE(_xlfn.TEXTAFTER(AA38,"-")),IF(AND(_xlpm.actual=0,OR(_xlpm.low<>0,_xlpm.high<>0)),"0 increase",IF(_xlpm.actual>_xlpm.high*1.2,">20",IF(_xlpm.actual<_xlpm.low*0.8,"<20","OK")))) -> OK
A39: CN15 | B39: 15000503 | C39: 赵 斌 | D39: Zhao Bin | E39: Indirect Active | F39: OP | G39: SNa | H39: FEDNa-V1 | I39: 370402 | J39: 38852 | K39: Senior Engineer | L39: Senior Process Engineer | M39: BAND A5 | N39: 2 | O39: 4 | P39: 10000 | Q39: 0.045 | R39: =ROUND(P39*Q39,0) -> 450 | S39: 0.0421 | T39: =ROUND(P39*S39,0) -> 421 | U39: =V39/P39 -> 0.0871 | V39: =R39+T39 -> 871 | W39: =P39+V39 -> 10871 | X39: 10700 | Y39: =X39-P39 -> 700 | Z39: =ROUND(X39/P39-1,4) -> 0.07 | AA39: =IF(OR(N39=1,N39=2,N39=4),TEXT(U39*0.8,"0.00%")&"-"&TEXT(U39*1.2,"0.00%"),IF(OR(N39=3,N39=6),TEXT(0,"0.00%")&"-"&TEXT(7%*1.2,"0.00%"),IF(OR(N39=5,N39=7),TEXT((T39/P39),"0.00%")&"-"&TEXT((T39/P39)+7%,"0.00%"),""))) -> 6.97%-10.45% | AF39: =ROUND(P39*AE39,0) -> 0 | AG39: =X39+AF39 -> 10700 | AH39: =AG39-P39 -> 700 | AI39: =AG39/P39-1 -> 0.07 | AJ39: 14 | AK39: 450 | AM39: 688 | AN39: =AG39*AJ39+AK39*12+AM39+IF(AD39="",AL39,IF(AD39="D",5000,IF(AD39="C",1000,0)))*12 -> 155888 | AO39: 3 | AS39: Ding Xudong（15000307） | AT39: Xu Lan（11013544） | AU39: Zhao Chujun | AY39: =_xlfn.LET(_xlpm.actual,Z39,_xlpm.low,VALUE(_xlfn.TEXTBEFORE(AA39,"-")),_xlpm.high,VALUE(_xlfn.TEXTAFTER(AA39,"-")),IF(AND(_xlpm.actual=0,OR(_xlpm.low<>0,_xlpm.high<>0)),"0 increase",IF(_xlpm.actual>_xlpm.high*1.2,">20",IF(_xlpm.actual<_xlpm.low*0.8,"<20","OK")))) -> OK
A40: CN15 | B40: 15022682 | C40: 董 小语 | D40: Dong Xiaoyu | E40: Indirect Active | F40: OP | G40: SNa | H40: SNa-ES | I40: 290125 | J40: 45910 | K40: Senior Engineer | L40: Senior EHS Engineer | M40: BAND A5 | N40: 2 | O40: 3 | P40: 13550 | Q40: 0 | R40: =ROUND(P40*Q40,0) -> 0 | S40: 0 | T40: =ROUND(P40*S40,0) -> 0 | U40: =V40/P40 -> 0 | V40: =R40+T40 -> 0 | W40: =P40+V40 -> 13550 | X40: =W40 -> 13550 | Y40: =X40-P40 -> 0 | Z40: =ROUND(X40/P40-1,4) -> 0 | AA40: =IF(OR(N40=1,N40=2,N40=4),TEXT(U40*0.8,"0.00%")&"-"&TEXT(U40*1.2,"0.00%"),IF(OR(N40=3,N40=6),TEXT(0,"0.00%")&"-"&TEXT(7%*1.2,"0.00%"),IF(OR(N40=5,N40=7),TEXT((T40/P40),"0.00%")&"-"&TEXT((T40/P40)+7%,"0.00%"),""))) -> 0.00%-0.00% | AF40: =ROUND(P40*AE40,0) -> 0 | AG40: =X40+AF40 -> 13550 | AH40: =AG40-P40 -> 0 | AI40: =AG40/P40-1 -> 0 | AJ40: 14 | AK40: 450 | AM40: 688 | AN40: =AG40*AJ40+AK40*12+AM40+IF(AD40="",AL40,IF(AD40="D",5000,IF(AD40="C",1000,0)))*12 -> 195788 | AO40: #N/A | AS40: Yao Da (15022352) | AT40: Xu Lan（11013544） | AU40: Zhao Chujun | AY40: =_xlfn.LET(_xlpm.actual,Z40,_xlpm.low,VALUE(_xlfn.TEXTBEFORE(AA40,"-")),_xlpm.high,VALUE(_xlfn.TEXTAFTER(AA40,"-")),IF(AND(_xlpm.actual=0,OR(_xlpm.low<>0,_xlpm.high<>0)),"0 increase",IF(_xlpm.actual>_xlpm.high*1.2,">20",IF(_xlpm.actual<_xlpm.low*0.8,"<20","OK")))) -> OK
...

Sheet data analysis
A1: Area | B1: Number of eligibility | C1: Total Salary Increase budget | D1: Person of increase | E1: Salary Increase budget used | G1: Person of increase | H1: Merit budget Balance | I1: Promotion Budget | J1: Promotion budget usage | K1: Number of promotion | L1: Promotion budget balance
A2: GOM-CGC | B2: 38 | C2: =SUMIF('Indirect Active'!E:E,'data analysis'!$A2,'Indirect Active'!T1:T1937) -> 9315 | D2: =COUNTIFS('Indirect Active'!E:E,$A2,'Indirect Active'!X:X,"<>0") -> 11 | E2: =SUMIF('Indirect Active'!E:E,'data analysis'!$A2,'Indirect Active'!W:W) -> 9315 | F2: =E2/C2 -> 1
A3: GOM-CLC | B3: 16 | C3: =SUMIF('Indirect Active'!E:E,'data analysis'!$A3,'Indirect Active'!T2:T1938) -> 14481 | D3: =COUNTIFS('Indirect Active'!E:E,$A3,'Indirect Active'!X:X,"<>0") -> 10 | E3: =SUMIF('Indirect Active'!E:E,'data analysis'!$A3,'Indirect Active'!W:W) -> 12320 | F3: =E3/C3 -> 0.85076997
A4: GOM-DCC | B4: 15 | C4: =SUMIF('Indirect Active'!E:E,'data analysis'!$A4,'Indirect Active'!T3:T1939) -> 6572 | D4: =COUNTIFS('Indirect Active'!E:E,$A4,'Indirect Active'!X:X,"<>0") -> 9 | E4: =SUMIF('Indirect Active'!E:E,'data analysis'!$A4,'Indirect Active'!W:W) -> 7067 | F4: =E4/C4 -> 1.0753195
A5: GOM-LCC | B5: 9 | C5: =SUMIF('Indirect Active'!E:E,'data analysis'!$A5,'Indirect Active'!T4:T1940) -> 18276 | D5: =COUNTIFS('Indirect Active'!E:E,$A5,'Indirect Active'!X:X,"<>0") -> 18 | E5: =SUMIF('Indirect Active'!E:E,'data analysis'!$A5,'Indirect Active'!W:W) -> 16165 | F5: =E5/C5 -> 0.88449332
A6: GPL-CN | B6: 23 | C6: =SUMIF('Indirect Active'!E:E,'data analysis'!$A6,'Indirect Active'!T5:T1941) -> 45803 | D6: =COUNTIFS('Indirect Active'!E:E,$A6,'Indirect Active'!X:X,"<>0") -> 87 | E6: =SUMIF('Indirect Active'!E:E,'data analysis'!$A6,'Indirect Active'!W:W) -> 50456 | F6: =E6/C6 -> 1.1015872
A7: GQM | B7: 152 | C7: =SUMIF('Indirect Active'!E:E,'data analysis'!$A7,'Indirect Active'!T6:T1942) -> 66324 | D7: =COUNTIFS('Indirect Active'!E:E,$A7,'Indirect Active'!X:X,"<>0") -> 110 | E7: =SUMIF('Indirect Active'!E:E,'data analysis'!$A7,'Indirect Active'!W:W) -> 72365 | F7: =E7/C7 -> 1.0910832
A8: PCP | B8: 151 | C8: =SUMIF('Indirect Active'!E:E,'data analysis'!$A8,'Indirect Active'!T7:T1943) -> 35317 | D8: =COUNTIFS('Indirect Active'!E:E,$A8,'Indirect Active'!X:X,"<>0") -> 59 | E8: =SUMIF('Indirect Active'!E:E,'data analysis'!$A8,'Indirect Active'!W:W) -> 33643 | F8: =E8/C8 -> 0.95260073
A9: CN/OP-RM | B9: 14 | C9: =SUMIF('Indirect Active'!E:E,'data analysis'!$A9,'Indirect Active'!T8:T1944) -> 24910 | D9: =COUNTIFS('Indirect Active'!E:E,$A9,'Indirect Active'!X:X,"<>0") -> 25 | E9: =SUMIF('Indirect Active'!E:E,'data analysis'!$A9,'Indirect Active'!W:W) -> 14433 | F9: =E9/C9 -> 0.57940586
A10: SC | B10: 86 | C10: =SUMIF('Indirect Active'!E:E,'data analysis'!$A10,'Indirect Active'!T9:T1945) -> 26305 | D10: =COUNTIFS('Indirect Active'!E:E,$A10,'Indirect Active'!X:X,"<>0") -> 51 | E10: =SUMIF('Indirect Active'!E:E,'data analysis'!$A10,'Indirect Active'!W:W) -> 26345 | F10: =E10/C10 -> 1.0015206
A11: SNa | B11: 29 | C11: =SUMIF('Indirect Active'!E:E,'data analysis'!$A11,'Indirect Active'!T10:T1946) -> 50713 | D11: =COUNTIFS('Indirect Active'!E:E,$A11,'Indirect Active'!X:X,"<>0") -> 61 | E11: =SUMIF('Indirect Active'!E:E,'data analysis'!$A11,'Indirect Active'!W:W) -> 38426.744 | F11: =E11/C11 -> 0.75772966
A12: SCh | B12: 82 | C12: =SUMIF('Indirect Active'!E:E,'data analysis'!$A12,'Indirect Active'!T11:T1947) -> 64901
A13: ALL | C13: =SUM(C2:C12) -> 362917
J14: 0.005
A15: 行标签 | B15: 求和项:Total Recommended Increase amount | C15: 求和项:Adjutsed increased/decreased basic salary by DH | D15: Surpus | E15: Usage | F15: No | G15: Person of Increase | I15: Basic Salary | J15: Promotion Budget | K15: Promotion Budget Used | M15: No of Promoted | O15: Thereof Special
A16: CN/OP-RM | B16: 14433 | C16: 14433 | D16: =B16-C16 -> 0 | E16: =C16/B16 -> 1 | F16: 38 | G16: 25 | H16: =G16/F16 -> 0.65789474 | I16: 565057 | J16: =I16*$J$14 -> 2825.285 | K16: 2825 | L16: =K16/J16 -> 0.99989913 | M16: 3 | N16: =M16/F16 -> 0.078947368
A17: GOM-CGC | B17: 9315 | C17: 9315 | D17: =B17-C17 -> 0 | E17: =C17/B17 -> 1 | F17: 16 | G17: 11 | H17: =G17/F17 -> 0.6875 | I17: 391477 | J17: =I17*$J$14 -> 1957.385 | K17: 1952 | L17: =K17/J17 -> 0.99724888 | M17: 1 | N17: =M17/F17 -> 0.0625
A18: GOM-CLC | B18: 12320 | C18: 12320 | D18: =B18-C18 -> 0 | E18: =C18/B18 -> 1 | F18: 15 | G18: 10 | H18: =G18/F18 -> 0.66666667 | I18: 415631 | J18: =I18*$J$14 -> 2078.155 | K18: 0 | L18: 0 | N18: =M18/F18 -> 0
A19: GOM-DCC | B19: 7067 | C19: 7067 | D19: =B19-C19 -> 0 | E19: =C19/B19 -> 1 | F19: 9 | G19: 9 | H19: =G19/F19 -> 1 | I19: 202173 | J19: =I19*$J$14 -> 1010.865 | K19: 1010 | L19: =K19/J19 -> 0.9991443 | M19: 1 | N19: =M19/F19 -> 0.11111111
A20: GOM-LCC | B20: 16166 | C20: 16165 | D20: =B20-C20 -> 1 | E20: =C20/B20 -> 0.99993814 | F20: 23 | G20: 18 | H20: =G20/F20 -> 0.7826087 | I20: 605993 | J20: =I20*$J$14 -> 3029.965 | K20: 3023 | L20: =K20/J20 -> 0.99770129 | M20: 2 | N20: =M20/F20 -> 0.086956522
A21: GPL-CN | B21: 50456 | C21: 50456 | D21: =B21-C21 -> 0 | E21: =C21/B21 -> 1 | F21: 152 | G21: 87 | H21: =G21/F21 -> 0.57236842 | I21: 2057648 | J21: =I21*$J$14 -> 10288.24 | K21: 9474 | L21: =K21/J21 -> 0.92085721 | M21: 8 | N21: =M21/F21 -> 0.052631579 | O21: 0
