Workbook

Sheet 数据分析
A1: Area | B1: Number of eligibility | C1: Total Salary Increase budget | D1: Person of increase | E1: Salary Increase budget used | G1: Person of increase | H1: Merit budget Balance | I1: Promotion Budget | J1: Promotion budget usage | K1: Number of promotion | L1: Promotion budget balance
A2: GOM-CGC | B2: 38 | C2: =SUMIF(白领!E:E,数据分析!$A2,白领!T1:T1937) -> 9315 | D2: =COUNTIFS(白领!E:E,$A2,白领!X:X,"<>0") -> 11 | E2: =SUMIF(白领!E:E,数据分析!$A2,白领!W:W) -> 9315 | F2: =E2/C2 -> 1
A3: GOM-CLC | B3: 16 | C3: =SUMIF(白领!E:E,数据分析!$A3,白领!T2:T1938) -> 14481 | D3: =COUNTIFS(白领!E:E,$A3,白领!X:X,"<>0") -> 10 | E3: =SUMIF(白领!E:E,数据分析!$A3,白领!W:W) -> 12320 | F3: =E3/C3 -> 0.85076997
A4: GOM-DCC | B4: 15 | C4: =SUMIF(白领!E:E,数据分析!$A4,白领!T3:T1939) -> 6572 | D4: =COUNTIFS(白领!E:E,$A4,白领!X:X,"<>0") -> 9 | E4: =SUMIF(白领!E:E,数据分析!$A4,白领!W:W) -> 7067 | F4: =E4/C4 -> 1.0753195
A5: GOM-LCC | B5: 9 | C5: =SUMIF(白领!E:E,数据分析!$A5,白领!T4:T1940) -> 18276 | D5: =COUNTIFS(白领!E:E,$A5,白领!X:X,"<>0") -> 18 | E5: =SUMIF(白领!E:E,数据分析!$A5,白领!W:W) -> 16165 | F5: =E5/C5 -> 0.88449332
A6: GPL-CN | B6: 23 | C6: =SUMIF(白领!E:E,数据分析!$A6,白领!T5:T1941) -> 45803 | D6: =COUNTIFS(白领!E:E,$A6,白领!X:X,"<>0") -> 87 | E6: =SUMIF(白领!E:E,数据分析!$A6,白领!W:W) -> 50456 | F6: =E6/C6 -> 1.1015872
A7: GQM | B7: 152 | C7: =SUMIF(白领!E:E,数据分析!$A7,白领!T6:T1942) -> 66324 | D7: =COUNTIFS(白领!E:E,$A7,白领!X:X,"<>0") -> 110 | E7: =SUMIF(白领!E:E,数据分析!$A7,白领!W:W) -> 72365 | F7: =E7/C7 -> 1.0910832
A8: PCP | B8: 151 | C8: =SUMIF(白领!E:E,数据分析!$A8,白领!T7:T1943) -> 35317 | D8: =COUNTIFS(白领!E:E,$A8,白领!X:X,"<>0") -> 59 | E8: =SUMIF(白领!E:E,数据分析!$A8,白领!W:W) -> 33643 | F8: =E8/C8 -> 0.95260073
A9: CN/OP-RM | B9: 14 | C9: =SUMIF(白领!E:E,数据分析!$A9,白领!T8:T1944) -> 24910 | D9: =COUNTIFS(白领!E:E,$A9,白领!X:X,"<>0") -> 25 | E9: =SUMIF(白领!E:E,数据分析!$A9,白领!W:W) -> 14433 | F9: =E9/C9 -> 0.57940586
A10: SC | B10: 86 | C10: =SUMIF(白领!E:E,数据分析!$A10,白领!T9:T1945) -> 25597 | D10: =COUNTIFS(白领!E:E,$A10,白领!X:X,"<>0") -> 51 | E10: =SUMIF(白领!E:E,数据分析!$A10,白领!W:W) -> 26345 | F10: =E10/C10 -> 1.0292222
A11: SNa | B11: 29 | C11: =SUMIF(白领!E:E,数据分析!$A11,白领!T10:T1946) -> 38434 | D11: =COUNTIFS(白领!E:E,$A11,白领!X:X,"<>0") -> 61 | E11: =SUMIF(白领!E:E,数据分析!$A11,白领!W:W) -> 38426.744 | F11: =E11/C11 -> 0.99981121
A12: SCh | B12: 82 | C12: =SUMIF(白领!E:E,数据分析!$A12,白领!T11:T1947) -> 64901
A13: ALL | C13: =SUM(C2:C12) -> 349930
J14: 0.005
A15: 行标签 | B15: 求和项:Total Recommended Increase amount | C15: 求和项:Adjutsed increased/decreased basic salary by DH | D15: Surpus | E15: Usage | F15: No | G15: Person of Increase | I15: Basic Salary | J15: Promotion Budget | K15: Promotion Budget Used | M15: No of Promoted | O15: Thereof Special
A16: CN/OP-RM | B16: 14433 | C16: 14433 | D16: =B16-C16 -> 0 | E16: =C16/B16 -> 1 | F16: 38 | G16: 25 | H16: =G16/F16 -> 0.65789474 | I16: 565057 | J16: =I16*$J$14 -> 2825.285 | K16: 2825 | L16: =K16/J16 -> 0.99989913 | M16: 3 | N16: =M16/F16 -> 0.078947368
A17: GOM-CGC | B17: 9315 | C17: 9315 | D17: =B17-C17 -> 0 | E17: =C17/B17 -> 1 | F17: 16 | G17: 11 | H17: =G17/F17 -> 0.6875 | I17: 391477 | J17: =I17*$J$14 -> 1957.385 | K17: 1952 | L17: =K17/J17 -> 0.99724888 | M17: 1 | N17: =M17/F17 -> 0.0625
A18: GOM-CLC | B18: 12320 | C18: 12320 | D18: =B18-C18 -> 0 | E18: =C18/B18 -> 1 | F18: 15 | G18: 10 | H18: =G18/F18 -> 0.66666667 | I18: 415631 | J18: =I18*$J$14 -> 2078.155 | K18: 0 | L18: 0 | N18: =M18/F18 -> 0
A19: GOM-DCC | B19: 7067 | C19: 7067 | D19: =B19-C19 -> 0 | E19: =C19/B19 -> 1 | F19: 9 | G19: 9 | H19: =G19/F19 -> 1 | I19: 202173 | J19: =I19*$J$14 -> 1010.865 | K19: 1010 | L19: =K19/J19 -> 0.9991443 | M19: 1 | N19: =M19/F19 -> 0.11111111
A20: GOM-LCC | B20: 16166 | C20: 16165 | D20: =B20-C20 -> 1 | E20: =C20/B20 -> 0.99993814 | F20: 23 | G20: 18 | H20: =G20/F20 -> 0.7826087 | I20: 605993 | J20: =I20*$J$14 -> 3029.965 | K20: 3023 | L20: =K20/J20 -> 0.99770129 | M20: 2 | N20: =M20/F20 -> 0.086956522
A21: GPL-CN | B21: 50456 | C21: 50456 | D21: =B21-C21 -> 0 | E21: =C21/B21 -> 1 | F21: 152 | G21: 87 | H21: =G21/F21 -> 0.57236842 | I21: 2057648 | J21: =I21*$J$14 -> 10288.24 | K21: 9474 | L21: =K21/J21 -> 0.92085721 | M21: 8 | N21: =M21/F21 -> 0.052631579 | O21: 0
A22: GQM | B22: 68266 | C22: 72365 | D22: =B22-C22 -> -4099 | E22: =C22/B22 -> 1.0600445 | F22: 151 | G22: 110 | H22: =G22/F22 -> 0.72847682 | I22: 2138146 | J22: =I22*$J$14 -> 10690.73 | K22: 10691 | L22: =K22/J22 -> 1.0000253 | M22: 13 | N22: =M22/F22 -> 0.086092715
A23: OP-TE | B23: 9953 | C23: 9953 | D23: =B23-C23 -> 0 | E23: =C23/B23 -> 1 | F23: 14 | G23: 10 | H23: =G23/F23 -> 0.71428571 | I23: 281769 | J23: =I23*$J$14 -> 1408.845 | K23: 1436 | L23: =K23/J23 -> 1.0192747 | M23: 1 | N23: =M23/F23 -> 0.071428571
A24: PCP | B24: 33643 | C24: 33643 | D24: =B24-C24 -> 0 | E24: =C24/B24 -> 1 | F24: 86 | G24: 59 | H24: =G24/F24 -> 0.68604651 | I24: 1418496 | J24: =I24*$J$14 -> 7092.48 | K24: 7089 | L24: =K24/J24 -> 0.99950934 | M24: 7 | N24: =M24/F24 -> 0.081395349
A25: SC | B25: 26990 | C25: 26345 | D25: =B25-C25 -> 645 | E25: =C25/B25 -> 0.97610226 | F25: 66 | G25: 51 | H25: =G25/F25 -> 0.77272727 | I25: 841434 | J25: =I25*$J$14 -> 4207.17 | K25: 4048 | L25: =K25/J25 -> 0.96216697 | M25: 6 | N25: =M25/F25 -> 0.090909091
A26: SNa | B26: 38293 | C26: 38476.744 | D26: =B26-C26 -> -183.744 | E26: =C26/B26 -> 1.0047984 | F26: 82 | G26: 62 | H26: =G26/F26 -> 0.75609756 | I26: 1370342 | J26: =I26*$J$14 -> 6851.71 | K26: 8701 | L26: =K26/J26 -> 1.269902 | M26: 6 | N26: =M26/F26 -> 0.073170732
A27: SCh | B27: 74651 | C27: 73144 | D27: =B27-C27 -> 1507 | E27: =C27/B27 -> 0.97981273 | F27: 142 | G27: 92 | H27: =G27/F27 -> 0.64788732 | I27: 2083527 | J27: =I27*$J$14 -> 10417.635 | K27: 8341 | L27: =K27/J27 -> 0.80066157 | M27: 9 | N27: =M27/F27 -> 0.063380282
A28: Overall | B28: 361553 | C28: 363682.74 | D28: =B28-C28 -> -2129.744 | E28: =C28/B28 -> 1.0058905 | F28: 794 | G28: 544 | H28: =G28/F28 -> 0.68513854 | I28: 12371693 | J28: =I28*$J$14 -> 61858.465 | K28: 58590 | L28: =K28/J28 -> 0.9471622 | M28: 57 | N28: =M28/F28 -> 0.071788413
G30: Remark
A31: PL1 | B31: 14 | C31: 1 | D31: =C31/B31 -> 0.071428571 | E31: -0.022 | F31: 1 | G31: demotion
A32: PL2 | B32: 47 | C32: 6 | D32: =C32/B32 -> 0.12765957 | E32: 0.02016 | F32: 5 | G32: 1 new comer, 4 newly promoted
A33: PL3 | B33: 482 | C33: 305 | D33: =C33/B33 -> 0.63278008 | E33: 0.029135082 | F33: 305
A34: PL4 | B34: 170 | C34: 163 | D34: =C34/B34 -> 0.95882353 | E34: 0.054025153 | F34: 163
A35: PL5 | B35: 75 | C35: 67 | D35: =C35/B35 -> 0.89333333 | E35: 0.083274627 | F35: 67
A36: Overall | B36: 6 | C36: 2 | D36: =C36/B36 -> 0.33333333 | E36: 0.06545 | F36: 2
B37: 794 | C37: 544 | D37: =C37/B37 -> 0.68513854 | E37: 0.043243831 | F37: 543
A38: Band A | B38: 607 | C38: 398 | D38: =C38/B38 -> 0.65568369 | E38: 0.044312312
A39: Band B | B39: 138 | C39: 109 | D39: =C39/B39 -> 0.78985507 | E39: 0.039050459
A40: Band C | B40: 42 | C40: 34 | D40: =C40/B40 -> 0.80952381 | E40: 0.040932353
A41: Band D | B41: 7 | C41: 3 | D41: =C41/B41 -> 0.42857143 | E41: 0.0672 | G41: due to a great porportion of Band D below CR85%
...

Sheet 数据透视
A3: Adjusted basic increase/decreased % by DH | B3: (多项)
A5: 行标签 | B5: 平均值项:Adjusted basic increase/decreased % by DH | C5: 计数项:Pers.no. | D5: 求和项: Basic salary
A6: 1 | B6: -0.022 | C6: 1 | D6: 8937
A7: 2 | B7: 0.02016 | C7: 5 | D7: 74430
A8: 3 | B8: 0.029135082 | C8: 305 | D8: 4773822
A9: 4 | B9: 0.054025153 | C9: 163 | D9: 2641918
A10: 5 | B10: 0.083274627 | C10: 67 | D10: 1314375
A11: NA | B11: 0.06545 | C11: 2 | D11: 13420
A12: 总计 | B12: 0.043243831 | C12: 543 | D12: 8826902

Sheet 白领
A1: Company code | B1: Pers.no. | C1: Subgroup | D1: Area | E1: Subarea | F1: Dept. | G1: Cost ctr | H1: Join date | I1: Job | J1: Position | K1: Band Level | L1: Workplan type | M1: 2025 Performance Level | N1: Basic salary | O1: ① Merit increase % | P1: Merit Increase amount | Q1: ② Equity Increase% | R1: Equity Increase amount | S1: Total recommended Increase % (①+②) | T1: Total Recommended Increase amount | U1: Recommended new basic salary | V1: Adjutsed basic salary (input by DH) | W1: Adjutsed increased/decreased basic salary by DH | X1: Adjusted basic increase/decreased % by DH | Y1: Adjustment range reference | Z1: Promotion or demotion | AA1: New position title | AB1: New band | AC1: ③ Promotion increase/Demotion decrease % (±5%-±20%) | AD1: Promotion increase/Demotion decrease amount | AE1: Final new basic salary | AF1: Final increase/decrease amount | AG1: Final increase/decrease rate | AH1: Pay months | AI1: Monthly allowance/bonus | AJ1: Monthly Car Allowance | AK1: Other income(e.g.:festival bonus) | AL1: Annual target cash | AM1: 2024 Performance Level | AN1: Disciplinary Records | AO1: Justifications by DH | AP1: HR Remark | AQ1: Responsible ASR Manager | AR1: Responsible ASR HRBP | AS1: PY | AT1: 85% of LMW (for Technician/Counsellor) | AU1: Editable column 1 | AV1: Editable column 2 | AW1: - | AX1: Service Year | AY1: CR | AZ1: BSH CR | BA1: Dept CR
A2: CN15 | B2: 15000447 | C2: Indirect Active | D2: OP | E2: SNa | F2: FCGNa-VVP | G2: 330404 | H2: 38808 | I2: Workshop Leader | J2: Head of FCGNa-VVP | K2: BAND A6 | L2: 2 | M2: 5 | N2: 15840 | O2: 0.05 | P2: =ROUND(N2*O2,0) -> 792 | Q2: 0 | R2: =ROUND(N2*Q2,0) -> 0 | S2: =T2/N2 -> 0.05 | T2: =P2+R2 -> 792 | U2: =N2+T2 -> 16632 | V2: 16780 | W2: =V2-N2 -> 940 | X2: =ROUND(V2/N2-1,4) -> 0.0593 | Y2: =IF(OR(L2=1,L2=2,L2=4), TEXT(S2*0.8,"0.00%") & "-" & TEXT(S2*1.2,"0.00%"), IF(OR(L2=3,L2=6), TEXT(0,"0.00%") & "-" & TEXT(7%*1.2,"0.00%"), IF(OR(L2=5,L2=7), TEXT((R2/N2),"0.00%") & "-" & TEXT((R2/N2)+7%,"0.00%"), "" ) ) ) -> 4.00%-6.00% | AD2: =ROUND(N2*AC2,0) -> 0 | AE2: =V2+AD2 -> 16780 | AF2: =AE2-N2 -> 940 | AG2: =AE2/N2-1 -> 0.059343434 | AH2: 14 | AI2: 450 | AK2: 688 | AL2: =AE2*AH2+AI2*12+AK2+IF(AB2="",AJ2,IF(AB2="D",5000,IF(AB2="C",1000,0)))*12 -> 241008 | AM2: 4 | AQ2: Miao Siyuan（15005811） | AR2: Zhu Qianqian（11016705） | AS2: Zhao Chujun | AW2: =_xlfn.LET(_xlpm.actual,X2,_xlpm.low,VALUE(_xlfn.TEXTBEFORE(Y2,"-")),_xlpm.high,VALUE(_xlfn.TEXTAFTER(Y2,"-")),IF(AND(_xlpm.actual=0,OR(_xlpm.low<>0,_xlpm.high<>0)),"0 increase",IF(_xlpm.actual>_xlpm.high*1.2,">20",IF(_xlpm.actual<_xlpm.low*0.8,"<20","OK")))) -> OK | AX2: 16-20 | AY2: 70-90
A3: CN15 | B3: 15014416 | C3: Indirect Active | D3: OP | E3: SNa | F3: FCGNa-VVE | G3: 330404 | H3: 45063 | I3: Supervisor | J3: Head of Engineering Ventilation | K3: BAND A6 | L3: 2 | M3: 4 | N3: 16456 | O3: 0.045 | P3: =ROUND(N3*O3,0) -> 741 | Q3: 0.0155 | R3: =ROUND(N3*Q3,0) -> 255 | S3: =T3/N3 -> 0.060525036 | T3: =P3+R3 -> 996 | U3: =N3+T3 -> 17452 | V3: 17456 | W3: =V3-N3 -> 1000 | X3: =ROUND(V3/N3-1,4) -> 0.0608 | Y3: =IF(OR(L3=1,L3=2,L3=4), TEXT(S3*0.8,"0.00%") & "-" & TEXT(S3*1.2,"0.00%"), IF(OR(L3=3,L3=6), TEXT(0,"0.00%") & "-" & TEXT(7%*1.2,"0.00%"), IF(OR(L3=5,L3=7), TEXT((R3/N3),"0.00%") & "-" & TEXT((R3/N3)+7%,"0.00%"), "" ) ) ) -> 4.84%-7.26% | AD3: =ROUND(N3*AC3,0) -> 0 | AE3: =V3+AD3 -> 17456 | AF3: =AE3-N3 -> 1000 | AG3: =AE3/N3-1 -> 0.060768109 | AH3: 14 | AI3: 450 | AK3: 688 | AL3: =AE3*AH3+AI3*12+AK3+IF(AB3="",AJ3,IF(AB3="D",5000,IF(AB3="C",1000,0)))*12 -> 250472 | AM3: 5 | AQ3: Miao Siyuan（15005811） | AR3: Zhu Qianqian（11016705） | AS3: Zhao Chujun | AW3: =_xlfn.LET(_xlpm.actual,X3,_xlpm.low,VALUE(_xlfn.TEXTBEFORE(Y3,"-")),_xlpm.high,VALUE(_xlfn.TEXTAFTER(Y3,"-")),IF(AND(_xlpm.actual=0,OR(_xlpm.low<>0,_xlpm.high<>0)),"0 increase",IF(_xlpm.actual>_xlpm.high*1.2,">20",IF(_xlpm.actual<_xlpm.low*0.8,"<20","OK")))) -> OK | AX3: 0-5 | AY3: 50-70
A4: CN15 | B4: 15014868 | C4: Indirect Active | D4: OP | E4: SNa | F4: FCGNa-VVE | G4: 330404 | H4: 42291 | I4: Project Manager | J4: Project Manager | K4: BAND A6 | L4: 2 | M4: 3 | N4: 13630 | O4: 0.03 | P4: =ROUND(N4*O4,0) -> 409 | Q4: 0 | R4: =ROUND(N4*Q4,0) -> 0 | S4: =T4/N4 -> 0.030007337 | T4: =P4+R4 -> 409 | U4: =N4+T4 -> 14039 | V4: 14038 | W4: =V4-N4 -> 408 | X4: =ROUND(V4/N4-1,4) -> 0.0299 | Y4: =IF(OR(L4=1,L4=2,L4=4), TEXT(S4*0.8,"0.00%") & "-" & TEXT(S4*1.2,"0.00%"), IF(OR(L4=3,L4=6), TEXT(0,"0.00%") & "-" & TEXT(7%*1.2,"0.00%"), IF(OR(L4=5,L4=7), TEXT((R4/N4),"0.00%") & "-" & TEXT((R4/N4)+7%,"0.00%"), "" ) ) ) -> 2.40%-3.60% | AD4: =ROUND(N4*AC4,0) -> 0 | AE4: =V4+AD4 -> 14038 | AF4: =AE4-N4 -> 408 | AG4: =AE4/N4-1 -> 0.029933969 | AH4: 14 | AI4: 450 | AK4: 688 | AL4: =AE4*AH4+AI4*12+AK4+IF(AB4="",AJ4,IF(AB4="D",5000,IF(AB4="C",1000,0)))*12 -> 202620 | AM4: 4 | AQ4: Miao Siyuan（15005811） | AR4: Zhu Qianqian（11016705） | AS4: Zhao Chujun | AW4: =_xlfn.LET(_xlpm.actual,X4,_xlpm.low,VALUE(_xlfn.TEXTBEFORE(Y4,"-")),_xlpm.high,VALUE(_xlfn.TEXTAFTER(Y4,"-")),IF(AND(_xlpm.actual=0,OR(_xlpm.low<>0,_xlpm.high<>0)),"0 increase",IF(_xlpm.actual>_xlpm.high*1.2,">20",IF(_xlpm.actual<_xlpm.low*0.8,"<20","OK")))) -> OK | AX4: 6-10 | AY4: 50-70
A5: CN15 | B5: 15022166 | C5: Indirect Active | D5: OP | E5: SNa | F5: FCGNa-VVE | G5: 330404 | H5: 44664 | I5: Senior Engineer | J5: Senior Electrical Engineer | K5: BAND A5 | L5: 2 | M5: 4 | N5: 14440 | O5: 0.0375 | P5: =ROUND(N5*O5,0) -> 542 | Q5: 0 | R5: =ROUND(N5*Q5,0) -> 0 | S5: =T5/N5 -> 0.037534626 | T5: =P5+R5 -> 542 | U5: =N5+T5 -> 14982 | V5: 15000 | W5: =V5-N5 -> 560 | X5: =ROUND(V5/N5-1,4) -> 0.0388 | Y5: =IF(OR(L5=1,L5=2,L5=4), TEXT(S5*0.8,"0.00%") & "-" & TEXT(S5*1.2,"0.00%"), IF(OR(L5=3,L5=6), TEXT(0,"0.00%") & "-" & TEXT(7%*1.2,"0.00%"), IF(OR(L5=5,L5=7), TEXT((R5/N5),"0.00%") & "-" & TEXT((R5/N5)+7%,"0.00%"), "" ) ) ) -> 3.00%-4.50% | AD5: =ROUND(N5*AC5,0) -> 0 | AE5: =V5+AD5 -> 15000 | AF5: =AE5-N5 -> 560 | AG5: =AE5/N5-1 -> 0.038781163 | AH5: 14 | AI5: 450 | AK5: 688 | AL5: =AE5*AH5+AI5*12+AK5+IF(AB5="",AJ5,IF(AB5="D",5000,IF(AB5="C",1000,0)))*12 -> 216088 | AM5: 2 | AQ5: Miao Siyuan（15005811） | AR5: Zhu Qianqian（11016705） | AS5: Zhao Chujun | AW5: =_xlfn.LET(_xlpm.actual,X5,_xlpm.low,VALUE(_xlfn.TEXTBEFORE(Y5,"-")),_xlpm.high,VALUE(_xlfn.TEXTAFTER(Y5,"-")),IF(AND(_xlpm.actual=0,OR(_xlpm.low<>0,_xlpm.high<>0)),"0 increase",IF(_xlpm.actual>_xlpm.high*1.2,">20",IF(_xlpm.actual<_xlpm.low*0.8,"<20","OK")))) -> OK | AX5: 0-5 | AY5: 70-90
A6: CN15 | B6: 15016337 | C6: Indirect Active | D6: OP | E6: SNa | F6: FCGNa-VVE | G6: 330404 | H6: 42795 | I6: Functional Specialist | J6: Functional Specialist | K6: BAND A6 | L6: 2 | M6: 3 | N6: 14284 | O6: 0.03 | P6: =ROUND(N6*O6,0) -> 429 | Q6: 0 | R6: =ROUND(N6*Q6,0) -> 0 | S6: =T6/N6 -> 0.030033604 | T6: =P6+R6 -> 429 | U6: =N6+T6 -> 14713 | V6: 14688 | W6: =V6-N6 -> 404 | X6: =ROUND(V6/N6-1,4) -> 0.0283 | Y6: =IF(OR(L6=1,L6=2,L6=4), TEXT(S6*0.8,"0.00%") & "-" & TEXT(S6*1.2,"0.00%"), IF(OR(L6=3,L6=6), TEXT(0,"0.00%") & "-" & TEXT(7%*1.2,"0.00%"), IF(OR(L6=5,L6=7), TEXT((R6/N6),"0.00%") & "-" & TEXT((R6/N6)+7%,"0.00%"), "" ) ) ) -> 2.40%-3.60% | AD6: =ROUND(N6*AC6,0) -> 0 | AE6: =V6+AD6 -> 14688 | AF6: =AE6-N6 -> 404 | AG6: =AE6/N6-1 -> 0.028283394 | AH6: 14 | AI6: 450 | AK6: 688 | AL6: =AE6*AH6+AI6*12+AK6+IF(AB6="",AJ6,IF(AB6="D",5000,IF(AB6="C",1000,0)))*12 -> 211720 | AM6: 2 | AQ6: Miao Siyuan（15005811） | AR6: Zhu Qianqian（11016705） | AS6: Zhao Chujun | AW6: =_xlfn.LET(_xlpm.actual,X6,_xlpm.low,VALUE(_xlfn.TEXTBEFORE(Y6,"-")),_xlpm.high,VALUE(_xlfn.TEXTAFTER(Y6,"-")),IF(AND(_xlpm.actual=0,OR(_xlpm.low<>0,_xlpm.high<>0)),"0 increase",IF(_xlpm.actual>_xlpm.high*1.2,">20",IF(_xlpm.actual<_xlpm.low*0.8,"<20","OK")))) -> OK | AX6: 6-10 | AY6: 50-70
A7: CN15 | B7: 15022630 | C7: Indirect Active | D7: OP | E7: SNa | F7: FCGNa-VVE | G7: 330408 | H7: 45854 | I7: Functional Specialist | J7: Painting Functional Specialist | K7: BAND A6 | L7: 2 | M7: 3 | N7: 23000 | O7: 0 | P7: =ROUND(N7*O7,0) -> 0 | Q7: 0 | R7: =ROUND(N7*Q7,0) -> 0 | S7: =T7/N7 -> 0 | T7: =P7+R7 -> 0 | U7: =N7+T7 -> 23000 | V7: 23000 | W7: =V7-N7 -> 0 | X7: =ROUND(V7/N7-1,4) -> 0 | Y7: =IF(OR(L7=1,L7=2,L7=4), TEXT(S7*0.8,"0.00%") & "-" & TEXT(S7*1.2,"0.00%"), IF(OR(L7=3,L7=6), TEXT(0,"0.00%") & "-" & TEXT(7%*1.2,"0.00%"), IF(OR(L7=5,L7=7), TEXT((R7/N7),"0.00%") & "-" & TEXT((R7/N7)+7%,"0.00%"), "" ) ) ) -> 0.00%-0.00% | AD7: =ROUND(N7*AC7,0) -> 0 | AE7: =V7+AD7 -> 23000 | AF7: =AE7-N7 -> 0 | AG7: =AE7/N7-1 -> 0 | AH7: 14 | AI7: 450 | AK7: 688 | AL7: =AE7*AH7+AI7*12+AK7+IF(AB7="",AJ7,IF(AB7="D",5000,IF(AB7="C",1000,0)))*12 -> 328088 | AM7: #N/A | AQ7: Miao Siyuan（15005811） | AR7: Zhu Qianqian（11016705） | AS7: Zhao Chujun | AW7: =_xlfn.LET(_xlpm.actual,X7,_xlpm.low,VALUE(_xlfn.TEXTBEFORE(Y7,"-")),_xlpm.high,VALUE(_xlfn.TEXTAFTER(Y7,"-")),IF(AND(_xlpm.actual=0,OR(_xlpm.low<>0,_xlpm.high<>0)),"0 increase",IF(_xlpm.actual>_xlpm.high*1.2,">20",IF(_xlpm.actual<_xlpm.low*0.8,"<20","OK")))) -> OK | AX7: 0-5 | AY7: >90
A8: CN15 | B8: 15007556 | C8: Indirect Active | D8: OP | E8: SNa | F8: FCGNa-VVM | G8: 330204 | H8: 40962 | I8: Supervisor | J8: Head of FCGNa-VVM | K8: BAND A6 | L8: 2 | M8: 3 | N8: 16100 | O8: 0.025 | P8: =ROUND(N8*O8,0) -> 403 | Q8: 0 | R8: =ROUND(N8*Q8,0) -> 0 | S8: =T8/N8 -> 0.025031056 | T8: =P8+R8 -> 403 | U8: =N8+T8 -> 16503 | V8: 16518 | W8: =V8-N8 -> 418 | X8: =ROUND(V8/N8-1,4) -> 0.026 | Y8: =IF(OR(L8=1,L8=2,L8=4), TEXT(S8*0.8,"0.00%") & "-" & TEXT(S8*1.2,"0.00%"), IF(OR(L8=3,L8=6), TEXT(0,"0.00%") & "-" & TEXT(7%*1.2,"0.00%"), IF(OR(L8=5,L8=7), TEXT((R8/N8),"0.00%") & "-" & TEXT((R8/N8)+7%,"0.00%"), "" ) ) ) -> 2.00%-3.00% | AD8: =ROUND(N8*AC8,0) -> 0 | AE8: =V8+AD8 -> 16518 | AF8: =AE8-N8 -> 418 | AG8: =AE8/N8-1 -> 0.025962733 | AH8: 14 | AI8: 450 | AK8: 688 | AL8: =AE8*AH8+AI8*12+AK8+IF(AB8="",AJ8,IF(AB8="D",5000,IF(AB8="C",1000,0)))*12 -> 237340 | AM8: 3 | AQ8: Miao Siyuan（15005811） | AR8: Zhu Qianqian（11016705） | AS8: Zhao Chujun | AW8: =_xlfn.LET(_xlpm.actual,X8,_xlpm.low,VALUE(_xlfn.TEXTBEFORE(Y8,"-")),_xlpm.high,VALUE(_xlfn.TEXTAFTER(Y8,"-")),IF(AND(_xlpm.actual=0,OR(_xlpm.low<>0,_xlpm.high<>0)),"0 increase",IF(_xlpm.actual>_xlpm.high*1.2,">20",IF(_xlpm.actual<_xlpm.low*0.8,"<20","OK")))) -> OK | AX8: 11-15 | AY8: 70-90
A9: CN15 | B9: 1120246 | C9: Indirect Active | D9: OP | E9: SNa | F9: FCGNa-VVE | G9: 330404 | H9: 43864 | I9: Functional Specialist | J9: Functional Specialist | K9: BAND A6 | L9: 2 | M9: 4 | N9: 13111 | O9: 0.045 | P9: =ROUND(N9*O9,0) -> 590 | Q9: 0.0421 | R9: =ROUND(N9*Q9,0) -> 552 | S9: =T9/N9 -> 0.087102433 | T9: =P9+R9 -> 1142 | U9: =N9+T9 -> 14253 | V9: 14066 | W9: =V9-N9 -> 955 | X9: =ROUND(V9/N9-1,4) -> 0.0728 | Y9: =IF(OR(L9=1,L9=2,L9=4), TEXT(S9*0.8,"0.00%") & "-" & TEXT(S9*1.2,"0.00%"), IF(OR(L9=3,L9=6), TEXT(0,"0.00%") & "-" & TEXT(7%*1.2,"0.00%"), IF(OR(L9=5,L9=7), TEXT((R9/N9),"0.00%") & "-" & TEXT((R9/N9)+7%,"0.00%"), "" ) ) ) -> 6.97%-10.45% | AD9: =ROUND(N9*AC9,0) -> 0 | AE9: =V9+AD9 -> 14066 | AF9: =AE9-N9 -> 955 | AG9: =AE9/N9-1 -> 0.0728396 | AH9: 14 | AI9: 850 | AK9: 688 | AL9: =AE9*AH9+AI9*12+AK9+IF(AB9="",AJ9,IF(AB9="D",5000,IF(AB9="C",1000,0)))*12 -> 207812 | AM9: 3 | AQ9: Miao Siyuan（15005811） | AR9: Zhu Qianqian（11016705） | AS9: Zhao Chujun | AW9: =_xlfn.LET(_xlpm.actual,X9,_xlpm.low,VALUE(_xlfn.TEXTBEFORE(Y9,"-")),_xlpm.high,VALUE(_xlfn.TEXTAFTER(Y9,"-")),IF(AND(_xlpm.actual=0,OR(_xlpm.low<>0,_xlpm.high<>0)),"0 increase",IF(_xlpm.actual>_xlpm.high*1.2,">20",IF(_xlpm.actual<_xlpm.low*0.8,"<20","OK")))) -> OK | AX9: 6-10 | AY9: 50-70
A10: CN15 | B10: 15000219 | C10: Indirect Active | D10: OP | E10: SNa | F10: FCGNa-VVE | G10: 330404 | H10: 38608 | I10: Engineer | J10: Project Engineer | K10: BAND A4 | L10: 2 | M10: 2 | N10: 12256 | O10: 0 | P10: =ROUND(N10*O10,0) -> 0 | Q10: 0 | R10: =ROUND(N10*Q10,0) -> 0 | S10: =T10/N10 -> 0 | T10: =P10+R10 -> 0 | U10: =N10+T10 -> 12256 | V10: 12256 | W10: =V10-N10 -> 0 | X10: =ROUND(V10/N10-1,4) -> 0 | Y10: =IF(OR(L10=1,L10=2,L10=4), TEXT(S10*0.8,"0.00%") & "-" & TEXT(S10*1.2,"0.00%"), IF(OR(L10=3,L10=6), TEXT(0,"0.00%") & "-" & TEXT(7%*1.2,"0.00%"), IF(OR(L10=5,L10=7), TEXT((R10/N10),"0.00%") & "-" & TEXT((R10/N10)+7%,"0.00%"), "" ) ) ) -> 0.00%-0.00% | AD10: =ROUND(N10*AC10,0) -> 0 | AE10: =V10+AD10 -> 12256 | AF10: =AE10-N10 -> 0 | AG10: =AE10/N10-1 -> 0 | AH10: 14 | AI10: 450 | AK10: 688 | AL10: =AE10*AH10+AI10*12+AK10+IF(AB10="",AJ10,IF(AB10="D",5000,IF(AB10="C",1000,0)))*12 -> 177672 | AM10: 3 | AQ10: Miao Siyuan（15005811） | AR10: Zhu Qianqian（11016705） | AS10: Zhao Chujun | AW10: =_xlfn.LET(_xlpm.actual,X10,_xlpm.low,VALUE(_xlfn.TEXTBEFORE(Y10,"-")),_xlpm.high,VALUE(_xlfn.TEXTAFTER(Y10,"-")),IF(AND(_xlpm.actual=0,OR(_xlpm.low<>0,_xlpm.high<>0)),"0 increase",IF(_xlpm.actual>_xlpm.high*1.2,">20",IF(_xlpm.actual<_xlpm.low*0.8,"<20","OK")))) -> OK | AX10: 16-20 | AY10: 0
A11: CN15 | B11: 15014810 | C11: Indirect Active | D11: OP | E11: SNa | F11: FCGNa-VVE | G11: 330404 | H11: 42248 | I11: Senior Specialist | J11: Senior IE Specialist | K11: BAND A5 | L11: 2 | M11: 4 | N11: 11666 | O11: 0.0375 | P11: =ROUND(N11*O11,0) -> 437 | Q11: 0.0155 | R11: =ROUND(N11*Q11,0) -> 181 | S11: =T11/N11 -> 0.052974456 | T11: =P11+R11 -> 618 | U11: =N11+T11 -> 12284 | V11: 12312 | W11: =V11-N11 -> 646 | X11: =ROUND(V11/N11-1,4) -> 0.0554 | Y11: =IF(OR(L11=1,L11=2,L11=4), TEXT(S11*0.8,"0.00%") & "-" & TEXT(S11*1.2,"0.00%"), IF(OR(L11=3,L11=6), TEXT(0,"0.00%") & "-" & TEXT(7%*1.2,"0.00%"), IF(OR(L11=5,L11=7), TEXT((R11/N11),"0.00%") & "-" & TEXT((R11/N11)+7%,"0.00%"), "" ) ) ) -> 4.24%-6.36% | Z11: Promotion | AA11: Function specialist | AB11: A6 | AC11: 0.0646 | AD11: =ROUND(N11*AC11,0) -> 754 | AE11: =V11+AD11 -> 13066 | AF11: =AE11-N11 -> 1400 | AG11: =AE11/N11-1 -> 0.12000686 | AH11: 14 | AI11: 550 | AK11: 688 | AL11: =AE11*AH11+AI11*12+AK11+IF(AB11="",AJ11,IF(AB11="D",5000,IF(AB11="C",1000,0)))*12 -> 190212 | AM11: 4 | AO11: Good performance and high competence | AP11: Good performance and high competence | AQ11: Miao Siyuan（15005811） | AR11: Zhu Qianqian（11016705） | AS11: Zhao Chujun | AW11: =_xlfn.LET(_xlpm.actual,X11,_xlpm.low,VALUE(_xlfn.TEXTBEFORE(Y11,"-")),_xlpm.high,VALUE(_xlfn.TEXTAFTER(Y11,"-")),IF(AND(_xlpm.actual=0,OR(_xlpm.low<>0,_xlpm.high<>0)),"0 increase",IF(_xlpm.actual>_xlpm.high*1.2,">20",IF(_xlpm.actual<_xlpm.low*0.8,"<20","OK")))) -> OK | AX11: 6-10 | AY11: 70-90
A12: CN15 | B12: 15000226 | C12: Indirect Active | D12: OP | E12: SNa | F12: FCGNa-VCP | G12: 330405 | H12: 38614 | I12: Workshop Leader | J12: Head of FCGNa-VCP | K12: BAND A6 | L12: 2 | M12: 3 | N12: 15800 | O12: 0.025 | P12: =ROUND(N12*O12,0) -> 395 | Q12: 0 | R12: =ROUND(N12*Q12,0) -> 0 | S12: =T12/N12 -> 0.025 | T12: =P12+R12 -> 395 | U12: =N12+T12 -> 16195 | V12: 16272 | W12: =V12-N12 -> 472 | X12: =ROUND(V12/N12-1,4) -> 0.0299 | Y12: =IF(OR(L12=1,L12=2,L12=4), TEXT(S12*0.8,"0.00%") & "-" & TEXT(S12*1.2,"0.00%"), IF(OR(L12=3,L12=6), TEXT(0,"0.00%") & "-" & TEXT(7%*1.2,"0.00%"), IF(OR(L12=5,L12=7), TEXT((R12/N12),"0.00%") & "-" & TEXT((R12/N12)+7%,"0.00%"), "" ) ) ) -> 2.00%-3.00% | AD12: =ROUND(N12*AC12,0) -> 0 | AE12: =V12+AD12 -> 16272 | AF12: =AE12-N12 -> 472 | AG12: =AE12/N12-1 -> 0.029873418 | AH12: 14 | AI12: 450 | AK12: 688 | AL12: =AE12*AH12+AI12*12+AK12+IF(AB12="",AJ12,IF(AB12="D",5000,IF(AB12="C",1000,0)))*12 -> 233896 | AM12: 5 | AQ12: Liu Haigang（15013255） | AR12: Zhu Qianqian（11016705） | AS12: Zhao Chujun | AW12: =_xlfn.LET(_xlpm.actual,X12,_xlpm.low,VALUE(_xlfn.TEXTBEFORE(Y12,"-")),_xlpm.high,VALUE(_xlfn.TEXTAFTER(Y12,"-")),IF(AND(_xlpm.actual=0,OR(_xlpm.low<>0,_xlpm.high<>0)),"0 increase",IF(_xlpm.actual>_xlpm.high*1.2,">20",IF(_xlpm.actual<_xlpm.low*0.8,"<20","OK")))) -> OK | AX12: 16-20 | AY12: 70-90
A13: CN15 | B13: 15000166 | C13: Indirect Active | D13: OP | E13: SNa | F13: FCGNa-VCE | G13: 330405 | H13: 38600 | I13: Senior Engineer | J13: Senior Engineer | K13: BAND A5 | L13: 2 | M13: 3 | N13: 14610 | O13: 0.025 | P13: =ROUND(N13*O13,0) -> 365 | Q13: 0 | R13: =ROUND(N13*Q13,0) -> 0 | S13: =T13/N13 -> 0.024982888 | T13: =P13+R13 -> 365 | U13: =N13+T13 -> 14975 | V13: 14610 | W13: =V13-N13 -> 0 | X13: =ROUND(V13/N13-1,4) -> 0 | Y13: =IF(OR(L13=1,L13=2,L13=4), TEXT(S13*0.8,"0.00%") & "-" & TEXT(S13*1.2,"0.00%"), IF(OR(L13=3,L13=6), TEXT(0,"0.00%") & "-" & TEXT(7%*1.2,"0.00%"), IF(OR(L13=5,L13=7), TEXT((R13/N13),"0.00%") & "-" & TEXT((R13/N13)+7%,"0.00%"), "" ) ) ) -> 2.00%-3.00% | AD13: =ROUND(N13*AC13,0) -> 0 | AE13: =V13+AD13 -> 14610 | AF13: =AE13-N13 -> 0 | AG13: =AE13/N13-1 -> 0 | AH13: 14 | AI13: 450 | AK13: 688 | AL13: =AE13*AH13+AI13*12+AK13+IF(AB13="",AJ13,IF(AB13="D",5000,IF(AB13="C",1000,0)))*12 -> 210628 | AM13: 3 | AO13: Only focus on route tasks, lack of innovation and new product maturity improvement | AP13: Less responsibility compare with job level | AQ13: Liu Haigang（15013255） | AR13: Zhu Qianqian（11016705） | AS13: Zhao Chujun | AU13: recommend increasing but propose zero increase | AW13: =_xlfn.LET(_xlpm.actual,X13,_xlpm.low,VALUE(_xlfn.TEXTBEFORE(Y13,"-")),_xlpm.high,VALUE(_xlfn.TEXTAFTER(Y13,"-")),IF(AND(_xlpm.actual=0,OR(_xlpm.low<>0,_xlpm.high<>0)),"0 increase",IF(_xlpm.actual>_xlpm.high*1.2,">20",IF(_xlpm.actual<_xlpm.low*0.8,"<20","OK")))) -> 0 increase | AX13: 16-20 | AY13: 70-90
A14: CN15 | B14: 15007522 | C14: Indirect Active | D14: OP | E14: SNa | F14: FCGNa-VCE | G14: 330405 | H14: 41091 | I14: Supervisor | J14: Head of FCGNa-VCE | K14: BAND A6 | L14: 2 | M14: 3 | N14: 13100 | O14: 0.03 | P14: =ROUND(N14*O14,0) -> 393 | Q14: 0 | R14: =ROUND(N14*Q14,0) -> 0 | S14: =T14/N14 -> 0.03 | T14: =P14+R14 -> 393 | U14: =N14+T14 -> 13493 | V14: 14312 | W14: =V14-N14 -> 1212 | X14: =ROUND(V14/N14-1,4) -> 0.0925 | Y14: =IF(OR(L14=1,L14=2,L14=4), TEXT(S14*0.8,"0.00%") & "-" & TEXT(S14*1.2,"0.00%"), IF(OR(L14=3,L14=6), TEXT(0,"0.00%") & "-" & TEXT(7%*1.2,"0.00%"), IF(OR(L14=5,L14=7), TEXT((R14/N14),"0.00%") & "-" & TEXT((R14/N14)+7%,"0.00%"), "" ) ) ) -> 2.40%-3.60% | AD14: =ROUND(N14*AC14,0) -> 0 | AE14: =V14+AD14 -> 14312 | AF14: =AE14-N14 -> 1212 | AG14: =AE14/N14-1 -> 0.092519084 | AH14: 14 | AI14: 450 | AK14: 688 | AL14: =AE14*AH14+AI14*12+AK14+IF(AB14="",AJ14,IF(AB14="D",5000,IF(AB14="C",1000,0)))*12 -> 206456 | AM14: 2 | AO14: 1. In 2025, he achieved an 11% reduction in cooker SPC and cut silicone usage by 50%. 2. As a supervisor, his salary is the lowest in the team, so I need to catch up appropriately. | AP14: Good performers with relatively lower salary | AQ14: Liu Haigang（15013255） | AR14: Zhu Qianqian（11016705） | AS14: Zhao Chujun | AU14: exceed +/-20% adjustment | AV14: >20 | AW14: =_xlfn.LET(_xlpm.actual,X14,_xlpm.low,VALUE(_xlfn.TEXTBEFORE(Y14,"-")),_xlpm.high,VALUE(_xlfn.TEXTAFTER(Y14,"-")),IF(AND(_xlpm.actual=0,OR(_xlpm.low<>0,_xlpm.high<>0)),"0 increase",IF(_xlpm.actual>_xlpm.high*1.2,">20",IF(_xlpm.actual<_xlpm.low*0.8,"<20","OK")))) -> >20 | AX14: 11-15 | AY14: 50-70
A15: CN15 | B15: 15001471 | C15: Indirect Active | D15: OP | E15: SNa | F15: FCGNa-VCM | G15: 330405 | H15: 39546 | I15: Supervisor | J15: Head of FCGNa-VCM | K15: BAND A6 | L15: 2 | M15: 3 | N15: 15326 | O15: 0.03 | P15: =ROUND(N15*O15,0) -> 460 | Q15: 0 | R15: =ROUND(N15*Q15,0) -> 0 | S15: =T15/N15 -> 0.030014355 | T15: =P15+R15 -> 460 | U15: =N15+T15 -> 15786 | V15: 15326 | W15: =V15-N15 -> 0 | X15: =ROUND(V15/N15-1,4) -> 0 | Y15: =IF(OR(L15=1,L15=2,L15=4), TEXT(S15*0.8,"0.00%") & "-" & TEXT(S15*1.2,"0.00%"), IF(OR(L15=3,L15=6), TEXT(0,"0.00%") & "-" & TEXT(7%*1.2,"0.00%"), IF(OR(L15=5,L15=7), TEXT((R15/N15),"0.00%") & "-" & TEXT((R15/N15)+7%,"0.00%"), "" ) ) ) -> 2.40%-3.60% | AD15: =ROUND(N15*AC15,0) -> 0 | AE15: =V15+AD15 -> 15326 | AF15: =AE15-N15 -> 0 | AG15: =AE15/N15-1 -> 0 | AH15: 14 | AI15: 450 | AK15: 688 | AL15: =AE15*AH15+AI15*12+AK15+IF(AB15="",AJ15,IF(AB15="D",5000,IF(AB15="C",1000,0)))*12 -> 220652 | AM15: 4 | AO15: Low performance as supervisor | AP15: Low performer | AQ15: Liu Haigang（15013255） | AR15: Zhu Qianqian（11016705） | AS15: Zhao Chujun | AU15: recommend increasing but propose zero increase | AW15: =_xlfn.LET(_xlpm.actual,X15,_xlpm.low,VALUE(_xlfn.TEXTBEFORE(Y15,"-")),_xlpm.high,VALUE(_xlfn.TEXTAFTER(Y15,"-")),IF(AND(_xlpm.actual=0,OR(_xlpm.low<>0,_xlpm.high<>0)),"0 increase",IF(_xlpm.actual>_xlpm.high*1.2,">20",IF(_xlpm.actual<_xlpm.low*0.8,"<20","OK")))) -> 0 increase | AX15: 16-20 | AY15: 50-70
A16: CN15 | B16: 15022189 | C16: Indirect Active | D16: OP | E16: SNa | F16: FCGNa-VCE | G16: 330401 | H16: 44713 | I16: Senior Engineer | J16: Press Senior Engineer | K16: BAND A5 | L16: 2 | M16: 3 | N16: 14850 | O16: 0.025 | P16: =ROUND(N16*O16,0) -> 371 | Q16: 0 | R16: =ROUND(N16*Q16,0) -> 0 | S16: =T16/N16 -> 0.024983165 | T16: =P16+R16 -> 371 | U16: =N16+T16 -> 15221 | V16: 15150 | W16: =V16-N16 -> 300 | X16: =ROUND(V16/N16-1,4) -> 0.0202 | Y16: =IF(OR(L16=1,L16=2,L16=4), TEXT(S16*0.8,"0.00%") & "-" & TEXT(S16*1.2,"0.00%"), IF(OR(L16=3,L16=6), TEXT(0,"0.00%") & "-" & TEXT(7%*1.2,"0.00%"), IF(OR(L16=5,L16=7), TEXT((R16/N16),"0.00%") & "-" & TEXT((R16/N16)+7%,"0.00%"), "" ) ) ) -> 2.00%-3.00% | AD16: =ROUND(N16*AC16,0) -> 0 | AE16: =V16+AD16 -> 15150 | AF16: =AE16-N16 -> 300 | AG16: =AE16/N16-1 -> 0.02020202 | AH16: 14 | AI16: 450 | AK16: 688 | AL16: =AE16*AH16+AI16*12+AK16+IF(AB16="",AJ16,IF(AB16="D",5000,IF(AB16="C",1000,0)))*12 -> 218188 | AM16: 3 | AQ16: Liu Haigang（15013255） | AR16: Zhu Qianqian（11016705） | AS16: Zhao Chujun | AW16: =_xlfn.LET(_xlpm.actual,X16,_xlpm.low,VALUE(_xlfn.TEXTBEFORE(Y16,"-")),_xlpm.high,VALUE(_xlfn.TEXTAFTER(Y16,"-")),IF(AND(_xlpm.actual=0,OR(_xlpm.low<>0,_xlpm.high<>0)),"0 increase",IF(_xlpm.actual>_xlpm.high*1.2,">20",IF(_xlpm.actual<_xlpm.low*0.8,"<20","OK")))) -> OK | AX16: 0-5 | AY16: 70-90
A17: CN15 | B17: 15017481 | C17: Indirect Active | D17: OP | E17: SNa | F17: FCGNa-VCE | G17: 330405 | H17: 42893 | I17: Senior Engineer | J17: Senior Engineer | K17: BAND A5 | L17: 2 | M17: 2 | N17: 13610 | O17: 0 | P17: =ROUND(N17*O17,0) -> 0 | Q17: 0 | R17: =ROUND(N17*Q17,0) -> 0 | S17: =T17/N17 -> 0 | T17: =P17+R17 -> 0 | U17: =N17+T17 -> 13610 | V17: 13610 | W17: =V17-N17 -> 0 | X17: =ROUND(V17/N17-1,4) -> 0 | Y17: =IF(OR(L17=1,L17=2,L17=4), TEXT(S17*0.8,"0.00%") & "-" & TEXT(S17*1.2,"0.00%"), IF(OR(L17=3,L17=6), TEXT(0,"0.00%") & "-" & TEXT(7%*1.2,"0.00%"), IF(OR(L17=5,L17=7), TEXT((R17/N17),"0.00%") & "-" & TEXT((R17/N17)+7%,"0.00%"), "" ) ) ) -> 0.00%-0.00% | AD17: =ROUND(N17*AC17,0) -> 0 | AE17: =V17+AD17 -> 13610 | AF17: =AE17-N17 -> 0 | AG17: =AE17/N17-1 -> 0 | AH17: 14 | AI17: 550 | AK17: 688 | AL17: =AE17*AH17+AI17*12+AK17+IF(AB17="",AJ17,IF(AB17="D",5000,IF(AB17="C",1000,0)))*12 -> 197828 | AM17: 3 | AQ17: Liu Haigang（15013255） | AR17: Zhu Qianqian（11016705） | AS17: Zhao Chujun | AW17: =_xlfn.LET(_xlpm.actual,X17,_xlpm.low,VALUE(_xlfn.TEXTBEFORE(Y17,"-")),_xlpm.high,VALUE(_xlfn.TEXTAFTER(Y17,"-")),IF(AND(_xlpm.actual=0,OR(_xlpm.low<>0,_xlpm.high<>0)),"0 increase",IF(_xlpm.actual>_xlpm.high*1.2,">20",IF(_xlpm.actual<_xlpm.low*0.8,"<20","OK")))) -> OK | AX17: 6-10 | AY17: 0
A18: CN15 | B18: 15014900 | C18: Indirect Active | D18: OP | E18: SNa | F18: FCGNa | G18: 330100 | H18: 42298 | I18: Manager | J18: Manager | K18: BAND B | L18: 2 | M18: 2 | N18: 20200 | O18: 0 | P18: =ROUND(N18*O18,0) -> 0 | Q18: 0 | R18: =ROUND(N18*Q18,0) -> 0 | S18: =T18/N18 -> 0 | T18: =P18+R18 -> 0 | U18: =N18+T18 -> 20200 | V18: =U18 -> 20200 | W18: =V18-N18 -> 0 | X18: =ROUND(V18/N18-1,4) -> 0 | Y18: =IF(OR(L18=1,L18=2,L18=4), TEXT(S18*0.8,"0.00%") & "-" & TEXT(S18*1.2,"0.00%"), IF(OR(L18=3,L18=6), TEXT(0,"0.00%") & "-" & TEXT(7%*1.2,"0.00%"), IF(OR(L18=5,L18=7), TEXT((R18/N18),"0.00%") & "-" & TEXT((R18/N18)+7%,"0.00%"), "" ) ) ) -> 0.00%-0.00% | AD18: =ROUND(N18*AC18,0) -> 0 | AE18: =V18+AD18 -> 20200 | AF18: =AE18-N18 -> 0 | AG18: =AE18/N18-1 -> 0 | AH18: 14 | AI18: 450 | AK18: 688 | AL18: =AE18*AH18+AI18*12+AK18+IF(AB18="",AJ18,IF(AB18="D",5000,IF(AB18="C",1000,0)))*12 -> 288888 | AM18: 3 | AQ18: Chen Chao（15005032） | AR18: Zhu Qianqian（11016705） | AS18: Zhao Chujun | AW18: =_xlfn.LET(_xlpm.actual,X18,_xlpm.low,VALUE(_xlfn.TEXTBEFORE(Y18,"-")),_xlpm.high,VALUE(_xlfn.TEXTAFTER(Y18,"-")),IF(AND(_xlpm.actual=0,OR(_xlpm.low<>0,_xlpm.high<>0)),"0 increase",IF(_xlpm.actual>_xlpm.high*1.2,">20",IF(_xlpm.actual<_xlpm.low*0.8,"<20","OK")))) -> OK | AX18: 6-10 | AY18: 0
A19: CN15 | B19: 15013255 | C19: Indirect Active | D19: OP | E19: SNa | F19: FCGNa-VC | G19: 330405 | H19: 41801 | I19: Manager | J19: Head of Value Stream Cooktop | K19: BAND B | L19: 2 | M19: 4 | N19: 23800 | O19: 0.03 | P19: =ROUND(N19*O19,0) -> 714 | Q19: 0 | R19: =ROUND(N19*Q19,0) -> 0 | S19: =T19/N19 -> 0.03 | T19: =P19+R19 -> 714 | U19: =N19+T19 -> 24514 | V19: =U19 -> 24514 | W19: =V19-N19 -> 714 | X19: =ROUND(V19/N19-1,4) -> 0.03 | Y19: =IF(OR(L19=1,L19=2,L19=4), TEXT(S19*0.8,"0.00%") & "-" & TEXT(S19*1.2,"0.00%"), IF(OR(L19=3,L19=6), TEXT(0,"0.00%") & "-" & TEXT(7%*1.2,"0.00%"), IF(OR(L19=5,L19=7), TEXT((R19/N19),"0.00%") & "-" & TEXT((R19/N19)+7%,"0.00%"), "" ) ) ) -> 2.40%-3.60% | Z19: Promotion | AA19: Head of Value Stream Cooktop | AB19: C | AC19: 0.09 | AD19: =ROUND(N19*AC19,0) -> 2142 | AE19: =V19+AD19 -> 26656 | AF19: =AE19-N19 -> 2856 | AG19: =AE19/N19-1 -> 0.12 | AH19: 14 | AI19: 450 | AK19: 688 | AL19: =AE19*AH19+AI19*12+AK19+IF(AB19="",AJ19,IF(AB19="D",5000,IF(AB19="C",1000,0)))*12 -> 391272 | AM19: 5 | AO19: Good performance and high competence | AP19: Good performance and high competence | AQ19: Chen Chao（15005032） | AR19: Zhu Qianqian（11016705） | AS19: Zhao Chujun | AW19: =_xlfn.LET(_xlpm.actual,X19,_xlpm.low,VALUE(_xlfn.TEXTBEFORE(Y19,"-")),_xlpm.high,VALUE(_xlfn.TEXTAFTER(Y19,"-")),IF(AND(_xlpm.actual=0,OR(_xlpm.low<>0,_xlpm.high<>0)),"0 increase",IF(_xlpm.actual>_xlpm.high*1.2,">20",IF(_xlpm.actual<_xlpm.low*0.8,"<20","OK")))) -> OK | AX19: 11-15 | AY19: 90-110
A20: CN15 | B20: 15005811 | C20: Indirect Active | D20: OP | E20: SNa | F20: FCGNa-VV | G20: 330404 | H20: 40646 | I20: Manager | J20: Head of Value Stream Ventilation | K20: BAND B | L20: 2 | M20: 5 | N20: 24500 | O20: 0.04 | P20: =ROUND(N20*O20,0) -> 980 | Q20: 0 | R20: =ROUND(N20*Q20,0) -> 0 | S20: =T20/N20 -> 0.04 | T20: =P20+R20 -> 980 | U20: =N20+T20 -> 25480 | V20: =U20 -> 25480 | W20: =V20-N20 -> 980 | X20: =ROUND(V20/N20-1,4) -> 0.04 | Y20: =IF(OR(L20=1,L20=2,L20=4), TEXT(S20*0.8,"0.00%") & "-" & TEXT(S20*1.2,"0.00%"), IF(OR(L20=3,L20=6), TEXT(0,"0.00%") & "-" & TEXT(7%*1.2,"0.00%"), IF(OR(L20=5,L20=7), TEXT((R20/N20),"0.00%") & "-" & TEXT((R20/N20)+7%,"0.00%"), "" ) ) ) -> 3.20%-4.80% | Z20: Promotion | AA20: Head of Value Stream Ventilation | AB20: C | AC20: 0.08 | AD20: =ROUND(N20*AC20,0) -> 1960 | AE20: =V20+AD20 -> 27440 | AF20: =AE20-N20 -> 2940 | AG20: =AE20/N20-1 -> 0.12 | AH20: 14 | AI20: 450 | AK20: 688 | AL20: =AE20*AH20+AI20*12+AK20+IF(AB20="",AJ20,IF(AB20="D",5000,IF(AB20="C",1000,0)))*12 -> 402248 | AM20: 3 | AO20: Good performance and high competence | AP20: Good performance and high competence | AQ20: Chen Chao（15005032） | AR20: Zhu Qianqian（11016705） | AS20: Zhao Chujun | AW20: =_xlfn.LET(_xlpm.actual,X20,_xlpm.low,VALUE(_xlfn.TEXTBEFORE(Y20,"-")),_xlpm.high,VALUE(_xlfn.TEXTAFTER(Y20,"-")),IF(AND(_xlpm.actual=0,OR(_xlpm.low<>0,_xlpm.high<>0)),"0 increase",IF(_xlpm.actual>_xlpm.high*1.2,">20",IF(_xlpm.actual<_xlpm.low*0.8,"<20","OK")))) -> OK | AX20: 11-15 | AY20: 90-110
A21: CN15 | B21: 15022316 | C21: Indirect Active | D21: OP | E21: SNa | F21: FCGNa | G21: 330100 | H21: 44930 | I21: Senior Engineer | J21: Senior Testing and Programming Engineer | K21: BAND A5 | L21: 2 | M21: 3 | N21: 14375 | O21: 0.025 | P21: =ROUND(N21*O21,0) -> 359 | Q21: 0 | R21: =ROUND(N21*Q21,0) -> 0 | S21: =T21/N21 -> 0.024973913 | T21: =P21+R21 -> 359 | U21: =N21+T21 -> 14734 | V21: =U21 -> 14734 | W21: =V21-N21 -> 359 | X21: =ROUND(V21/N21-1,4) -> 0.025 | Y21: =IF(OR(L21=1,L21=2,L21=4), TEXT(S21*0.8,"0.00%") & "-" & TEXT(S21*1.2,"0.00%"), IF(OR(L21=3,L21=6), TEXT(0,"0.00%") & "-" & TEXT(7%*1.2,"0.00%"), IF(OR(L21=5,L21=7), TEXT((R21/N21),"0.00%") & "-" & TEXT((R21/N21)+7%,"0.00%"), "" ) ) ) -> 2.00%-3.00% | AD21: =ROUND(N21*AC21,0) -> 0 | AE21: =V21+AD21 -> 14734 | AF21: =AE21-N21 -> 359 | AG21: =AE21/N21-1 -> 0.024973913 | AH21: 14 | AI21: 450 | AK21: 688 | AL21: =AE21*AH21+AI21*12+AK21+IF(AB21="",AJ21,IF(AB21="D",5000,IF(AB21="C",1000,0)))*12 -> 212364 | AM21: 4 | AQ21: Chen Chao（15005032） | AR21: Zhu Qianqian（11016705） | AS21: Zhao Chujun | AW21: =_xlfn.LET(_xlpm.actual,X21,_xlpm.low,VALUE(_xlfn.TEXTBEFORE(Y21,"-")),_xlpm.high,VALUE(_xlfn.TEXTAFTER(Y21,"-")),IF(AND(_xlpm.actual=0,OR(_xlpm.low<>0,_xlpm.high<>0)),"0 increase",IF(_xlpm.actual>_xlpm.high*1.2,">20",IF(_xlpm.actual<_xlpm.low*0.8,"<20","OK")))) -> OK | AX21: 0-5 | AY21: 70-90
A22: CN15 | B22: 15001764 | C22: Indirect Active | D22: OP | E22: SNa | F22: FCGNa | G22: 330100 | H22: 40360 | I22: Senior Engineer | J22: Senior Engineer | K22: BAND A5 | L22: 2 | M22: 4 | N22: 9891 | O22: 0.045 | P22: =ROUND(N22*O22,0) -> 445 | Q22: 0.0421 | R22: =ROUND(N22*Q22,0) -> 416 | S22: =T22/N22 -> 0.087048832 | T22: =P22+R22 -> 861 | U22: =N22+T22 -> 10752 | V22: =U22 -> 10752 | W22: =V22-N22 -> 861 | X22: =ROUND(V22/N22-1,4) -> 0.087 | Y22: =IF(OR(L22=1,L22=2,L22=4), TEXT(S22*0.8,"0.00%") & "-" & TEXT(S22*1.2,"0.00%"), IF(OR(L22=3,L22=6), TEXT(0,"0.00%") & "-" & TEXT(7%*1.2,"0.00%"), IF(OR(L22=5,L22=7), TEXT((R22/N22),"0.00%") & "-" & TEXT((R22/N22)+7%,"0.00%"), "" ) ) ) -> 6.96%-10.45% | AD22: =ROUND(N22*AC22,0) -> 0 | AE22: =V22+AD22 -> 10752 | AF22: =AE22-N22 -> 861 | AG22: =AE22/N22-1 -> 0.087048832 | AH22: 14 | AI22: 450 | AK22: 688 | AL22: =AE22*AH22+AI22*12+AK22+IF(AB22="",AJ22,IF(AB22="D",5000,IF(AB22="C",1000,0)))*12 -> 156616 | AM22: 3 | AQ22: Chen Chao（15005032） | AR22: Zhu Qianqian（11016705） | AS22: Zhao Chujun | AW22: =_xlfn.LET(_xlpm.actual,X22,_xlpm.low,VALUE(_xlfn.TEXTBEFORE(Y22,"-")),_xlpm.high,VALUE(_xlfn.TEXTAFTER(Y22,"-")),IF(AND(_xlpm.actual=0,OR(_xlpm.low<>0,_xlpm.high<>0)),"0 increase",IF(_xlpm.actual>_xlpm.high*1.2,">20",IF(_xlpm.actual<_xlpm.low*0.8,"<20","OK")))) -> OK | AX22: 11-15 | AY22: 50-70
A23: CN15 | B23: 15022180 | C23: Indirect Active | D23: OP | E23: SNa | F23: FEDNa-MEP | G23: 370200 | H23: 44686 | I23: Engineer | J23: Process Engineer | K23: BAND A4 | L23: 2 | M23: 3 | N23: 8200 | O23: 0.025 | P23: =ROUND(N23*O23,0) -> 205 | Q23: 0 | R23: =ROUND(N23*Q23,0) -> 0 | S23: =T23/N23 -> 0.025 | T23: =P23+R23 -> 205 | U23: =N23+T23 -> 8405 | V23: 8415 | W23: =V23-N23 -> 215 | X23: =ROUND(V23/N23-1,4) -> 0.0262 | Y23: =IF(OR(L23=1,L23=2,L23=4),TEXT(S23*0.8,"0.00%")&"-"&TEXT(S23*1.2,"0.00%"),IF(OR(L23=3,L23=6),TEXT(0,"0.00%")&"-"&TEXT(7%*1.2,"0.00%"),IF(OR(L23=5,L23=7),TEXT((R23/N23),"0.00%")&"-"&TEXT((R23/N23)+7%,"0.00%"),""))) -> 2.00%-3.00% | AD23: =ROUND(N23*AC23,0) -> 0 | AE23: =V23+AD23 -> 8415 | AF23: =AE23-N23 -> 215 | AG23: =AE23/N23-1 -> 0.026219512 | AH23: 14 | AI23: 550 | AK23: 688 | AL23: =AE23*AH23+AI23*12+AK23+IF(AB23="",AJ23,IF(AB23="D",5000,IF(AB23="C",1000,0)))*12 -> 125098 | AM23: 3 | AQ23: Ding Xudong（15000307） | AR23: Xu Lan（11013544） | AS23: Zhao Chujun | AW23: =_xlfn.LET(_xlpm.actual,X23,_xlpm.low,VALUE(_xlfn.TEXTBEFORE(Y23,"-")),_xlpm.high,VALUE(_xlfn.TEXTAFTER(Y23,"-")),IF(AND(_xlpm.actual=0,OR(_xlpm.low<>0,_xlpm.high<>0)),"0 increase",IF(_xlpm.actual>_xlpm.high*1.2,">20",IF(_xlpm.actual<_xlpm.low*0.8,"<20","OK")))) -> OK | AX23: 0-5 | AY23: 70-90
A24: CN15 | B24: 15003790 | C24: Indirect Active | D24: OP | E24: SNa | F24: FEDNa-MEM | G24: 370201 | H24: 40310 | I24: Supervisor | J24: Head of Mechanical Support | K24: BAND A6 | L24: 2 | M24: 3 | N24: 15324 | O24: 0.03 | P24: =ROUND(N24*O24,0) -> 460 | Q24: 0 | R24: =ROUND(N24*Q24,0) -> 0 | S24: =T24/N24 -> 0.030018272 | T24: =P24+R24 -> 460 | U24: =N24+T24 -> 15784 | V24: 15600 | W24: =V24-N24 -> 276 | X24: =ROUND(V24/N24-1,4) -> 0.018 | Y24: =IF(OR(L24=1,L24=2,L24=4),TEXT(S24*0.8,"0.00%")&"-"&TEXT(S24*1.2,"0.00%"),IF(OR(L24=3,L24=6),TEXT(0,"0.00%")&"-"&TEXT(7%*1.2,"0.00%"),IF(OR(L24=5,L24=7),TEXT((R24/N24),"0.00%")&"-"&TEXT((R24/N24)+7%,"0.00%"),""))) -> 2.40%-3.60% | AD24: =ROUND(N24*AC24,0) -> 0 | AE24: =V24+AD24 -> 15600 | AF24: =AE24-N24 -> 276 | AG24: =AE24/N24-1 -> 0.018010963 | AH24: 14 | AI24: 450 | AK24: 688 | AL24: =AE24*AH24+AI24*12+AK24+IF(AB24="",AJ24,IF(AB24="D",5000,IF(AB24="C",1000,0)))*12 -> 224488 | AM24: 3 | AP24: Internal balance | AQ24: Ding Xudong（15000307） | AR24: Xu Lan（11013544） | AS24: Zhao Chujun | AU24: exceed +/-20% adjustment | AV24: <20 | AW24: =_xlfn.LET(_xlpm.actual,X24,_xlpm.low,VALUE(_xlfn.TEXTBEFORE(Y24,"-")),_xlpm.high,VALUE(_xlfn.TEXTAFTER(Y24,"-")),IF(AND(_xlpm.actual=0,OR(_xlpm.low<>0,_xlpm.high<>0)),"0 increase",IF(_xlpm.actual>_xlpm.high*1.2,">20",IF(_xlpm.actual<_xlpm.low*0.8,"<20","OK")))) -> <20 | AX24: 16-20 | AY24: 50-70
A25: CN15 | B25: 15016330 | C25: Indirect Active | D25: OP | E25: SNa | F25: FEDNa-V2 | G25: 370400 | H25: 42781 | I25: Manager | J25: Head of FEDNa-V2 | K25: BAND B | L25: 2 | M25: 4 | N25: 20300 | O25: 0.0375 | P25: =ROUND(N25*O25,0) -> 761 | Q25: 0.0155 | R25: =ROUND(N25*Q25,0) -> 315 | S25: =T25/N25 -> 0.053004926 | T25: =P25+R25 -> 1076 | U25: =N25+T25 -> 21376 | V25: 21500 | W25: =V25-N25 -> 1200 | X25: =ROUND(V25/N25-1,4) -> 0.0591 | Y25: =IF(OR(L25=1,L25=2,L25=4),TEXT(S25*0.8,"0.00%")&"-"&TEXT(S25*1.2,"0.00%"),IF(OR(L25=3,L25=6),TEXT(0,"0.00%")&"-"&TEXT(7%*1.2,"0.00%"),IF(OR(L25=5,L25=7),TEXT((R25/N25),"0.00%")&"-"&TEXT((R25/N25)+7%,"0.00%"),""))) -> 4.24%-6.36% | AD25: =ROUND(N25*AC25,0) -> 0 | AE25: =V25+AD25 -> 21500 | AF25: =AE25-N25 -> 1200 | AG25: =AE25/N25-1 -> 0.0591133 | AH25: 14 | AI25: 450 | AK25: 688 | AL25: =AE25*AH25+AI25*12+AK25+IF(AB25="",AJ25,IF(AB25="D",5000,IF(AB25="C",1000,0)))*12 -> 307088 | AM25: 3 | AQ25: Ding Xudong（15000307） | AR25: Xu Lan（11013544） | AS25: Zhao Chujun | AW25: =_xlfn.LET(_xlpm.actual,X25,_xlpm.low,VALUE(_xlfn.TEXTBEFORE(Y25,"-")),_xlpm.high,VALUE(_xlfn.TEXTAFTER(Y25,"-")),IF(AND(_xlpm.actual=0,OR(_xlpm.low<>0,_xlpm.high<>0)),"0 increase",IF(_xlpm.actual>_xlpm.high*1.2,">20",IF(_xlpm.actual<_xlpm.low*0.8,"<20","OK")))) -> OK | AX25: 6-10 | AY25: 70-90
A26: CN15 | B26: 15001485 | C26: Indirect Active | D26: OP | E26: SNa | F26: FEDNa-ME | G26: 370200 | H26: 39547 | I26: Manager | J26: Head of Manufacturing Engineering | K26: BAND B | L26: 2 | M26: 3 | N26: 27011 | O26: 0.025 | P26: =ROUND(N26*O26,0) -> 675 | Q26: 0 | R26: =ROUND(N26*Q26,0) -> 0 | S26: =T26/N26 -> 0.024989819 | T26: =P26+R26 -> 675 | U26: =N26+T26 -> 27686 | V26: 27700 | W26: =V26-N26 -> 689 | X26: =ROUND(V26/N26-1,4) -> 0.0255 | Y26: =IF(OR(L26=1,L26=2,L26=4),TEXT(S26*0.8,"0.00%")&"-"&TEXT(S26*1.2,"0.00%"),IF(OR(L26=3,L26=6),TEXT(0,"0.00%")&"-"&TEXT(7%*1.2,"0.00%"),IF(OR(L26=5,L26=7),TEXT((R26/N26),"0.00%")&"-"&TEXT((R26/N26)+7%,"0.00%"),""))) -> 2.00%-3.00% | AD26: =ROUND(N26*AC26,0) -> 0 | AE26: =V26+AD26 -> 27700 | AF26: =AE26-N26 -> 689 | AG26: =AE26/N26-1 -> 0.025508126 | AH26: 14 | AI26: 450 | AK26: 688 | AL26: =AE26*AH26+AI26*12+AK26+IF(AB26="",AJ26,IF(AB26="D",5000,IF(AB26="C",1000,0)))*12 -> 393888 | AM26: 4 | AQ26: Ding Xudong（15000307） | AR26: Xu Lan（11013544） | AS26: Zhao Chujun | AW26: =_xlfn.LET(_xlpm.actual,X26,_xlpm.low,VALUE(_xlfn.TEXTBEFORE(Y26,"-")),_xlpm.high,VALUE(_xlfn.TEXTAFTER(Y26,"-")),IF(AND(_xlpm.actual=0,OR(_xlpm.low<>0,_xlpm.high<>0)),"0 increase",IF(_xlpm.actual>_xlpm.high*1.2,">20",IF(_xlpm.actual<_xlpm.low*0.8,"<20","OK")))) -> OK | AX26: 16-20 | AY26: 70-90
A27: CN15 | B27: 1020358 | C27: Indirect Active | D27: OP | E27: SNa | F27: FEDNa-MEP | G27: 370200 | H27: 45000 | I27: Senior Engineer | J27: Senior Process Engineer | K27: BAND A5 | L27: 2 | M27: 5 | N27: 13610 | O27: 0.05 | P27: =ROUND(N27*O27,0) -> 681 | Q27: 0.027 | R27: =ROUND(N27*Q27,0) -> 367 | S27: =T27/N27 -> 0.077002204 | T27: =P27+R27 -> 1048 | U27: =N27+T27 -> 14658 | V27: 15000 | W27: =V27-N27 -> 1390 | X27: =ROUND(V27/N27-1,4) -> 0.1021 | Y27: =IF(OR(L27=1,L27=2,L27=4),TEXT(S27*0.8,"0.00%")&"-"&TEXT(S27*1.2,"0.00%"),IF(OR(L27=3,L27=6),TEXT(0,"0.00%")&"-"&TEXT(7%*1.2,"0.00%"),IF(OR(L27=5,L27=7),TEXT((R27/N27),"0.00%")&"-"&TEXT((R27/N27)+7%,"0.00%"),""))) -> 6.16%-9.24% | AD27: =ROUND(N27*AC27,0) -> 0 | AE27: =V27+AD27 -> 15000 | AF27: =AE27-N27 -> 1390 | AG27: =AE27/N27-1 -> 0.10213079 | AH27: 14 | AI27: 450 | AK27: 688 | AL27: =AE27*AH27+AI27*12+AK27+IF(AB27="",AJ27,IF(AB27="D",5000,IF(AB27="C",1000,0)))*12 -> 216088 | AM27: 3 | AP27: Rounding | AQ27: Ding Xudong（15000307） | AR27: Xu Lan（11013544） | AS27: Zhao Chujun | AU27: exceed +/-20% adjustment | AV27: >20 | AW27: =_xlfn.LET(_xlpm.actual,X27,_xlpm.low,VALUE(_xlfn.TEXTBEFORE(Y27,"-")),_xlpm.high,VALUE(_xlfn.TEXTAFTER(Y27,"-")),IF(AND(_xlpm.actual=0,OR(_xlpm.low<>0,_xlpm.high<>0)),"0 increase",IF(_xlpm.actual>_xlpm.high*1.2,">20",IF(_xlpm.actual<_xlpm.low*0.8,"<20","OK")))) -> OK | AX27: 0-5 | AY27: 70-90
A28: CN15 | B28: 15021547 | C28: Indirect Active | D28: OP | E28: SNa | F28: FEDNa-MEP | G28: 370200 | H28: 44391 | I28: Engineer | J28: Electrical Engineer | K28: BAND A4 | L28: 2 | M28: 4 | N28: 10500 | O28: 0.0375 | P28: =ROUND(N28*O28,0) -> 394 | Q28: 0 | R28: =ROUND(N28*Q28,0) -> 0 | S28: =T28/N28 -> 0.03752381 | T28: =P28+R28 -> 394 | U28: =N28+T28 -> 10894 | V28: 10827 | W28: =V28-N28 -> 327 | X28: =ROUND(V28/N28-1,4) -> 0.0311 | Y28: =IF(OR(L28=1,L28=2,L28=4),TEXT(S28*0.8,"0.00%")&"-"&TEXT(S28*1.2,"0.00%"),IF(OR(L28=3,L28=6),TEXT(0,"0.00%")&"-"&TEXT(7%*1.2,"0.00%"),IF(OR(L28=5,L28=7),TEXT((R28/N28),"0.00%")&"-"&TEXT((R28/N28)+7%,"0.00%"),""))) -> 3.00%-4.50% | Z28: Promotion | AA28: senior engineer | AB28: A5 | AC28: 0.1117 | AD28: =ROUND(N28*AC28,0) -> 1173 | AE28: =V28+AD28 -> 12000 | AF28: =AE28-N28 -> 1500 | AG28: =AE28/N28-1 -> 0.14285714 | AH28: 14 | AI28: 500 | AK28: 688 | AL28: =AE28*AH28+AI28*12+AK28+IF(AB28="",AJ28,IF(AB28="D",5000,IF(AB28="C",1000,0)))*12 -> 174688 | AM28: 3 | AP28: Good performance and high competence | AQ28: Ding Xudong（15000307） | AR28: Xu Lan（11013544） | AS28: Zhao Chujun | AW28: =_xlfn.LET(_xlpm.actual,X28,_xlpm.low,VALUE(_xlfn.TEXTBEFORE(Y28,"-")),_xlpm.high,VALUE(_xlfn.TEXTAFTER(Y28,"-")),IF(AND(_xlpm.actual=0,OR(_xlpm.low<>0,_xlpm.high<>0)),"0 increase",IF(_xlpm.actual>_xlpm.high*1.2,">20",IF(_xlpm.actual<_xlpm.low*0.8,"<20","OK")))) -> OK | AX28: 0-5 | AY28: 70-90
A29: CN15 | B29: 15012913 | C29: Indirect Active | D29: OP | E29: SNa | F29: FEDNa-ME | G29: 370200 | H29: 41738 | I29: Associate Expert (CN) | J29: Associate Expert (C) | K29: BAND A6 | L29: 2 | M29: 5 | N29: 16000 | O29: 0.06 | P29: =ROUND(N29*O29,0) -> 960 | Q29: 0.0778 | R29: =ROUND(N29*Q29,0) -> 1245 | S29: =T29/N29 -> 0.1378125 | T29: =P29+R29 -> 2205 | U29: =N29+T29 -> 18205 | V29: 18000 | W29: =V29-N29 -> 2000 | X29: =ROUND(V29/N29-1,4) -> 0.125 | Y29: =IF(OR(L29=1,L29=2,L29=4),TEXT(S29*0.8,"0.00%")&"-"&TEXT(S29*1.2,"0.00%"),IF(OR(L29=3,L29=6),TEXT(0,"0.00%")&"-"&TEXT(7%*1.2,"0.00%"),IF(OR(L29=5,L29=7),TEXT((R29/N29),"0.00%")&"-"&TEXT((R29/N29)+7%,"0.00%"),""))) -> 11.03%-16.54% | AD29: =ROUND(N29*AC29,0) -> 0 | AE29: =V29+AD29 -> 18000 | AF29: =AE29-N29 -> 2000 | AG29: =AE29/N29-1 -> 0.125 | AH29: 14 | AI29: 500 | AK29: 688 | AL29: =AE29*AH29+AI29*12+AK29+IF(AB29="",AJ29,IF(AB29="D",5000,IF(AB29="C",1000,0)))*12 -> 258688 | AM29: 4 | AQ29: Ding Xudong（15000307） | AR29: Xu Lan（11013544） | AS29: Zhao Chujun | AW29: =_xlfn.LET(_xlpm.actual,X29,_xlpm.low,VALUE(_xlfn.TEXTBEFORE(Y29,"-")),_xlpm.high,VALUE(_xlfn.TEXTAFTER(Y29,"-")),IF(AND(_xlpm.actual=0,OR(_xlpm.low<>0,_xlpm.high<>0)),"0 increase",IF(_xlpm.actual>_xlpm.high*1.2,">20",IF(_xlpm.actual<_xlpm.low*0.8,"<20","OK")))) -> OK | AX29: 11-15 | AY29: 0
A30: CN15 | B30: 15001306 | C30: Indirect Active | D30: OP | E30: SNa | F30: FEDNa-ME | G30: 370200 | H30: 39420 | I30: Functional Specialist | J30: Functional Specialist | K30: BAND A6 | L30: 2 | M30: 3 | N30: 20306 | O30: 0 | P30: =ROUND(N30*O30,0) -> 0 | Q30: 0 | R30: =ROUND(N30*Q30,0) -> 0 | S30: =T30/N30 -> 0 | T30: =P30+R30 -> 0 | U30: =N30+T30 -> 20306 | V30: 20500 | W30: =V30-N30 -> 194 | X30: =ROUND(V30/N30-1,4) -> 0.0096 | Y30: =IF(OR(L30=1,L30=2,L30=4),TEXT(S30*0.8,"0.00%")&"-"&TEXT(S30*1.2,"0.00%"),IF(OR(L30=3,L30=6),TEXT(0,"0.00%")&"-"&TEXT(7%*1.2,"0.00%"),IF(OR(L30=5,L30=7),TEXT((R30/N30),"0.00%")&"-"&TEXT((R30/N30)+7%,"0.00%"),""))) -> 0.00%-0.00% | AD30: =ROUND(N30*AC30,0) -> 0 | AE30: =V30+AD30 -> 20500 | AF30: =AE30-N30 -> 194 | AG30: =AE30/N30-1 -> 0.0095538265 | AH30: 14 | AI30: 600 | AK30: 688 | AL30: =AE30*AH30+AI30*12+AK30+IF(AB30="",AJ30,IF(AB30="D",5000,IF(AB30="C",1000,0)))*12 -> 294888 | AM30: 4 | AP30: Good performance and high competence | AQ30: Ding Xudong（15000307） | AR30: Xu Lan（11013544） | AS30: Zhao Chujun | AU30: exceed +/-20% adjustment | AV30: >20 | AW30: =_xlfn.LET(_xlpm.actual,X30,_xlpm.low,VALUE(_xlfn.TEXTBEFORE(Y30,"-")),_xlpm.high,VALUE(_xlfn.TEXTAFTER(Y30,"-")),IF(AND(_xlpm.actual=0,OR(_xlpm.low<>0,_xlpm.high<>0)),"0 increase",IF(_xlpm.actual>_xlpm.high*1.2,">20",IF(_xlpm.actual<_xlpm.low*0.8,"<20","OK")))) -> >20 | AX30: 16-20 | AY30: >90
A31: CN15 | B31: 15021548 | C31: Indirect Active | D31: OP | E31: SNa | F31: FEDNa-ME | G31: 370200 | H31: 44391 | I31: Senior Engineer | J31: Senior Equipment Engineer | K31: BAND A5 | L31: 2 | M31: 3 | N31: 13330 | O31: 0.025 | P31: =ROUND(N31*O31,0) -> 333 | Q31: 0 | R31: =ROUND(N31*Q31,0) -> 0 | S31: =T31/N31 -> 0.024981245 | T31: =P31+R31 -> 333 | U31: =N31+T31 -> 13663 | V31: 13600 | W31: =V31-N31 -> 270 | X31: =ROUND(V31/N31-1,4) -> 0.0203 | Y31: =IF(OR(L31=1,L31=2,L31=4),TEXT(S31*0.8,"0.00%")&"-"&TEXT(S31*1.2,"0.00%"),IF(OR(L31=3,L31=6),TEXT(0,"0.00%")&"-"&TEXT(7%*1.2,"0.00%"),IF(OR(L31=5,L31=7),TEXT((R31/N31),"0.00%")&"-"&TEXT((R31/N31)+7%,"0.00%"),""))) -> 2.00%-3.00% | AD31: =ROUND(N31*AC31,0) -> 0 | AE31: =V31+AD31 -> 13600 | AF31: =AE31-N31 -> 270 | AG31: =AE31/N31-1 -> 0.020255064 | AH31: 14 | AI31: 450 | AK31: 688 | AL31: =AE31*AH31+AI31*12+AK31+IF(AB31="",AJ31,IF(AB31="D",5000,IF(AB31="C",1000,0)))*12 -> 196488 | AM31: 3 | AQ31: Ding Xudong（15000307） | AR31: Xu Lan（11013544） | AS31: Zhao Chujun | AW31: =_xlfn.LET(_xlpm.actual,X31,_xlpm.low,VALUE(_xlfn.TEXTBEFORE(Y31,"-")),_xlpm.high,VALUE(_xlfn.TEXTAFTER(Y31,"-")),IF(AND(_xlpm.actual=0,OR(_xlpm.low<>0,_xlpm.high<>0)),"0 increase",IF(_xlpm.actual>_xlpm.high*1.2,">20",IF(_xlpm.actual<_xlpm.low*0.8,"<20","OK")))) -> OK | AX31: 0-5 | AY31: 70-90
A32: CN15 | B32: 15021979 | C32: Indirect Active | D32: OP | E32: SNa | F32: FEDNa-V2 | G32: 370404 | H32: 44503 | I32: Engineer | J32: Production Engineer | K32: BAND A4 | L32: 2 | M32: 3 | N32: 9450 | O32: 0.025 | P32: =ROUND(N32*O32,0) -> 236 | Q32: 0 | R32: =ROUND(N32*Q32,0) -> 0 | S32: =T32/N32 -> 0.024973545 | T32: =P32+R32 -> 236 | U32: =N32+T32 -> 9686 | V32: 9700 | W32: =V32-N32 -> 250 | X32: =ROUND(V32/N32-1,4) -> 0.0265 | Y32: =IF(OR(L32=1,L32=2,L32=4),TEXT(S32*0.8,"0.00%")&"-"&TEXT(S32*1.2,"0.00%"),IF(OR(L32=3,L32=6),TEXT(0,"0.00%")&"-"&TEXT(7%*1.2,"0.00%"),IF(OR(L32=5,L32=7),TEXT((R32/N32),"0.00%")&"-"&TEXT((R32/N32)+7%,"0.00%"),""))) -> 2.00%-3.00% | AD32: =ROUND(N32*AC32,0) -> 0 | AE32: =V32+AD32 -> 9700 | AF32: =AE32-N32 -> 250 | AG32: =AE32/N32-1 -> 0.026455026 | AH32: 14 | AI32: 450 | AK32: 688 | AL32: =AE32*AH32+AI32*12+AK32+IF(AB32="",AJ32,IF(AB32="D",5000,IF(AB32="C",1000,0)))*12 -> 141888 | AM32: 2 | AQ32: Ding Xudong（15000307） | AR32: Xu Lan（11013544） | AS32: Zhao Chujun | AW32: =_xlfn.LET(_xlpm.actual,X32,_xlpm.low,VALUE(_xlfn.TEXTBEFORE(Y32,"-")),_xlpm.high,VALUE(_xlfn.TEXTAFTER(Y32,"-")),IF(AND(_xlpm.actual=0,OR(_xlpm.low<>0,_xlpm.high<>0)),"0 increase",IF(_xlpm.actual>_xlpm.high*1.2,">20",IF(_xlpm.actual<_xlpm.low*0.8,"<20","OK")))) -> OK | AX32: 0-5 | AY32: 70-90
A33: CN15 | B33: 15000525 | C33: Indirect Active | D33: OP | E33: SNa | F33: FEDNa-FS | G33: 370100 | H33: 38869 | I33: Coordinator | J33: TPM Coordinator | K33: BAND A4 | L33: 2 | M33: 3 | N33: 7900 | O33: 0 | P33: =ROUND(N33*O33,0) -> 0 | Q33: 0 | R33: =ROUND(N33*Q33,0) -> 0 | S33: =T33/N33 -> 0 | T33: =P33+R33 -> 0 | U33: =N33+T33 -> 7900 | V33: 8000 | W33: =V33-N33 -> 100 | X33: =ROUND(V33/N33-1,4) -> 0.0127 | Y33: =IF(OR(L33=1,L33=2,L33=4),TEXT(S33*0.8,"0.00%")&"-"&TEXT(S33*1.2,"0.00%"),IF(OR(L33=3,L33=6),TEXT(0,"0.00%")&"-"&TEXT(7%*1.2,"0.00%"),IF(OR(L33=5,L33=7),TEXT((R33/N33),"0.00%")&"-"&TEXT((R33/N33)+7%,"0.00%"),""))) -> 0.00%-0.00% | AD33: =ROUND(N33*AC33,0) -> 0 | AE33: =V33+AD33 -> 8000 | AF33: =AE33-N33 -> 100 | AG33: =AE33/N33-1 -> 0.012658228 | AH33: 14 | AI33: 650 | AK33: 688 | AL33: =AE33*AH33+AI33*12+AK33+IF(AB33="",AJ33,IF(AB33="D",5000,IF(AB33="C",1000,0)))*12 -> 120488 | AM33: 3 | AP33: Internal balance | AQ33: Ding Xudong（15000307） | AR33: Xu Lan（11013544） | AS33: Zhao Chujun | AU33: exceed +/-20% adjustment | AV33: >20 | AW33: =_xlfn.LET(_xlpm.actual,X33,_xlpm.low,VALUE(_xlfn.TEXTBEFORE(Y33,"-")),_xlpm.high,VALUE(_xlfn.TEXTAFTER(Y33,"-")),IF(AND(_xlpm.actual=0,OR(_xlpm.low<>0,_xlpm.high<>0)),"0 increase",IF(_xlpm.actual>_xlpm.high*1.2,">20",IF(_xlpm.actual<_xlpm.low*0.8,"<20","OK")))) -> >20 | AX33: 16-20 | AY33: >90
A34: CN15 | B34: 15020089 | C34: Indirect Active | D34: OP | E34: SNa | F34: FEDNa-MEP | G34: 370200 | H34: 43908 | I34: Engineer | J34: Process Engineer | K34: BAND A4 | L34: 2 | M34: 3 | N34: 10100 | O34: 0.025 | P34: =ROUND(N34*O34,0) -> 253 | Q34: 0 | R34: =ROUND(N34*Q34,0) -> 0 | S34: =T34/N34 -> 0.025049505 | T34: =P34+R34 -> 253 | U34: =N34+T34 -> 10353 | V34: 10300 | W34: =V34-N34 -> 200 | X34: =ROUND(V34/N34-1,4) -> 0.0198 | Y34: =IF(OR(L34=1,L34=2,L34=4),TEXT(S34*0.8,"0.00%")&"-"&TEXT(S34*1.2,"0.00%"),IF(OR(L34=3,L34=6),TEXT(0,"0.00%")&"-"&TEXT(7%*1.2,"0.00%"),IF(OR(L34=5,L34=7),TEXT((R34/N34),"0.00%")&"-"&TEXT((R34/N34)+7%,"0.00%"),""))) -> 2.00%-3.01% | AD34: =ROUND(N34*AC34,0) -> 0 | AE34: =V34+AD34 -> 10300 | AF34: =AE34-N34 -> 200 | AG34: =AE34/N34-1 -> 0.01980198 | AH34: 14 | AI34: 450 | AK34: 688 | AL34: =AE34*AH34+AI34*12+AK34+IF(AB34="",AJ34,IF(AB34="D",5000,IF(AB34="C",1000,0)))*12 -> 150288 | AM34: 3 | AP34: Rounding | AQ34: Ding Xudong（15000307） | AR34: Xu Lan（11013544） | AS34: Zhao Chujun | AU34: exceed +/-20% adjustment | AV34: <20 | AW34: =_xlfn.LET(_xlpm.actual,X34,_xlpm.low,VALUE(_xlfn.TEXTBEFORE(Y34,"-")),_xlpm.high,VALUE(_xlfn.TEXTAFTER(Y34,"-")),IF(AND(_xlpm.actual=0,OR(_xlpm.low<>0,_xlpm.high<>0)),"0 increase",IF(_xlpm.actual>_xlpm.high*1.2,">20",IF(_xlpm.actual<_xlpm.low*0.8,"<20","OK")))) -> OK | AX34: 6-10 | AY34: 70-90
A35: CN15 | B35: 15000550 | C35: Indirect Active | D35: OP | E35: SNa | F35: FEDNa-V2 | G35: 370404 | H35: 38881 | I35: Engineer | J35: Engineer | K35: BAND A4 | L35: 2 | M35: 4 | N35: 9800 | O35: 0.0375 | P35: =ROUND(N35*O35,0) -> 368 | Q35: 0.0155 | R35: =ROUND(N35*Q35,0) -> 152 | S35: =T35/N35 -> 0.053061224 | T35: =P35+R35 -> 520 | U35: =N35+T35 -> 10320 | V35: 10300 | W35: =V35-N35 -> 500 | X35: =ROUND(V35/N35-1,4) -> 0.051 | Y35: =IF(OR(L35=1,L35=2,L35=4),TEXT(S35*0.8,"0.00%")&"-"&TEXT(S35*1.2,"0.00%"),IF(OR(L35=3,L35=6),TEXT(0,"0.00%")&"-"&TEXT(7%*1.2,"0.00%"),IF(OR(L35=5,L35=7),TEXT((R35/N35),"0.00%")&"-"&TEXT((R35/N35)+7%,"0.00%"),""))) -> 4.24%-6.37% | AD35: =ROUND(N35*AC35,0) -> 0 | AE35: =V35+AD35 -> 10300 | AF35: =AE35-N35 -> 500 | AG35: =AE35/N35-1 -> 0.051020408 | AH35: 14 | AI35: 550 | AK35: 688 | AL35: =AE35*AH35+AI35*12+AK35+IF(AB35="",AJ35,IF(AB35="D",5000,IF(AB35="C",1000,0)))*12 -> 151488 | AM35: 3 | AQ35: Ding Xudong（15000307） | AR35: Xu Lan（11013544） | AS35: Zhao Chujun | AW35: =_xlfn.LET(_xlpm.actual,X35,_xlpm.low,VALUE(_xlfn.TEXTBEFORE(Y35,"-")),_xlpm.high,VALUE(_xlfn.TEXTAFTER(Y35,"-")),IF(AND(_xlpm.actual=0,OR(_xlpm.low<>0,_xlpm.high<>0)),"0 increase",IF(_xlpm.actual>_xlpm.high*1.2,">20",IF(_xlpm.actual<_xlpm.low*0.8,"<20","OK")))) -> OK | AX35: 16-20 | AY35: 70-90
A36: CN15 | B36: 15015967 | C36: Indirect Active | D36: OP | E36: SNa | F36: FEDNa-FS | G36: 370100 | H36: 42683 | I36: Associate Expert (CN) | J36: Associate Expert (C) | K36: BAND A6 | L36: 2 | M36: 4 | N36: 12360 | O36: 0.045 | P36: =ROUND(N36*O36,0) -> 556 | Q36: 0.0421 | R36: =ROUND(N36*Q36,0) -> 520 | S36: =T36/N36 -> 0.087055016 | T36: =P36+R36 -> 1076 | U36: =N36+T36 -> 13436 | V36: 13300 | W36: =V36-N36 -> 940 | X36: =ROUND(V36/N36-1,4) -> 0.0761 | Y36: =IF(OR(L36=1,L36=2,L36=4),TEXT(S36*0.8,"0.00%")&"-"&TEXT(S36*1.2,"0.00%"),IF(OR(L36=3,L36=6),TEXT(0,"0.00%")&"-"&TEXT(7%*1.2,"0.00%"),IF(OR(L36=5,L36=7),TEXT((R36/N36),"0.00%")&"-"&TEXT((R36/N36)+7%,"0.00%"),""))) -> 6.96%-10.45% | AD36: =ROUND(N36*AC36,0) -> 0 | AE36: =V36+AD36 -> 13300 | AF36: =AE36-N36 -> 940 | AG36: =AE36/N36-1 -> 0.07605178 | AH36: 14 | AI36: 450 | AK36: 688 | AL36: =AE36*AH36+AI36*12+AK36+IF(AB36="",AJ36,IF(AB36="D",5000,IF(AB36="C",1000,0)))*12 -> 192288 | AM36: 3 | AQ36: Ding Xudong（15000307） | AR36: Xu Lan（11013544） | AS36: Zhao Chujun | AW36: =_xlfn.LET(_xlpm.actual,X36,_xlpm.low,VALUE(_xlfn.TEXTBEFORE(Y36,"-")),_xlpm.high,VALUE(_xlfn.TEXTAFTER(Y36,"-")),IF(AND(_xlpm.actual=0,OR(_xlpm.low<>0,_xlpm.high<>0)),"0 increase",IF(_xlpm.actual>_xlpm.high*1.2,">20",IF(_xlpm.actual<_xlpm.low*0.8,"<20","OK")))) -> OK | AX36: 6-10 | AY36: 50-70
A37: CN15 | B37: 15001287 | C37: Indirect Active | D37: OP | E37: SNa | F37: FEDNa-MEP | G37: 370200 | H37: 39392 | I37: Senior Engineer | J37: Senior Electrical Engineer | K37: BAND A5 | L37: 2 | M37: 3 | N37: 12500 | O37: 0.025 | P37: =ROUND(N37*O37,0) -> 313 | Q37: 0 | R37: =ROUND(N37*Q37,0) -> 0 | S37: =T37/N37 -> 0.02504 | T37: =P37+R37 -> 313 | U37: =N37+T37 -> 12813 | V37: 12600 | W37: =V37-N37 -> 100 | X37: =ROUND(V37/N37-1,4) -> 0.008 | Y37: =IF(OR(L37=1,L37=2,L37=4),TEXT(S37*0.8,"0.00%")&"-"&TEXT(S37*1.2,"0.00%"),IF(OR(L37=3,L37=6),TEXT(0,"0.00%")&"-"&TEXT(7%*1.2,"0.00%"),IF(OR(L37=5,L37=7),TEXT((R37/N37),"0.00%")&"-"&TEXT((R37/N37)+7%,"0.00%"),""))) -> 2.00%-3.00% | AD37: =ROUND(N37*AC37,0) -> 0 | AE37: =V37+AD37 -> 12600 | AF37: =AE37-N37 -> 100 | AG37: =AE37/N37-1 -> 0.008 | AH37: 14 | AI37: 450 | AK37: 688 | AL37: =AE37*AH37+AI37*12+AK37+IF(AB37="",AJ37,IF(AB37="D",5000,IF(AB37="C",1000,0)))*12 -> 182488 | AM37: 3 | AP37: Left/will leave/retire soon | AQ37: Ding Xudong（15000307） | AR37: Xu Lan（11013544） | AS37: Zhao Chujun | AU37: exceed +/-20% adjustment | AV37: <20 | AW37: =_xlfn.LET(_xlpm.actual,X37,_xlpm.low,VALUE(_xlfn.TEXTBEFORE(Y37,"-")),_xlpm.high,VALUE(_xlfn.TEXTAFTER(Y37,"-")),IF(AND(_xlpm.actual=0,OR(_xlpm.low<>0,_xlpm.high<>0)),"0 increase",IF(_xlpm.actual>_xlpm.high*1.2,">20",IF(_xlpm.actual<_xlpm.low*0.8,"<20","OK")))) -> <20 | AX37: 16-20 | AY37: 70-90
A38: CN15 | B38: 15016938 | C38: Indirect Active | D38: OP | E38: SNa | F38: FEDNa-MEP | G38: 370200 | H38: 42830 | I38: Supervisor | J38: Head of FEDNa-MEP | K38: BAND A6 | L38: 2 | M38: 5 | N38: 18000 | O38: 0.05 | P38: =ROUND(N38*O38,0) -> 900 | Q38: 0.027 | R38: =ROUND(N38*Q38,0) -> 486 | S38: =T38/N38 -> 0.077 | T38: =P38+R38 -> 1386 | U38: =N38+T38 -> 19386 | V38: 19700 | W38: =V38-N38 -> 1700 | X38: =ROUND(V38/N38-1,4) -> 0.0944 | Y38: =IF(OR(L38=1,L38=2,L38=4),TEXT(S38*0.8,"0.00%")&"-"&TEXT(S38*1.2,"0.00%"),IF(OR(L38=3,L38=6),TEXT(0,"0.00%")&"-"&TEXT(7%*1.2,"0.00%"),IF(OR(L38=5,L38=7),TEXT((R38/N38),"0.00%")&"-"&TEXT((R38/N38)+7%,"0.00%"),""))) -> 6.16%-9.24% | AD38: =ROUND(N38*AC38,0) -> 0 | AE38: =V38+AD38 -> 19700 | AF38: =AE38-N38 -> 1700 | AG38: =AE38/N38-1 -> 0.094444444 | AH38: 14 | AI38: 450 | AK38: 688 | AL38: =AE38*AH38+AI38*12+AK38+IF(AB38="",AJ38,IF(AB38="D",5000,IF(AB38="C",1000,0)))*12 -> 281888 | AM38: 5 | AP38: Good performance/talent | AQ38: Ding Xudong（15000307） | AR38: Xu Lan（11013544） | AS38: Zhao Chujun | AU38: exceed +/-20% adjustment | AV38: >20 | AW38: =_xlfn.LET(_xlpm.actual,X38,_xlpm.low,VALUE(_xlfn.TEXTBEFORE(Y38,"-")),_xlpm.high,VALUE(_xlfn.TEXTAFTER(Y38,"-")),IF(AND(_xlpm.actual=0,OR(_xlpm.low<>0,_xlpm.high<>0)),"0 increase",IF(_xlpm.actual>_xlpm.high*1.2,">20",IF(_xlpm.actual<_xlpm.low*0.8,"<20","OK")))) -> OK | AX38: 6-10 | AY38: 70-90
